Workbook

Sheet 面板数据
A1: id | B1: 地 | C1: year | D1: 能源消费总量(万吨标准煤) | E1: CO2排放总量(万吨) | F1: 生产总值（亿元） | G1: 单位GDP能耗 | H1: 单位GDP能耗增长率 | I1: 非化石能源占比 | J1: 非化石能源占比增长率 | K1: 单位GDP碳排放量 | L1: 单位GDP碳排放量增长率 | M1: post1 | N1: post2 | O1: treated | P1: avg_direct_sim | Q1: avg_direct_degree | R1: avg_hidden_degree | S1: target | T1: target_hid | U1: deg70 | V1: deg80 | W1: deg90 | X1: std_sim | Y1: std_deg | Z1: std_hid_deg | AA1: std_target | AB1: std_hid_target | AC1: std_70 | AD1: std_80 | AE1: std_90 | AF1: a145 | AG1: b145 | AH1: c145 | AI1: a155 | AJ1: c155 | AK1: std_a145 | AL1: std_b145 | AM1: std_c145 | AN1: std_a155 | AO1: std_c155 | AP1: a | AQ1: b | AR1: c | AS1: if_a | AT1: if_b | AU1: if_c | AV1: if_a_155 | AW1: if_c_155
A2: 1 | B2: 北京 | C2: 2016 | D2: 6917 | E2: 7413.4217 | F2: 25669.13 | G2: 0.26946764 | I2: 0.35776976 | K2: 0.28880689 | M2: 0 | N2: 0 | O2: 1 | P2: 0.75759066 | Q2: 0.49120235 | R2: 0.1919221 | S2: 1.1 | T2: -0.03 | U2: 0.51785714 | V2: 0.24380165 | W2: 0.85714286 | X2: 0 | Y2: 0.35300316 | Z2: 0.13763137 | AA2: 0.31428571 | AB2: -0.01744186 | AC2: 0.41857143 | AD2: 0.26063706 | AE2: 1 | AF2: 0.144 | AG2: 0.14 | AH2: 0.18 | AI2: 0.25 | AJ2: 0.65 | AK2: 0.72 | AL2: 1.037037 | AM2: 1 | AN2: 1 | AO2: 1 | AP2: =AVERAGE(AK2,AN2) -> 0.86 | AQ2: =AVERAGE(AL2) -> 1.037037 | AR2: =AVERAGE(AM2,AO2) -> 1 | AS2: {=_xlfn.IFS(AF2>'“主要目标”数据分表'!$C$2,1,AF2='“主要目标”数据分表'!$C$2,0,AF2<'“主要目标”数据分表'!$C$2,-1)} -> -1 | AT2: {=_xlfn.IFS(AG2>'“主要目标”数据分表'!$D$2,1,AG2='“主要目标”数据分表'!$D$2,0,AG2<'“主要目标”数据分表'!$D$2,-1)} -> 1 | AU2: {=_xlfn.IFS(AH2>'“主要目标”数据分表'!$E$2,1,AH2='“主要目标”数据分表'!$E$2,0,AH2<'“主要目标”数据分表'!$E$2,-1)} -> 0 | AV2: {=_xlfn.IFS(AI2>'“主要目标”数据分表'!$F$2,1,AI2='“主要目标”数据分表'!$F$2,0,AI2<'“主要目标”数据分表'!$F$2,-1)} -> 0 | AW2: {=_xlfn.IFS(AJ2>'“主要目标”数据分表'!$G$2,1,AJ2='“主要目标”数据分表'!$G$2,0,AJ2<'“主要目标”数据分表'!$G$2,-1)} -> 0
A3: 1 | B3: 北京 | C3: 2017 | D3: 7088 | E3: 7623.383 | F3: 28014.94 | G3: 0.25300786 | H3: =(G3-G2)/G2 -> -0.061082603 | I3: 0.36853608 | J3: =(I3-I2)/I2 -> 0.030092858 | K3: 0.27211849 | L3: =(K3-K2)/K2 -> -0.057783963 | M3: 0 | N3: 0 | O3: 1 | P3: 0.75759066 | Q3: 0.49120235 | R3: 0.1919221 | S3: 1.1 | T3: -0.03 | U3: 0.51785714 | V3: 0.24380165 | W3: 0.85714286 | X3: 0 | Y3: 0.35300316 | Z3: 0.13763137 | AA3: 0.31428571 | AB3: -0.01744186 | AC3: 0.41857143 | AD3: 0.26063706 | AE3: 1 | AF3: 0.144 | AG3: 0.14 | AH3: 0.18 | AI3: 0.25 | AJ3: 0.65 | AK3: 0.72 | AL3: 1.037037 | AM3: 1 | AN3: 1 | AO3: 1 | AP3: =AVERAGE(AK3,AN3) -> 0.86 | AQ3: =AVERAGE(AL3) -> 1.037037 | AR3: =AVERAGE(AM3,AO3) -> 1 | AS3: {=_xlfn.IFS(AF3>'“主要目标”数据分表'!$C$2,1,AF3='“主要目标”数据分表'!$C$2,0,AF3<'“主要目标”数据分表'!$C$2,-1)} -> -1 | AT3: {=_xlfn.IFS(AG3>'“主要目标”数据分表'!$D$2,1,AG3='“主要目标”数据分表'!$D$2,0,AG3<'“主要目标”数据分表'!$D$2,-1)} -> 1 | AU3: {=_xlfn.IFS(AH3>'“主要目标”数据分表'!$E$2,1,AH3='“主要目标”数据分表'!$E$2,0,AH3<'“主要目标”数据分表'!$E$2,-1)} -> 0 | AV3: {=_xlfn.IFS(AI3>'“主要目标”数据分表'!$F$2,1,AI3='“主要目标”数据分表'!$F$2,0,AI3<'“主要目标”数据分表'!$F$2,-1)} -> 0 | AW3: {=_xlfn.IFS(AJ3>'“主要目标”数据分表'!$G$2,1,AJ3='“主要目标”数据分表'!$G$2,0,AJ3<'“主要目标”数据分表'!$G$2,-1)} -> 0
A4: 1 | B4: 北京 | C4: 2018 | D4: 7270 | E4: 7770.4187 | F4: 30319.98 | G4: 0.23977588 | H4: =(G4-G3)/G3 -> -0.052298674 | I4: 0.3894371 | J4: =(I4-I3)/I3 -> 0.056713642 | K4: 0.25628047 | L4: =(K4-K3)/K3 -> -0.058202652 | M4: 0 | N4: 0 | O4: 1 | P4: 0.75759066 | Q4: 0.49120235 | R4: 0.1919221 | S4: 1.1 | T4: -0.03 | U4: 0.51785714 | V4: 0.24380165 | W4: 0.85714286 | X4: 0 | Y4: 0.35300316 | Z4: 0.13763137 | AA4: 0.31428571 | AB4: -0.01744186 | AC4: 0.41857143 | AD4: 0.26063706 | AE4: 1 | AF4: 0.144 | AG4: 0.14 | AH4: 0.18 | AI4: 0.25 | AJ4: 0.65 | AK4: 0.72 | AL4: 1.037037 | AM4: 1 | AN4: 1 | AO4: 1 | AP4: =AVERAGE(AK4,AN4) -> 0.86 | AQ4: =AVERAGE(AL4) -> 1.037037 | AR4: =AVERAGE(AM4,AO4) -> 1 | AS4: {=_xlfn.IFS(AF4>'“主要目标”数据分表'!$C$2,1,AF4='“主要目标”数据分表'!$C$2,0,AF4<'“主要目标”数据分表'!$C$2,-1)} -> -1 | AT4: {=_xlfn.IFS(AG4>'“主要目标”数据分表'!$D$2,1,AG4='“主要目标”数据分表'!$D$2,0,AG4<'“主要目标”数据分表'!$D$2,-1)} -> 1 | AU4: {=_xlfn.IFS(AH4>'“主要目标”数据分表'!$E$2,1,AH4='“主要目标”数据分表'!$E$2,0,AH4<'“主要目标”数据分表'!$E$2,-1)} -> 0 | AV4: {=_xlfn.IFS(AI4>'“主要目标”数据分表'!$F$2,1,AI4='“主要目标”数据分表'!$F$2,0,AI4<'“主要目标”数据分表'!$F$2,-1)} -> 0 | AW4: {=_xlfn.IFS(AJ4>'“主要目标”数据分表'!$G$2,1,AJ4='“主要目标”数据分表'!$G$2,0,AJ4<'“主要目标”数据分表'!$G$2,-1)} -> 0
A5: 1 | B5: 北京 | C5: 2019 | D5: 7360 | E5: 7804.4413 | F5: 35371.28 | G5: 0.20807842 | H5: =(G5-G4)/G4 -> -0.13219622 | I5: 0.39378508 | J5: =(I5-I4)/I4 -> 0.011164767 | K5: 0.22064345 | L5: =(K5-K4)/K4 -> -0.13905475 | M5: 0 | N5: 0 | O5: 1 | P5: 0.75759066 | Q5: 0.49120235 | R5: 0.1919221 | S5: 1.1 | T5: -0.03 | U5: 0.51785714 | V5: 0.24380165 | W5: 0.85714286 | X5: 0 | Y5: 0.35300316 | Z5: 0.13763137 | AA5: 0.31428571 | AB5: -0.01744186 | AC5: 0.41857143 | AD5: 0.26063706 | AE5: 1 | AF5: 0.144 | AG5: 0.14 | AH5: 0.18 | AI5: 0.25 | AJ5: 0.65 | AK5: 0.72 | AL5: 1.037037 | AM5: 1 | AN5: 1 | AO5: 1 | AP5: =AVERAGE(AK5,AN5) -> 0.86 | AQ5: =AVERAGE(AL5) -> 1.037037 | AR5: =AVERAGE(AM5,AO5) -> 1 | AS5: {=_xlfn.IFS(AF5>'“主要目标”数据分表'!$C$2,1,AF5='“主要目标”数据分表'!$C$2,0,AF5<'“主要目标”数据分表'!$C$2,-1)} -> -1 | AT5: {=_xlfn.IFS(AG5>'“主要目标”数据分表'!$D$2,1,AG5='“主要目标”数据分表'!$D$2,0,AG5<'“主要目标”数据分表'!$D$2,-1)} -> 1 | AU5: {=_xlfn.IFS(AH5>'“主要目标”数据分表'!$E$2,1,AH5='“主要目标”数据分表'!$E$2,0,AH5<'“主要目标”数据分表'!$E$2,-1)} -> 0 | AV5: {=_xlfn.IFS(AI5>'“主要目标”数据分表'!$F$2,1,AI5='“主要目标”数据分表'!$F$2,0,AI5<'“主要目标”数据分表'!$F$2,-1)} -> 0 | AW5: {=_xlfn.IFS(AJ5>'“主要目标”数据分表'!$G$2,1,AJ5='“主要目标”数据分表'!$G$2,0,AJ5<'“主要目标”数据分表'!$G$2,-1)} -> 0
A6: 1 | B6: 北京 | C6: 2020 | D6: 6762.1 | E6: 7763.0137 | F6: 36102.55 | G6: 0.18730256 | H6: =(G6-G5)/G5 -> -0.099846297 | I6: 0.45559969 | J6: =(I6-I5)/I5 -> 0.15697552 | K6: 0.21502674 | L6: =(K6-K5)/K5 -> -0.025456044 | M6: 0 | N6: 0 | O6: 1 | P6: 0.75759066 | Q6: 0.49120235 | R6: 0.1919221 | S6: 1.1 | T6: -0.03 | U6: 0.51785714 | V6: 0.24380165 | W6: 0.85714286 | X6: 0 | Y6: 0.35300316 | Z6: 0.13763137 | AA6: 0.31428571 | AB6: -0.01744186 | AC6: 0.41857143 | AD6: 0.26063706 | AE6: 1 | AF6: 0.144 | AG6: 0.14 | AH6: 0.18 | AI6: 0.25 | AJ6: 0.65 | AK6: 0.72 | AL6: 1.037037 | AM6: 1 | AN6: 1 | AO6: 1 | AP6: =AVERAGE(AK6,AN6) -> 0.86 | AQ6: =AVERAGE(AL6) -> 1.037037 | AR6: =AVERAGE(AM6,AO6) -> 1 | AS6: {=_xlfn.IFS(AF6>'“主要目标”数据分表'!$C$2,1,AF6='“主要目标”数据分表'!$C$2,0,AF6<'“主要目标”数据分表'!$C$2,-1)} -> -1 | AT6: {=_xlfn.IFS(AG6>'“主要目标”数据分表'!$D$2,1,AG6='“主要目标”数据分表'!$D$2,0,AG6<'“主要目标”数据分表'!$D$2,-1)} -> 1 | AU6: {=_xlfn.IFS(AH6>'“主要目标”数据分表'!$E$2,1,AH6='“主要目标”数据分表'!$E$2,0,AH6<'“主要目标”数据分表'!$E$2,-1)} -> 0 | AV6: {=_xlfn.IFS(AI6>'“主要目标”数据分表'!$F$2,1,AI6='“主要目标”数据分表'!$F$2,0,AI6<'“主要目标”数据分表'!$F$2,-1)} -> 0 | AW6: {=_xlfn.IFS(AJ6>'“主要目标”数据分表'!$G$2,1,AJ6='“主要目标”数据分表'!$G$2,0,AJ6<'“主要目标”数据分表'!$G$2,-1)} -> 0
A7: 1 | B7: 北京 | C7: 2021 | D7: 7103.62 | E7: 8010.2176 | F7: 40269.55 | G7: 0.17640177 | H7: =(G7-G6)/G6 -> -0.058198812 | I7: 0.44803091 | J7: =(I7-I6)/I6 -> -0.016612797 | K7: 0.198915 | L7: =(K7-K6)/K6 -> -0.074929003 | M7: 0 | N7: 0 | O7: 1 | P7: 0.75759066 | Q7: 0.49120235 | R7: 0.1919221 | S7: 1.1 | T7: -0.03 | U7: 0.51785714 | V7: 0.24380165 | W7: 0.85714286 | X7: 0 | Y7: 0.35300316 | Z7: 0.13763137 | AA7: 0.31428571 | AB7: -0.01744186 | AC7: 0.41857143 | AD7: 0.26063706 | AE7: 1 | AF7: 0.144 | AG7: 0.14 | AH7: 0.18 | AI7: 0.25 | AJ7: 0.65 | AK7: 0.72 | AL7: 1.037037 | AM7: 1 | AN7: 1 | AO7: 1 | AP7: =AVERAGE(AK7,AN7) -> 0.86 | AQ7: =AVERAGE(AL7) -> 1.037037 | AR7: =AVERAGE(AM7,AO7) -> 1 | AS7: {=_xlfn.IFS(AF7>'“主要目标”数据分表'!$C$2,1,AF7='“主要目标”数据分表'!$C$2,0,AF7<'“主要目标”数据分表'!$C$2,-1)} -> -1 | AT7: {=_xlfn.IFS(AG7>'“主要目标”数据分表'!$D$2,1,AG7='“主要目标”数据分表'!$D$2,0,AG7<'“主要目标”数据分表'!$D$2,-1)} -> 1 | AU7: {=_xlfn.IFS(AH7>'“主要目标”数据分表'!$E$2,1,AH7='“主要目标”数据分表'!$E$2,0,AH7<'“主要目标”数据分表'!$E$2,-1)} -> 0 | AV7: {=_xlfn.IFS(AI7>'“主要目标”数据分表'!$F$2,1,AI7='“主要目标”数据分表'!$F$2,0,AI7<'“主要目标”数据分表'!$F$2,-1)} -> 0 | AW7: {=_xlfn.IFS(AJ7>'“主要目标”数据分表'!$G$2,1,AJ7='“主要目标”数据分表'!$G$2,0,AJ7<'“主要目标”数据分表'!$G$2,-1)} -> 0
A8: 1 | B8: 北京 | C8: 2022 | D8: 6896.89 | E8: 7715.7245 | F8: 41610.9 | G8: 0.1657472 | H8: =(G8-G7)/G7 -> -0.060399487 | I8: 0.49718448 | J8: =(I8-I7)/I7 -> 0.10971023 | K8: 0.18542556 | L8: =(K8-K7)/K7 -> -0.0678151 | M8: 1 | N8: 0 | O8: 1 | P8: 0.75759066 | Q8: 0.49120235 | R8: 0.1919221 | S8: 1.1 | T8: -0.03 | U8: 0.51785714 | V8: 0.24380165 | W8: 0.85714286 | X8: 0 | Y8: 0.35300316 | Z8: 0.13763137 | AA8: 0.31428571 | AB8: -0.01744186 | AC8: 0.41857143 | AD8: 0.26063706 | AE8: 1 | AF8: 0.144 | AG8: 0.14 | AH8: 0.18 | AI8: 0.25 | AJ8: 0.65 | AK8: 0.72 | AL8: 1.037037 | AM8: 1 | AN8: 1 | AO8: 1 | AP8: =AVERAGE(AK8,AN8) -> 0.86 | AQ8: =AVERAGE(AL8) -> 1.037037 | AR8: =AVERAGE(AM8,AO8) -> 1 | AS8: {=_xlfn.IFS(AF8>'“主要目标”数据分表'!$C$2,1,AF8='“主要目标”数据分表'!$C$2,0,AF8<'“主要目标”数据分表'!$C$2,-1)} -> -1 | AT8: {=_xlfn.IFS(AG8>'“主要目标”数据分表'!$D$2,1,AG8='“主要目标”数据分表'!$D$2,0,AG8<'“主要目标”数据分表'!$D$2,-1)} -> 1 | AU8: {=_xlfn.IFS(AH8>'“主要目标”数据分表'!$E$2,1,AH8='“主要目标”数据分表'!$E$2,0,AH8<'“主要目标”数据分表'!$E$2,-1)} -> 0 | AV8: {=_xlfn.IFS(AI8>'“主要目标”数据分表'!$F$2,1,AI8='“主要目标”数据分表'!$F$2,0,AI8<'“主要目标”数据分表'!$F$2,-1)} -> 0 | AW8: {=_xlfn.IFS(AJ8>'“主要目标”数据分表'!$G$2,1,AJ8='“主要目标”数据分表'!$G$2,0,AJ8<'“主要目标”数据分表'!$G$2,-1)} -> 0
A9: 1 | B9: 北京 | C9: 2023 | D9: 7571.35 | E9: 8227.266 | F9: 43760.7 | G9: 0.17301711 | H9: =(G9-G8)/G8 -> 0.043861481 | K9: 0.18800581 | L9: =(K9-K8)/K8 -> 0.013915294 | M9: 1 | N9: 1 | O9: 1 | P9: 0.75759066 | Q9: 0.49120235 | R9: 0.1919221 | S9: 1.1 | T9: -0.03 | U9: 0.51785714 | V9: 0.24380165 | W9: 0.85714286 | X9: 0 | Y9: 0.35300316 | Z9: 0.13763137 | AA9: 0.31428571 | AB9: -0.01744186 | AC9: 0.41857143 | AD9: 0.26063706 | AE9: 1 | AF9: 0.144 | AG9: 0.14 | AH9: 0.18 | AI9: 0.25 | AJ9: 0.65 | AK9: 0.72 | AL9: 1.037037 | AM9: 1 | AN9: 1 | AO9: 1 | AP9: =AVERAGE(AK9,AN9) -> 0.86 | AQ9: =AVERAGE(AL9) -> 1.037037 | AR9: =AVERAGE(AM9,AO9) -> 1 | AS9: {=_xlfn.IFS(AF9>'“主要目标”数据分表'!$C$2,1,AF9='“主要目标”数据分表'!$C$2,0,AF9<'“主要目标”数据分表'!$C$2,-1)} -> -1 | AT9: {=_xlfn.IFS(AG9>'“主要目标”数据分表'!$D$2,1,AG9='“主要目标”数据分表'!$D$2,0,AG9<'“主要目标”数据分表'!$D$2,-1)} -> 1 | AU9: {=_xlfn.IFS(AH9>'“主要目标”数据分表'!$E$2,1,AH9='“主要目标”数据分表'!$E$2,0,AH9<'“主要目标”数据分表'!$E$2,-1)} -> 0 | AV9: {=_xlfn.IFS(AI9>'“主要目标”数据分表'!$F$2,1,AI9='“主要目标”数据分表'!$F$2,0,AI9<'“主要目标”数据分表'!$F$2,-1)} -> 0 | AW9: {=_xlfn.IFS(AJ9>'“主要目标”数据分表'!$G$2,1,AJ9='“主要目标”数据分表'!$G$2,0,AJ9<'“主要目标”数据分表'!$G$2,-1)} -> 0
A10: 2 | B10: 天津 | C10: 2016 | D10: 8078 | E10: 12475.773 | F10: 17885.39 | G10: 0.45165356 | I10: 0.31494388 | K10: 0.69753988 | M10: 0 | N10: 0 | O10: 1 | P10: 0.83038969 | Q10: 1.3914956 | R10: 1.3944648 | S10: 2.5 | T10: 1.72 | U10: 1.2372014 | V10: 0.79904306 | W10: 0.33505155 | X10: =(P10-MIN(P:P))/(MAX(P:P)-MIN(P:P)) -> 0.30031447 | Y10: {=Q10/MAX(ABS(Q$2:Q$26))} -> 1 | Z10: {=R10/MAX(ABS(R$2:R$26))} -> 1 | AA10: {=S10/MAX(ABS(S$2:S$26))} -> 0.86206897 | AB10: {=T10/MAX(ABS(T$2:T$26))} -> 1 | AC10: {=U10/MAX(ABS(U$2:U$26))} -> 1 | AD10: {=V10/MAX(ABS(V$2:V$26))} -> 1 | AE10: {=W10/MAX(ABS(W$2:W$26))} -> 0.39089347 | AF10: 0.117 | AG10: 0.135 | AH10: 0.18 | AI10: 0.16 | AJ10: 0.65 | AK10: 0.585 | AL10: 1 | AM10: 1 | AN10: 0.64 | AO10: 1 | AP10: =AVERAGE(AK10,AN10) -> 0.6125 | AQ10: =AVERAGE(AL10) -> 1 | AR10: =AVERAGE(AM10,AO10) -> 1 | AS10: {=_xlfn.IFS(AF10>'“主要目标”数据分表'!$C$2,1,AF10='“主要目标”数据分表'!$C$2,0,AF10<'“主要目标”数据分表'!$C$2,-1)} -> -1 | AT10: {=_xlfn.IFS(AG10>'“主要目标”数据分表'!$D$2,1,AG10='“主要目标”数据分表'!$D$2,0,AG10<'“主要目标”数据分表'!$D$2,-1)} -> 0 | AU10: {=_xlfn.IFS(AH10>'“主要目标”数据分表'!$E$2,1,AH10='“主要目标”数据分表'!$E$2,0,AH10<'“主要目标”数据分表'!$E$2,-1)} -> 0 | AV10: {=_xlfn.IFS(AI10>'“主要目标”数据分表'!$F$2,1,AI10='“主要目标”数据分表'!$F$2,0,AI10<'“主要目标”数据分表'!$F$2,-1)} -> -1 | AW10: {=_xlfn.IFS(AJ10>'“主要目标”数据分表'!$G$2,1,AJ10='“主要目标”数据分表'!$G$2,0,AJ10<'“主要目标”数据分表'!$G$2,-1)} -> 0
A11: 2 | B11: 天津 | C11: 2017 | D11: 7832 | E11: 12589.065 | F11: 18549.19 | G11: 0.42222868 | H11: =(G11-G10)/G10 -> -0.06514922 | I11: 0.33162627 | J11: =(I11-I10)/I10 -> 0.052969385 | K11: 0.67868544 | L11: =(K11-K10)/K10 -> -0.027029909 | M11: 0 | N11: 0 | O11: 1 | P11: 0.83038969 | Q11: 1.3914956 | R11: 1.3944648 | S11: 2.5 | T11: 1.72 | U11: 1.2372014 | V11: 0.79904306 | W11: 0.33505155 | X11: =(P11-MIN(P:P))/(MAX(P:P)-MIN(P:P)) -> 0.30031447 | Y11: {=Q11/MAX(ABS(Q$2:Q$26))} -> 1 | Z11: {=R11/MAX(ABS(R$2:R$26))} -> 1 | AA11: {=S11/MAX(ABS(S$2:S$26))} -> 0.86206897 | AB11: {=T11/MAX(ABS(T$2:T$26))} -> 1 | AC11: {=U11/MAX(ABS(U$2:U$26))} -> 1 | AD11: {=V11/MAX(ABS(V$2:V$26))} -> 1 | AE11: {=W11/MAX(ABS(W$2:W$26))} -> 0.39089347 | AF11: 0.117 | AG11: 0.135 | AH11: 0.18 | AI11: 0.16 | AJ11: 0.65 | AK11: 0.585 | AL11: 1 | AM11: 1 | AN11: 0.64 | AO11: 1 | AP11: =AVERAGE(AK11,AN11) -> 0.6125 | AQ11: =AVERAGE(AL11) -> 1 | AR11: =AVERAGE(AM11,AO11) -> 1 | AS11: {=_xlfn.IFS(AF11>'“主要目标”数据分表'!$C$2,1,AF11='“主要目标”数据分表'!$C$2,0,AF11<'“主要目标”数据分表'!$C$2,-1)} -> -1 | AT11: {=_xlfn.IFS(AG11>'“主要目标”数据分表'!$D$2,1,AG11='“主要目标”数据分表'!$D$2,0,AG11<'“主要目标”数据分表'!$D$2,-1)} -> 0 | AU11: {=_xlfn.IFS(AH11>'“主要目标”数据分表'!$E$2,1,AH11='“主要目标”数据分表'!$E$2,0,AH11<'“主要目标”数据分表'!$E$2,-1)} -> 0 | AV11: {=_xlfn.IFS(AI11>'“主要目标”数据分表'!$F$2,1,AI11='“主要目标”数据分表'!$F$2,0,AI11<'“主要目标”数据分表'!$F$2,-1)} -> -1 | AW11: {=_xlfn.IFS(AJ11>'“主要目标”数据分表'!$G$2,1,AJ11='“主要目标”数据分表'!$G$2,0,AJ11<'“主要目标”数据分表'!$G$2,-1)} -> 0
A12: 2 | B12: 天津 | C12: 2018 | D12: 7973 | E12: 13632.001 | F12: 18809.64 | G12: 0.42387839 | H12: =(G12-G11)/G11 -> 0.0039071594 | I12: 0.34692661 | J12: =(I12-I11)/I11 -> 0.046137301 | K12: 0.7247348 | L12: =(K12-K11)/K11 -> 0.067850805 | M12: 0 | N12: 0 | O12: 1 | P12: 0.83038969 | Q12: 1.3914956 | R12: 1.3944648 | S12: 2.5 | T12: 1.72 | U12: 1.2372014 | V12: 0.79904306 | W12: 0.33505155 | X12: =(P12-MIN(P:P))/(MAX(P:P)-MIN(P:P)) -> 0.30031447 | Y12: {=Q12/MAX(ABS(Q$2:Q$26))} -> 1 | Z12: {=R12/MAX(ABS(R$2:R$26))} -> 1 | AA12: {=S12/MAX(ABS(S$2:S$26))} -> 0.86206897 | AB12: {=T12/MAX(ABS(T$2:T$26))} -> 1 | AC12: {=U12/MAX(ABS(U$2:U$26))} -> 1 | AD12: {=V12/MAX(ABS(V$2:V$26))} -> 1 | AE12: {=W12/MAX(ABS(W$2:W$26))} -> 0.39089347 | AF12: 0.117 | AG12: 0.135 | AH12: 0.18 | AI12: 0.16 | AJ12: 0.65 | AK12: 0.585 | AL12: 1 | AM12: 1 | AN12: 0.64 | AO12: 1 | AP12: =AVERAGE(AK12,AN12) -> 0.6125 | AQ12: =AVERAGE(AL12) -> 1 | AR12: =AVERAGE(AM12,AO12) -> 1 | AS12: {=_xlfn.IFS(AF12>'“主要目标”数据分表'!$C$2,1,AF12='“主要目标”数据分表'!$C$2,0,AF12<'“主要目标”数据分表'!$C$2,-1)} -> -1 | AT12: {=_xlfn.IFS(AG12>'“主要目标”数据分表'!$D$2,1,AG12='“主要目标”数据分表'!$D$2,0,AG12<'“主要目标”数据分表'!$D$2,-1)} -> 0 | AU12: {=_xlfn.IFS(AH12>'“主要目标”数据分表'!$E$2,1,AH12='“主要目标”数据分表'!$E$2,0,AH12<'“主要目标”数据分表'!$E$2,-1)} -> 0 | AV12: {=_xlfn.IFS(AI12>'“主要目标”数据分表'!$F$2,1,AI12='“主要目标”数据分表'!$F$2,0,AI12<'“主要目标”数据分表'!$F$2,-1)} -> -1 | AW12: {=_xlfn.IFS(AJ12>'“主要目标”数据分表'!$G$2,1,AJ12='“主要目标”数据分表'!$G$2,0,AJ12<'“主要目标”数据分表'!$G$2,-1)} -> 0
A13: 2 | B13: 天津 | C13: 2019 | D13: 8241 | E13: 14204.096 | F13: 14104.28 | G13: 0.58429073 | H13: =(G13-G12)/G12 -> 0.37843951 | I13: 0.35395048 | J13: =(I13-I12)/I12 -> 0.020245993 | K13: 1.007077 | L13: =(K13-K12)/K12 -> 0.38958007 | M13: 0 | N13: 0 | O13: 1 | P13: 0.83038969 | Q13: 1.3914956 | R13: 1.3944648 | S13: 2.5 | T13: 1.72 | U13: 1.2372014 | V13: 0.79904306 | W13: 0.33505155 | X13: =(P13-MIN(P:P))/(MAX(P:P)-MIN(P:P)) -> 0.30031447 | Y13: {=Q13/MAX(ABS(Q$2:Q$26))} -> 1 | Z13: {=R13/MAX(ABS(R$2:R$26))} -> 1 | AA13: {=S13/MAX(ABS(S$2:S$26))} -> 0.86206897 | AB13: {=T13/MAX(ABS(T$2:T$26))} -> 1 | AC13: {=U13/MAX(ABS(U$2:U$26))} -> 1 | AD13: {=V13/MAX(ABS(V$2:V$26))} -> 1 | AE13: {=W13/MAX(ABS(W$2:W$26))} -> 0.39089347 | AF13: 0.117 | AG13: 0.135 | AH13: 0.18 | AI13: 0.16 | AJ13: 0.65 | AK13: 0.585 | AL13: 1 | AM13: 1 | AN13: 0.64 | AO13: 1 | AP13: =AVERAGE(AK13,AN13) -> 0.6125 | AQ13: =AVERAGE(AL13) -> 1 | AR13: =AVERAGE(AM13,AO13) -> 1 | AS13: {=_xlfn.IFS(AF13>'“主要目标”数据分表'!$C$2,1,AF13='“主要目标”数据分表'!$C$2,0,AF13<'“主要目标”数据分表'!$C$2,-1)} -> -1 | AT13: {=_xlfn.IFS(AG13>'“主要目标”数据分表'!$D$2,1,AG13='“主要目标”数据分表'!$D$2,0,AG13<'“主要目标”数据分表'!$D$2,-1)} -> 0 | AU13: {=_xlfn.IFS(AH13>'“主要目标”数据分表'!$E$2,1,AH13='“主要目标”数据分表'!$E$2,0,AH13<'“主要目标”数据分表'!$E$2,-1)} -> 0 | AV13: {=_xlfn.IFS(AI13>'“主要目标”数据分表'!$F$2,1,AI13='“主要目标”数据分表'!$F$2,0,AI13<'“主要目标”数据分表'!$F$2,-1)} -> -1 | AW13: {=_xlfn.IFS(AJ13>'“主要目标”数据分表'!$G$2,1,AJ13='“主要目标”数据分表'!$G$2,0,AJ13<'“主要目标”数据分表'!$G$2,-1)} -> 0
A14: 2 | B14: 天津 | C14: 2020 | D14: 8104.6 | E14: 13993.579 | F14: 14083.73 | G14: 0.57545835 | H14: =(G14-G13)/G13 -> -0.01511641 | I14: 0.36016632 | J14: =(I14-I13)/I13 -> 0.017561309 | K14: 0.9935989 | L14: =(K14-K13)/K13 -> -0.013383414 | M14: 0 | N14: 0 | O14: 1 | P14: 0.83038969 | Q14: 1.3914956 | R14: 1.3944648 | S14: 2.5 | T14: 1.72 | U14: 1.2372014 | V14: 0.79904306 | W14: 0.33505155 | X14: =(P14-MIN(P:P))/(MAX(P:P)-MIN(P:P)) -> 0.30031447 | Y14: {=Q14/MAX(ABS(Q$2:Q$26))} -> 1 | Z14: {=R14/MAX(ABS(R$2:R$26))} -> 1 | AA14: {=S14/MAX(ABS(S$2:S$26))} -> 0.86206897 | AB14: {=T14/MAX(ABS(T$2:T$26))} -> 1 | AC14: {=U14/MAX(ABS(U$2:U$26))} -> 1 | AD14: {=V14/MAX(ABS(V$2:V$26))} -> 1 | AE14: {=W14/MAX(ABS(W$2:W$26))} -> 0.39089347 | AF14: 0.117 | AG14: 0.135 | AH14: 0.18 | AI14: 0.16 | AJ14: 0.65 | AK14: 0.585 | AL14: 1 | AM14: 1 | AN14: 0.64 | AO14: 1 | AP14: =AVERAGE(AK14,AN14) -> 0.6125 | AQ14: =AVERAGE(AL14) -> 1 | AR14: =AVERAGE(AM14,AO14) -> 1 | AS14: {=_xlfn.IFS(AF14>'“主要目标”数据分表'!$C$2,1,AF14='“主要目标”数据分表'!$C$2,0,AF14<'“主要目标”数据分表'!$C$2,-1)} -> -1 | AT14: {=_xlfn.IFS(AG14>'“主要目标”数据分表'!$D$2,1,AG14='“主要目标”数据分表'!$D$2,0,AG14<'“主要目标”数据分表'!$D$2,-1)} -> 0 | AU14: {=_xlfn.IFS(AH14>'“主要目标”数据分表'!$E$2,1,AH14='“主要目标”数据分表'!$E$2,0,AH14<'“主要目标”数据分表'!$E$2,-1)} -> 0 | AV14: {=_xlfn.IFS(AI14>'“主要目标”数据分表'!$F$2,1,AI14='“主要目标”数据分表'!$F$2,0,AI14<'“主要目标”数据分表'!$F$2,-1)} -> -1 | AW14: {=_xlfn.IFS(AJ14>'“主要目标”数据分表'!$G$2,1,AJ14='“主要目标”数据分表'!$G$2,0,AJ14<'“主要目标”数据分表'!$G$2,-1)} -> 0
A15: 2 | B15: 天津 | C15: 2021 | D15: 8205.69 | E15: 14483.594 | F15: 15695.046 | G15: 0.52282039 | H15: =(G15-G14)/G14 -> -0.091471357 | I15: 0.35929797 | J15: =(I15-I14)/I14 -> -0.0024109645 | K15: 0.92281311 | L15: =(K15-K14)/K14 -> -0.071241818 | M15: 0 | N15: 0 | O15: 1 | P15: 0.83038969 | Q15: 1.3914956 | R15: 1.3944648 | S15: 2.5 | T15: 1.72 | U15: 1.2372014 | V15: 0.79904306 | W15: 0.33505155 | X15: =(P15-MIN(P:P))/(MAX(P:P)-MIN(P:P)) -> 0.30031447 | Y15: {=Q15/MAX(ABS(Q$2:Q$26))} -> 1 | Z15: {=R15/MAX(ABS(R$2:R$26))} -> 1 | AA15: {=S15/MAX(ABS(S$2:S$26))} -> 0.86206897 | AB15: {=T15/MAX(ABS(T$2:T$26))} -> 1 | AC15: {=U15/MAX(ABS(U$2:U$26))} -> 1 | AD15: {=V15/MAX(ABS(V$2:V$26))} -> 1 | AE15: {=W15/MAX(ABS(W$2:W$26))} -> 0.39089347 | AF15: 0.117 | AG15: 0.135 | AH15: 0.18 | AI15: 0.16 | AJ15: 0.65 | AK15: 0.585 | AL15: 1 | AM15: 1 | AN15: 0.64 | AO15: 1 | AP15: =AVERAGE(AK15,AN15) -> 0.6125 | AQ15: =AVERAGE(AL15) -> 1 | AR15: =AVERAGE(AM15,AO15) -> 1 | AS15: {=_xlfn.IFS(AF15>'“主要目标”数据分表'!$C$2,1,AF15='“主要目标”数据分表'!$C$2,0,AF15<'“主要目标”数据分表'!$C$2,-1)} -> -1 | AT15: {=_xlfn.IFS(AG15>'“主要目标”数据分表'!$D$2,1,AG15='“主要目标”数据分表'!$D$2,0,AG15<'“主要目标”数据分表'!$D$2,-1)} -> 0 | AU15: {=_xlfn.IFS(AH15>'“主要目标”数据分表'!$E$2,1,AH15='“主要目标”数据分表'!$E$2,0,AH15<'“主要目标”数据分表'!$E$2,-1)} -> 0 | AV15: {=_xlfn.IFS(AI15>'“主要目标”数据分表'!$F$2,1,AI15='“主要目标”数据分表'!$F$2,0,AI15<'“主要目标”数据分表'!$F$2,-1)} -> -1 | AW15: {=_xlfn.IFS(AJ15>'“主要目标”数据分表'!$G$2,1,AJ15='“主要目标”数据分表'!$G$2,0,AJ15<'“主要目标”数据分表'!$G$2,-1)} -> 0
A16: 2 | B16: 天津 | C16: 2022 | D16: 8121.77 | E16: 14301.85 | F16: 16311.3 | G16: 0.49792291 | H16: =(G16-G15)/G15 -> -0.047621478 | I16: 0.39162797 | J16: =(I16-I15)/I15 -> 0.089981019 | K16: 0.87680625 | L16: =(K16-K15)/K15 -> -0.049855008 | M16: 1 | N16: 0 | O16: 1 | P16: 0.83038969 | Q16: 1.3914956 | R16: 1.3944648 | S16: 2.5 | T16: 1.72 | U16: 1.2372014 | V16: 0.79904306 | W16: 0.33505155 | X16: =(P16-MIN(P:P))/(MAX(P:P)-MIN(P:P)) -> 0.30031447 | Y16: {=Q16/MAX(ABS(Q$2:Q$26))} -> 1 | Z16: {=R16/MAX(ABS(R$2:R$26))} -> 1 | AA16: {=S16/MAX(ABS(S$2:S$26))} -> 0.86206897 | AB16: {=T16/MAX(ABS(T$2:T$26))} -> 1 | AC16: {=U16/MAX(ABS(U$2:U$26))} -> 1 | AD16: {=V16/MAX(ABS(V$2:V$26))} -> 1 | AE16: {=W16/MAX(ABS(W$2:W$26))} -> 0.39089347 | AF16: 0.117 | AG16: 0.135 | AH16: 0.18 | AI16: 0.16 | AJ16: 0.65 | AK16: 0.585 | AL16: 1 | AM16: 1 | AN16: 0.64 | AO16: 1 | AP16: =AVERAGE(AK16,AN16) -> 0.6125 | AQ16: =AVERAGE(AL16) -> 1 | AR16: =AVERAGE(AM16,AO16) -> 1 | AS16: {=_xlfn.IFS(AF16>'“主要目标”数据分表'!$C$2,1,AF16='“主要目标”数据分表'!$C$2,0,AF16<'“主要目标”数据分表'!$C$2,-1)} -> -1 | AT16: {=_xlfn.IFS(AG16>'“主要目标”数据分表'!$D$2,1,AG16='“主要目标”数据分表'!$D$2,0,AG16<'“主要目标”数据分表'!$D$2,-1)} -> 0 | AU16: {=_xlfn.IFS(AH16>'“主要目标”数据分表'!$E$2,1,AH16='“主要目标”数据分表'!$E$2,0,AH16<'“主要目标”数据分表'!$E$2,-1)} -> 0 | AV16: {=_xlfn.IFS(AI16>'“主要目标”数据分表'!$F$2,1,AI16='“主要目标”数据分表'!$F$2,0,AI16<'“主要目标”数据分表'!$F$2,-1)} -> -1 | AW16: {=_xlfn.IFS(AJ16>'“主要目标”数据分表'!$G$2,1,AJ16='“主要目标”数据分表'!$G$2,0,AJ16<'“主要目标”数据分表'!$G$2,-1)} -> 0
A17: 2 | B17: 天津 | C17: 2023 | D17: 8493.12 | E17: 15167.833 | F17: 16737.3 | G17: 0.50743668 | H17: =(G17-G16)/G16 -> 0.019106915 | K17: 0.90622935 | L17: =(K17-K16)/K16 -> 0.033557127 | M17: 1 | N17: 1 | O17: 1 | P17: 0.83038969 | Q17: 1.3914956 | R17: 1.3944648 | S17: 2.5 | T17: 1.72 | U17: 1.2372014 | V17: 0.79904306 | W17: 0.33505155 | X17: =(P17-MIN(P:P))/(MAX(P:P)-MIN(P:P)) -> 0.30031447 | Y17: {=Q17/MAX(ABS(Q$2:Q$26))} -> 1 | Z17: {=R17/MAX(ABS(R$2:R$26))} -> 1 | AA17: {=S17/MAX(ABS(S$2:S$26))} -> 0.86206897 | AB17: {=T17/MAX(ABS(T$2:T$26))} -> 1 | AC17: {=U17/MAX(ABS(U$2:U$26))} -> 1 | AD17: {=V17/MAX(ABS(V$2:V$26))} -> 1 | AE17: {=W17/MAX(ABS(W$2:W$26))} -> 0.39089347 | AF17: 0.117 | AG17: 0.135 | AH17: 0.18 | AI17: 0.16 | AJ17: 0.65 | AK17: 0.585 | AL17: 1 | AM17: 1 | AN17: 0.64 | AO17: 1 | AP17: =AVERAGE(AK17,AN17) -> 0.6125 | AQ17: =AVERAGE(AL17) -> 1 | AR17: =AVERAGE(AM17,AO17) -> 1 | AS17: {=_xlfn.IFS(AF17>'“主要目标”数据分表'!$C$2,1,AF17='“主要目标”数据分表'!$C$2,0,AF17<'“主要目标”数据分表'!$C$2,-1)} -> -1 | AT17: {=_xlfn.IFS(AG17>'“主要目标”数据分表'!$D$2,1,AG17='“主要目标”数据分表'!$D$2,0,AG17<'“主要目标”数据分表'!$D$2,-1)} -> 0 | AU17: {=_xlfn.IFS(AH17>'“主要目标”数据分表'!$E$2,1,AH17='“主要目标”数据分表'!$E$2,0,AH17<'“主要目标”数据分表'!$E$2,-1)} -> 0 | AV17: {=_xlfn.IFS(AI17>'“主要目标”数据分表'!$F$2,1,AI17='“主要目标”数据分表'!$F$2,0,AI17<'“主要目标”数据分表'!$F$2,-1)} -> -1 | AW17: {=_xlfn.IFS(AJ17>'“主要目标”数据分表'!$G$2,1,AJ17='“主要目标”数据分表'!$G$2,0,AJ17<'“主要目标”数据分表'!$G$2,-1)} -> 0
A18: 3 | B18: 河北 | C18: 2016 | D18: 31458 | E18: 74877.961 | F18: 32070.45 | G18: 0.98090298 | I18: 0.22307135 | K18: 2.3347961 | M18: 0 | N18: 0 | O18: 1 | P18: 0.86522324 | Q18: 0.032258065 | R18: -0.22026952 | S18: 1.3 | T18: -0.16 | U18: -0.03514377 | V18: -0.052 | W18: -0.1294964 | X18: 0.44401167 | Y18: 0.023182297 | Z18: -0.1579599 | AA18: 0.37142857 | AB18: -0.093023256 | AC18: -0.028405861 | AD18: -0.055590793 | AE18: -0.15107914 | AF18: 0.13 | AG18: 0.135 | AH18: 0.18 | AI18: 0.19 | AJ18: 0.65 | AK18: 0.65 | AL18: 1 | AM18: 1 | AN18: 0.76 | AO18: 1 | AP18: =AVERAGE(AK18,AN18) -> 0.705 | AQ18: =AVERAGE(AL18) -> 1 | AR18: =AVERAGE(AM18,AO18) -> 1 | AS18: {=_xlfn.IFS(AF18>'“主要目标”数据分表'!$C$2,1,AF18='“主要目标”数据分表'!$C$2,0,AF18<'“主要目标”数据分表'!$C$2,-1)} -> -1 | AT18: {=_xlfn.IFS(AG18>'“主要目标”数据分表'!$D$2,1,AG18='“主要目标”数据分表'!$D$2,0,AG18<'“主要目标”数据分表'!$D$2,-1)} -> 0 | AU18: {=_xlfn.IFS(AH18>'“主要目标”数据分表'!$E$2,1,AH18='“主要目标”数据分表'!$E$2,0,AH18<'“主要目标”数据分表'!$E$2,-1)} -> 0 | AV18: {=_xlfn.IFS(AI18>'“主要目标”数据分表'!$F$2,1,AI18='“主要目标”数据分表'!$F$2,0,AI18<'“主要目标”数据分表'!$F$2,-1)} -> -1 | AW18: {=_xlfn.IFS(AJ18>'“主要目标”数据分表'!$G$2,1,AJ18='“主要目标”数据分表'!$G$2,0,AJ18<'“主要目标”数据分表'!$G$2,-1)} -> 0
A19: 3 | B19: 河北 | C19: 2017 | D19: 32083 | E19: 75443.372 | F19: 34016.32 | G19: 0.94316493 | H19: =(G19-G18)/G18 -> -0.038472768 | I19: 0.24563241 | J19: =(I19-I18)/I18 -> 0.1011383 | K19: 2.2178581 | L19: =(K19-K18)/K18 -> -0.050084873 | M19: 0 | N19: 0 | O19: 1 | P19: 0.86522324 | Q19: 0.032258065 | R19: -0.22026952 | S19: 1.3 | T19: -0.16 | U19: -0.03514377 | V19: -0.052 | W19: -0.1294964 | X19: 0.44401167 | Y19: 0.023182297 | Z19: -0.1579599 | AA19: 0.37142857 | AB19: -0.093023256 | AC19: -0.028405861 | AD19: -0.055590793 | AE19: -0.15107914 | AF19: 0.13 | AG19: 0.135 | AH19: 0.18 | AI19: 0.19 | AJ19: 0.65 | AK19: 0.65 | AL19: 1 | AM19: 1 | AN19: 0.76 | AO19: 1 | AP19: =AVERAGE(AK19,AN19) -> 0.705 | AQ19: =AVERAGE(AL19) -> 1 | AR19: =AVERAGE(AM19,AO19) -> 1 | AS19: {=_xlfn.IFS(AF19>'“主要目标”数据分表'!$C$2,1,AF19='“主要目标”数据分表'!$C$2,0,AF19<'“主要目标”数据分表'!$C$2,-1)} -> -1 | AT19: {=_xlfn.IFS(AG19>'“主要目标”数据分表'!$D$2,1,AG19='“主要目标”数据分表'!$D$2,0,AG19<'“主要目标”数据分表'!$D$2,-1)} -> 0 | AU19: {=_xlfn.IFS(AH19>'“主要目标”数据分表'!$E$2,1,AH19='“主要目标”数据分表'!$E$2,0,AH19<'“主要目标”数据分表'!$E$2,-1)} -> 0 | AV19: {=_xlfn.IFS(AI19>'“主要目标”数据分表'!$F$2,1,AI19='“主要目标”数据分表'!$F$2,0,AI19<'“主要目标”数据分表'!$F$2,-1)} -> -1 | AW19: {=_xlfn.IFS(AJ19>'“主要目标”数据分表'!$G$2,1,AJ19='“主要目标”数据分表'!$G$2,0,AJ19<'“主要目标”数据分表'!$G$2,-1)} -> 0
A20: 3 | B20: 河北 | C20: 2018 | D20: 32185 | E20: 79620.28 | F20: 36010.27 | G20: 0.8937728 | H20: =(G20-G19)/G19 -> -0.052368491 | I20: 0.28301301 | J20: =(I20-I19)/I19 -> 0.15218106 | K20: 2.2110437 | L20: =(K20-K19)/K19 -> -0.0030725317 | M20: 0 | N20: 0 | O20: 1 | P20: 0.86522324 | Q20: 0.032258065 | R20: -0.22026952 | S20: 1.3 | T20: -0.16 | U20: -0.03514377 | V20: -0.052 | W20: -0.1294964 | X20: 0.44401167 | Y20: 0.023182297 | Z20: -0.1579599 | AA20: 0.37142857 | AB20: -0.093023256 | AC20: -0.028405861 | AD20: -0.055590793 | AE20: -0.15107914 | AF20: 0.13 | AG20: 0.135 | AH20: 0.18 | AI20: 0.19 | AJ20: 0.65 | AK20: 0.65 | AL20: 1 | AM20: 1 | AN20: 0.76 | AO20: 1 | AP20: =AVERAGE(AK20,AN20) -> 0.705 | AQ20: =AVERAGE(AL20) -> 1 | AR20: =AVERAGE(AM20,AO20) -> 1 | AS20: {=_xlfn.IFS(AF20>'“主要目标”数据分表'!$C$2,1,AF20='“主要目标”数据分表'!$C$2,0,AF20<'“主要目标”数据分表'!$C$2,-1)} -> -1 | AT20: {=_xlfn.IFS(AG20>'“主要目标”数据分表'!$D$2,1,AG20='“主要目标”数据分表'!$D$2,0,AG20<'“主要目标”数据分表'!$D$2,-1)} -> 0 | AU20: {=_xlfn.IFS(AH20>'“主要目标”数据分表'!$E$2,1,AH20='“主要目标”数据分表'!$E$2,0,AH20<'“主要目标”数据分表'!$E$2,-1)} -> 0 | AV20: {=_xlfn.IFS(AI20>'“主要目标”数据分表'!$F$2,1,AI20='“主要目标”数据分表'!$F$2,0,AI20<'“主要目标”数据分表'!$F$2,-1)} -> -1 | AW20: {=_xlfn.IFS(AJ20>'“主要目标”数据分表'!$G$2,1,AJ20='“主要目标”数据分表'!$G$2,0,AJ20<'“主要目标”数据分表'!$G$2,-1)} -> 0
A21: 3 | B21: 河北 | C21: 2019 | D21: 32545 | E21: 82819.72 | F21: 35104.52 | G21: 0.92708859 | H21: =(G21-G20)/G20 -> 0.037275454 | I21: 0.26492564 | J21: =(I21-I20)/I20 -> -0.063910033 | K21: 2.3592324 | L21: =(K21-K20)/K20 -> 0.067022053 | M21: 0 | N21: 0 | O21: 1 | P21: 0.86522324 | Q21: 0.032258065 | R21: -0.22026952 | S21: 1.3 | T21: -0.16 | U21: -0.03514377 | V21: -0.052 | W21: -0.1294964 | X21: 0.44401167 | Y21: 0.023182297 | Z21: -0.1579599 | AA21: 0.37142857 | AB21: -0.093023256 | AC21: -0.028405861 | AD21: -0.055590793 | AE21: -0.15107914 | AF21: 0.13 | AG21: 0.135 | AH21: 0.18 | AI21: 0.19 | AJ21: 0.65 | AK21: 0.65 | AL21: 1 | AM21: 1 | AN21: 0.76 | AO21: 1 | AP21: =AVERAGE(AK21,AN21) -> 0.705 | AQ21: =AVERAGE(AL21) -> 1 | AR21: =AVERAGE(AM21,AO21) -> 1 | AS21: {=_xlfn.IFS(AF21>'“主要目标”数据分表'!$C$2,1,AF21='“主要目标”数据分表'!$C$2,0,AF21<'“主要目标”数据分表'!$C$2,-1)} -> -1 | AT21: {=_xlfn.IFS(AG21>'“主要目标”数据分表'!$D$2,1,AG21='“主要目标”数据分表'!$D$2,0,AG21<'“主要目标”数据分表'!$D$2,-1)} -> 0 | AU21: {=_xlfn.IFS(AH21>'“主要目标”数据分表'!$E$2,1,AH21='“主要目标”数据分表'!$E$2,0,AH21<'“主要目标”数据分表'!$E$2,-1)} -> 0 | AV21: {=_xlfn.IFS(AI21>'“主要目标”数据分表'!$F$2,1,AI21='“主要目标”数据分表'!$F$2,0,AI21<'“主要目标”数据分表'!$F$2,-1)} -> -1 | AW21: {=_xlfn.IFS(AJ21>'“主要目标”数据分表'!$G$2,1,AJ21='“主要目标”数据分表'!$G$2,0,AJ21<'“主要目标”数据分表'!$G$2,-1)} -> 0
A22: 3 | B22: 河北 | C22: 2020 | D22: 32782.76 | E22: 82674.329 | F22: 36206.89 | G22: 0.90542877 | H22: =(G22-G21)/G21 -> -0.023363267 | I22: 0.27888529 | J22: =(I22-I21)/I21 -> 0.052692731 | K22: 2.2833866 | L22: =(K22-K21)/K21 -> -0.03214848 | M22: 0 | N22: 0 | O22: 1 | P22: 0.86522324 | Q22: 0.032258065 | R22: -0.22026952 | S22: 1.3 | T22: -0.16 | U22: -0.03514377 | V22: -0.052 | W22: -0.1294964 | X22: 0.44401167 | Y22: 0.023182297 | Z22: -0.1579599 | AA22: 0.37142857 | AB22: -0.093023256 | AC22: -0.028405861 | AD22: -0.055590793 | AE22: -0.15107914 | AF22: 0.13 | AG22: 0.135 | AH22: 0.18 | AI22: 0.19 | AJ22: 0.65 | AK22: 0.65 | AL22: 1 | AM22: 1 | AN22: 0.76 | AO22: 1 | AP22: =AVERAGE(AK22,AN22) -> 0.705 | AQ22: =AVERAGE(AL22) -> 1 | AR22: =AVERAGE(AM22,AO22) -> 1 | AS22: {=_xlfn.IFS(AF22>'“主要目标”数据分表'!$C$2,1,AF22='“主要目标”数据分表'!$C$2,0,AF22<'“主要目标”数据分表'!$C$2,-1)} -> -1 | AT22: {=_xlfn.IFS(AG22>'“主要目标”数据分表'!$D$2,1,AG22='“主要目标”数据分表'!$D$2,0,AG22<'“主要目标”数据分表'!$D$2,-1)} -> 0 | AU22: {=_xlfn.IFS(AH22>'“主要目标”数据分表'!$E$2,1,AH22='“主要目标”数据分表'!$E$2,0,AH22<'“主要目标”数据分表'!$E$2,-1)} -> 0 | AV22: {=_xlfn.IFS(AI22>'“主要目标”数据分表'!$F$2,1,AI22='“主要目标”数据分表'!$F$2,0,AI22<'“主要目标”数据分表'!$F$2,-1)} -> -1 | AW22: {=_xlfn.IFS(AJ22>'“主要目标”数据分表'!$G$2,1,AJ22='“主要目标”数据分表'!$G$2,0,AJ22<'“主要目标”数据分表'!$G$2,-1)} -> 0
A23: 3 | B23: 河北 | C23: 2021 | D23: 33085.852 | E23: 82061.505 | F23: 40391.27 | G23: 0.81913373 | H23: =(G23-G22)/G22 -> -0.095308486 | I23: 0.31943668 | J23: =(I23-I22)/I22 -> 0.14540525 | K23: 2.0316644 | L23: =(K23-K22)/K22 -> -0.11024075 | M23: 0 | N23: 0 | O23: 1 | P23: 0.86522324 | Q23: 0.032258065 | R23: -0.22026952 | S23: 1.3 | T23: -0.16 | U23: -0.03514377 | V23: -0.052 | W23: -0.1294964 | X23: 0.44401167 | Y23: 0.023182297 | Z23: -0.1579599 | AA23: 0.37142857 | AB23: -0.093023256 | AC23: -0.028405861 | AD23: -0.055590793 | AE23: -0.15107914 | AF23: 0.13 | AG23: 0.135 | AH23: 0.18 | AI23: 0.19 | AJ23: 0.65 | AK23: 0.65 | AL23: 1 | AM23: 1 | AN23: 0.76 | AO23: 1 | AP23: =AVERAGE(AK23,AN23) -> 0.705 | AQ23: =AVERAGE(AL23) -> 1 | AR23: =AVERAGE(AM23,AO23) -> 1 | AS23: {=_xlfn.IFS(AF23>'“主要目标”数据分表'!$C$2,1,AF23='“主要目标”数据分表'!$C$2,0,AF23<'“主要目标”数据分表'!$C$2,-1)} -> -1 | AT23: {=_xlfn.IFS(AG23>'“主要目标”数据分表'!$D$2,1,AG23='“主要目标”数据分表'!$D$2,0,AG23<'“主要目标”数据分表'!$D$2,-1)} -> 0 | AU23: {=_xlfn.IFS(AH23>'“主要目标”数据分表'!$E$2,1,AH23='“主要目标”数据分表'!$E$2,0,AH23<'“主要目标”数据分表'!$E$2,-1)} -> 0 | AV23: {=_xlfn.IFS(AI23>'“主要目标”数据分表'!$F$2,1,AI23='“主要目标”数据分表'!$F$2,0,AI23<'“主要目标”数据分表'!$F$2,-1)} -> -1 | AW23: {=_xlfn.IFS(AJ23>'“主要目标”数据分表'!$G$2,1,AJ23='“主要目标”数据分表'!$G$2,0,AJ23<'“主要目标”数据分表'!$G$2,-1)} -> 0
A24: 3 | B24: 河北 | C24: 2022 | D24: 32538.48 | E24: 78668.402 | F24: 42370.4 | G24: 0.7679531 | H24: =(G24-G23)/G23 -> -0.062481408 | I24: 0.32134809 | J24: =(I24-I23)/I23 -> 0.0059836922 | K24: 1.856683 | L24: =(K24-K23)/K23 -> -0.086127107 | M24: 1 | N24: 0 | O24: 1 | P24: 0.86522324 | Q24: 0.032258065 | R24: -0.22026952 | S24: 1.3 | T24: -0.16 | U24: -0.03514377 | V24: -0.052 | W24: -0.1294964 | X24: 0.44401167 | Y24: 0.023182297 | Z24: -0.1579599 | AA24: 0.37142857 | AB24: -0.093023256 | AC24: -0.028405861 | AD24: -0.055590793 | AE24: -0.15107914 | AF24: 0.13 | AG24: 0.135 | AH24: 0.18 | AI24: 0.19 | AJ24: 0.65 | AK24: 0.65 | AL24: 1 | AM24: 1 | AN24: 0.76 | AO24: 1 | AP24: =AVERAGE(AK24,AN24) -> 0.705 | AQ24: =AVERAGE(AL24) -> 1 | AR24: =AVERAGE(AM24,AO24) -> 1 | AS24: {=_xlfn.IFS(AF24>'“主要目标”数据分表'!$C$2,1,AF24='“主要目标”数据分表'!$C$2,0,AF24<'“主要目标”数据分表'!$C$2,-1)} -> -1 | AT24: {=_xlfn.IFS(AG24>'“主要目标”数据分表'!$D$2,1,AG24='“主要目标”数据分表'!$D$2,0,AG24<'“主要目标”数据分表'!$D$2,-1)} -> 0 | AU24: {=_xlfn.IFS(AH24>'“主要目标”数据分表'!$E$2,1,AH24='“主要目标”数据分表'!$E$2,0,AH24<'“主要目标”数据分表'!$E$2,-1)} -> 0 | AV24: {=_xlfn.IFS(AI24>'“主要目标”数据分表'!$F$2,1,AI24='“主要目标”数据分表'!$F$2,0,AI24<'“主要目标”数据分表'!$F$2,-1)} -> -1 | AW24: {=_xlfn.IFS(AJ24>'“主要目标”数据分表'!$G$2,1,AJ24='“主要目标”数据分表'!$G$2,0,AJ24<'“主要目标”数据分表'!$G$2,-1)} -> 0
A25: 3 | B25: 河北 | C25: 2023 | D25: 33615.32 | E25: 81030.319 | F25: 43944.1 | G25: 0.76495639 | H25: =(G25-G24)/G24 -> -0.0039022065 | K25: 1.8439408 | L25: =(K25-K24)/K24 -> -0.0068628902 | M25: 1 | N25: 1 | O25: 1 | P25: 0.86522324 | Q25: 0.032258065 | R25: -0.22026952 | S25: 1.3 | T25: -0.16 | U25: -0.03514377 | V25: -0.052 | W25: -0.1294964 | X25: 0.44401167 | Y25: 0.023182297 | Z25: -0.1579599 | AA25: 0.37142857 | AB25: -0.093023256 | AC25: -0.028405861 | AD25: -0.055590793 | AE25: -0.15107914 | AF25: 0.13 | AG25: 0.135 | AH25: 0.18 | AI25: 0.19 | AJ25: 0.65 | AK25: 0.65 | AL25: 1 | AM25: 1 | AN25: 0.76 | AO25: 1 | AP25: =AVERAGE(AK25,AN25) -> 0.705 | AQ25: =AVERAGE(AL25) -> 1 | AR25: =AVERAGE(AM25,AO25) -> 1 | AS25: {=_xlfn.IFS(AF25>'“主要目标”数据分表'!$C$2,1,AF25='“主要目标”数据分表'!$C$2,0,AF25<'“主要目标”数据分表'!$C$2,-1)} -> -1 | AT25: {=_xlfn.IFS(AG25>'“主要目标”数据分表'!$D$2,1,AG25='“主要目标”数据分表'!$D$2,0,AG25<'“主要目标”数据分表'!$D$2,-1)} -> 0 | AU25: {=_xlfn.IFS(AH25>'“主要目标”数据分表'!$E$2,1,AH25='“主要目标”数据分表'!$E$2,0,AH25<'“主要目标”数据分表'!$E$2,-1)} -> 0 | AV25: {=_xlfn.IFS(AI25>'“主要目标”数据分表'!$F$2,1,AI25='“主要目标”数据分表'!$F$2,0,AI25<'“主要目标”数据分表'!$F$2,-1)} -> -1 | AW25: {=_xlfn.IFS(AJ25>'“主要目标”数据分表'!$G$2,1,AJ25='“主要目标”数据分表'!$G$2,0,AJ25<'“主要目标”数据分表'!$G$2,-1)} -> 0
A26: 4 | B26: 山西 | C26: 2016 | D26: 18974 | E26: 50115.142 | F26: 13050.41 | G26: 1.4539007 | I26: 0.24061153 | K26: 3.8401201 | M26: 0 | N26: 0 | O26: 1 | P26: 0.83606886 | Q26: 0.81818182 | R26: 0.63020121 | S26: 2.9 | T26: 0.82 | U26: 0.47260274 | V26: 0.39013453 | W26: 0.091743119 | X26: 0.32374247 | Y26: 0.58798736 | Z26: 0.45193052 | AA26: 0.82857143 | AB26: 0.47674419 | AC26: 0.38199339 | AD26: 0.41707477 | AE26: 0.10703364 | AF26: 0.12 | AG26: 0.135 | AH26: 0.18 | AI26: 0.18 | AJ26: 0.65 | AK26: 0.6 | AL26: 1 | AM26: 1 | AN26: 0.72 | AO26: 1 | AP26: =AVERAGE(AK26,AN26) -> 0.66 | AQ26: =AVERAGE(AL26) -> 1 | AR26: =AVERAGE(AM26,AO26) -> 1 | AS26: {=_xlfn.IFS(AF26>'“主要目标”数据分表'!$C$2,1,AF26='“主要目标”数据分表'!$C$2,0,AF26<'“主要目标”数据分表'!$C$2,-1)} -> -1 | AT26: {=_xlfn.IFS(AG26>'“主要目标”数据分表'!$D$2,1,AG26='“主要目标”数据分表'!$D$2,0,AG26<'“主要目标”数据分表'!$D$2,-1)} -> 0 | AU26: {=_xlfn.IFS(AH26>'“主要目标”数据分表'!$E$2,1,AH26='“主要目标”数据分表'!$E$2,0,AH26<'“主要目标”数据分表'!$E$2,-1)} -> 0 | AV26: {=_xlfn.IFS(AI26>'“主要目标”数据分表'!$F$2,1,AI26='“主要目标”数据分表'!$F$2,0,AI26<'“主要目标”数据分表'!$F$2,-1)} -> -1 | AW26: {=_xlfn.IFS(AJ26>'“主要目标”数据分表'!$G$2,1,AJ26='“主要目标”数据分表'!$G$2,0,AJ26<'“主要目标”数据分表'!$G$2,-1)} -> 0
A27: 4 | B27: 山西 | C27: 2017 | D27: 19581 | E27: 50653.639 | F27: 15528.42 | G27: 1.2609783 | H27: =(G27-G26)/G26 -> -0.13269299 | I27: 0.26312939 | J27: =(I27-I26)/I26 -> 0.093585968 | K27: 3.2619957 | L27: =(K27-K26)/K26 -> -0.15054853 | M27: 0 | N27: 0 | O27: 1 | P27: 0.83606886 | Q27: 0.81818182 | R27: 0.63020121 | S27: 2.9 | T27: 0.82 | U27: 0.47260274 | V27: 0.39013453 | W27: 0.091743119 | X27: 0.32374247 | Y27: 0.58798736 | Z27: 0.45193052 | AA27: 0.82857143 | AB27: 0.47674419 | AC27: 0.38199339 | AD27: 0.41707477 | AE27: 0.10703364 | AF27: 0.12 | AG27: 0.135 | AH27: 0.18 | AI27: 0.18 | AJ27: 0.65 | AK27: 0.6 | AL27: 1 | AM27: 1 | AN27: 0.72 | AO27: 1 | AP27: =AVERAGE(AK27,AN27) -> 0.66 | AQ27: =AVERAGE(AL27) -> 1 | AR27: =AVERAGE(AM27,AO27) -> 1 | AS27: {=_xlfn.IFS(AF27>'“主要目标”数据分表'!$C$2,1,AF27='“主要目标”数据分表'!$C$2,0,AF27<'“主要目标”数据分表'!$C$2,-1)} -> -1 | AT27: {=_xlfn.IFS(AG27>'“主要目标”数据分表'!$D$2,1,AG27='“主要目标”数据分表'!$D$2,0,AG27<'“主要目标”数据分表'!$D$2,-1)} -> 0 | AU27: {=_xlfn.IFS(AH27>'“主要目标”数据分表'!$E$2,1,AH27='“主要目标”数据分表'!$E$2,0,AH27<'“主要目标”数据分表'!$E$2,-1)} -> 0 | AV27: {=_xlfn.IFS(AI27>'“主要目标”数据分表'!$F$2,1,AI27='“主要目标”数据分表'!$F$2,0,AI27<'“主要目标”数据分表'!$F$2,-1)} -> -1 | AW27: {=_xlfn.IFS(AJ27>'“主要目标”数据分表'!$G$2,1,AJ27='“主要目标”数据分表'!$G$2,0,AJ27<'“主要目标”数据分表'!$G$2,-1)} -> 0
A28: 4 | B28: 山西 | C28: 2018 | D28: 20199 | E28: 52257.304 | F28: 16818.11 | G28: 1.2010268 | H28: =(G28-G27)/G27 -> -0.047543649 | I28: 0.29171652 | J28: =(I28-I27)/I27 -> 0.10864285 | K28: 3.1072043 | L28: =(K28-K27)/K27 -> -0.047452958 | M28: 0 | N28: 0 | O28: 1 | P28: 0.83606886 | Q28: 0.81818182 | R28: 0.63020121 | S28: 2.9 | T28: 0.82 | U28: 0.47260274 | V28: 0.39013453 | W28: 0.091743119 | X28: 0.32374247 | Y28: 0.58798736 | Z28: 0.45193052 | AA28: 0.82857143 | AB28: 0.47674419 | AC28: 0.38199339 | AD28: 0.41707477 | AE28: 0.10703364 | AF28: 0.12 | AG28: 0.135 | AH28: 0.18 | AI28: 0.18 | AJ28: 0.65 | AK28: 0.6 | AL28: 1 | AM28: 1 | AN28: 0.72 | AO28: 1 | AP28: =AVERAGE(AK28,AN28) -> 0.66 | AQ28: =AVERAGE(AL28) -> 1 | AR28: =AVERAGE(AM28,AO28) -> 1 | AS28: {=_xlfn.IFS(AF28>'“主要目标”数据分表'!$C$2,1,AF28='“主要目标”数据分表'!$C$2,0,AF28<'“主要目标”数据分表'!$C$2,-1)} -> -1 | AT28: {=_xlfn.IFS(AG28>'“主要目标”数据分表'!$D$2,1,AG28='“主要目标”数据分表'!$D$2,0,AG28<'“主要目标”数据分表'!$D$2,-1)} -> 0 | AU28: {=_xlfn.IFS(AH28>'“主要目标”数据分表'!$E$2,1,AH28='“主要目标”数据分表'!$E$2,0,AH28<'“主要目标”数据分表'!$E$2,-1)} -> 0 | AV28: {=_xlfn.IFS(AI28>'“主要目标”数据分表'!$F$2,1,AI28='“主要目标”数据分表'!$F$2,0,AI28<'“主要目标”数据分表'!$F$2,-1)} -> -1 | AW28: {=_xlfn.IFS(AJ28>'“主要目标”数据分表'!$G$2,1,AJ28='“主要目标”数据分表'!$G$2,0,AJ28<'“主要目标”数据分表'!$G$2,-1)} -> 0
A29: 4 | B29: 山西 | C29: 2019 | D29: 20859 | E29: 52940.152 | F29: 17026.68 | G29: 1.2250773 | H29: =(G29-G28)/G28 -> 0.020025032 | I29: 0.29011884 | J29: =(I29-I28)/I28 -> -0.0054768283 | K29: 3.1092469 | L29: =(K29-K28)/K28 -> 0.0006573652 | M29: 0 | N29: 0 | O29: 1 | P29: 0.83606886 | Q29: 0.81818182 | R29: 0.63020121 | S29: 2.9 | T29: 0.82 | U29: 0.47260274 | V29: 0.39013453 | W29: 0.091743119 | X29: 0.32374247 | Y29: 0.58798736 | Z29: 0.45193052 | AA29: 0.82857143 | AB29: 0.47674419 | AC29: 0.38199339 | AD29: 0.41707477 | AE29: 0.10703364 | AF29: 0.12 | AG29: 0.135 | AH29: 0.18 | AI29: 0.18 | AJ29: 0.65 | AK29: 0.6 | AL29: 1 | AM29: 1 | AN29: 0.72 | AO29: 1 | AP29: =AVERAGE(AK29,AN29) -> 0.66 | AQ29: =AVERAGE(AL29) -> 1 | AR29: =AVERAGE(AM29,AO29) -> 1 | AS29: {=_xlfn.IFS(AF29>'“主要目标”数据分表'!$C$2,1,AF29='“主要目标”数据分表'!$C$2,0,AF29<'“主要目标”数据分表'!$C$2,-1)} -> -1 | AT29: {=_xlfn.IFS(AG29>'“主要目标”数据分表'!$D$2,1,AG29='“主要目标”数据分表'!$D$2,0,AG29<'“主要目标”数据分表'!$D$2,-1)} -> 0 | AU29: {=_xlfn.IFS(AH29>'“主要目标”数据分表'!$E$2,1,AH29='“主要目标”数据分表'!$E$2,0,AH29<'“主要目标”数据分表'!$E$2,-1)} -> 0 | AV29: {=_xlfn.IFS(AI29>'“主要目标”数据分表'!$F$2,1,AI29='“主要目标”数据分表'!$F$2,0,AI29<'“主要目标”数据分表'!$F$2,-1)} -> -1 | AW29: {=_xlfn.IFS(AJ29>'“主要目标”数据分表'!$G$2,1,AJ29='“主要目标”数据分表'!$G$2,0,AJ29<'“主要目标”数据分表'!$G$2,-1)} -> 0
A30: 4 | B30: 山西 | C30: 2020 | D30: 20980.55 | E30: 53023.822 | F30: 17651.93 | G30: 1.1885697 | H30: =(G30-G29)/G29 -> -0.029800241 | I30: 0.30115491 | J30: =(I30-I29)/I29 -> 0.038039843 | K30: 3.0038541 | L30: =(K30-K29)/K29 -> -0.033896568 | M30: 0 | N30: 0 | O30: 1 | P30: 0.83606886 | Q30: 0.81818182 | R30: 0.63020121 | S30: 2.9 | T30: 0.82 | U30: 0.47260274 | V30: 0.39013453 | W30: 0.091743119 | X30: 0.32374247 | Y30: 0.58798736 | Z30: 0.45193052 | AA30: 0.82857143 | AB30: 0.47674419 | AC30: 0.38199339 | AD30: 0.41707477 | AE30: 0.10703364 | AF30: 0.12 | AG30: 0.135 | AH30: 0.18 | AI30: 0.18 | AJ30: 0.65 | AK30: 0.6 | AL30: 1 | AM30: 1 | AN30: 0.72 | AO30: 1 | AP30: =AVERAGE(AK30,AN30) -> 0.66 | AQ30: =AVERAGE(AL30) -> 1 | AR30: =AVERAGE(AM30,AO30) -> 1 | AS30: {=_xlfn.IFS(AF30>'“主要目标”数据分表'!$C$2,1,AF30='“主要目标”数据分表'!$C$2,0,AF30<'“主要目标”数据分表'!$C$2,-1)} -> -1 | AT30: {=_xlfn.IFS(AG30>'“主要目标”数据分表'!$D$2,1,AG30='“主要目标”数据分表'!$D$2,0,AG30<'“主要目标”数据分表'!$D$2,-1)} -> 0 | AU30: {=_xlfn.IFS(AH30>'“主要目标”数据分表'!$E$2,1,AH30='“主要目标”数据分表'!$E$2,0,AH30<'“主要目标”数据分表'!$E$2,-1)} -> 0 | AV30: {=_xlfn.IFS(AI30>'“主要目标”数据分表'!$F$2,1,AI30='“主要目标”数据分表'!$F$2,0,AI30<'“主要目标”数据分表'!$F$2,-1)} -> -1 | AW30: {=_xlfn.IFS(AJ30>'“主要目标”数据分表'!$G$2,1,AJ30='“主要目标”数据分表'!$G$2,0,AJ30<'“主要目标”数据分表'!$G$2,-1)} -> 0
A31: 4 | B31: 山西 | C31: 2021 | D31: 21643.94 | E31: 57900.73 | F31: 22590.161 | G31: 0.95811359 | H31: =(G31-G30)/G30 -> -0.19389368 | I31: 0.30944368 | J31: =(I31-I30)/I30 -> 0.027523269 | K31: 2.5630951 | L31: =(K31-K30)/K30 -> -0.14673117 | M31: 0 | N31: 0 | O31: 1 | P31: 0.83606886 | Q31: 0.81818182 | R31: 0.63020121 | S31: 2.9 | T31: 0.82 | U31: 0.47260274 | V31: 0.39013453 | W31: 0.091743119 | X31: 0.32374247 | Y31: 0.58798736 | Z31: 0.45193052 | AA31: 0.82857143 | AB31: 0.47674419 | AC31: 0.38199339 | AD31: 0.41707477 | AE31: 0.10703364 | AF31: 0.12 | AG31: 0.135 | AH31: 0.18 | AI31: 0.18 | AJ31: 0.65 | AK31: 0.6 | AL31: 1 | AM31: 1 | AN31: 0.72 | AO31: 1 | AP31: =AVERAGE(AK31,AN31) -> 0.66 | AQ31: =AVERAGE(AL31) -> 1 | AR31: =AVERAGE(AM31,AO31) -> 1 | AS31: {=_xlfn.IFS(AF31>'“主要目标”数据分表'!$C$2,1,AF31='“主要目标”数据分表'!$C$2,0,AF31<'“主要目标”数据分表'!$C$2,-1)} -> -1 | AT31: {=_xlfn.IFS(AG31>'“主要目标”数据分表'!$D$2,1,AG31='“主要目标”数据分表'!$D$2,0,AG31<'“主要目标”数据分表'!$D$2,-1)} -> 0 | AU31: {=_xlfn.IFS(AH31>'“主要目标”数据分表'!$E$2,1,AH31='“主要目标”数据分表'!$E$2,0,AH31<'“主要目标”数据分表'!$E$2,-1)} -> 0 | AV31: {=_xlfn.IFS(AI31>'“主要目标”数据分表'!$F$2,1,AI31='“主要目标”数据分表'!$F$2,0,AI31<'“主要目标”数据分表'!$F$2,-1)} -> -1 | AW31: {=_xlfn.IFS(AJ31>'“主要目标”数据分表'!$G$2,1,AJ31='“主要目标”数据分表'!$G$2,0,AJ31<'“主要目标”数据分表'!$G$2,-1)} -> 0
A32: 4 | B32: 山西 | C32: 2022 | D32: 21918.5 | E32: 58957.834 | F32: 25642.6 | G32: 0.85476902 | H32: =(G32-G31)/G31 -> -0.10786255 | I32: 0.376648 | J32: =(I32-I31)/I31 -> 0.21717787 | K32: 2.2992143 | L32: =(K32-K31)/K31 -> -0.10295393 | M32: 1 | N32: 0 | O32: 1 | P32: 0.83606886 | Q32: 0.81818182 | R32: 0.63020121 | S32: 2.9 | T32: 0.82 | U32: 0.47260274 | V32: 0.39013453 | W32: 0.091743119 | X32: 0.32374247 | Y32: 0.58798736 | Z32: 0.45193052 | AA32: 0.82857143 | AB32: 0.47674419 | AC32: 0.38199339 | AD32: 0.41707477 | AE32: 0.10703364 | AF32: 0.12 | AG32: 0.135 | AH32: 0.18 | AI32: 0.18 | AJ32: 0.65 | AK32: 0.6 | AL32: 1 | AM32: 1 | AN32: 0.72 | AO32: 1 | AP32: =AVERAGE(AK32,AN32) -> 0.66 | AQ32: =AVERAGE(AL32) -> 1 | AR32: =AVERAGE(AM32,AO32) -> 1 | AS32: {=_xlfn.IFS(AF32>'“主要目标”数据分表'!$C$2,1,AF32='“主要目标”数据分表'!$C$2,0,AF32<'“主要目标”数据分表'!$C$2,-1)} -> -1 | AT32: {=_xlfn.IFS(AG32>'“主要目标”数据分表'!$D$2,1,AG32='“主要目标”数据分表'!$D$2,0,AG32<'“主要目标”数据分表'!$D$2,-1)} -> 0 | AU32: {=_xlfn.IFS(AH32>'“主要目标”数据分表'!$E$2,1,AH32='“主要目标”数据分表'!$E$2,0,AH32<'“主要目标”数据分表'!$E$2,-1)} -> 0 | AV32: {=_xlfn.IFS(AI32>'“主要目标”数据分表'!$F$2,1,AI32='“主要目标”数据分表'!$F$2,0,AI32<'“主要目标”数据分表'!$F$2,-1)} -> -1 | AW32: {=_xlfn.IFS(AJ32>'“主要目标”数据分表'!$G$2,1,AJ32='“主要目标”数据分表'!$G$2,0,AJ32<'“主要目标”数据分表'!$G$2,-1)} -> 0
A33: 4 | B33: 山西 | C33: 2023 | D33: 8426.28 | E33: 62909.476 | F33: 25698.184 | G33: 0.32789398 | H33: =(G33-G32)/G32 -> -0.61639464 | K33: 2.4480125 | L33: =(K33-K32)/K32 -> 0.064716948 | M33: 1 | N33: 1 | O33: 1 | P33: 0.83606886 | Q33: 0.81818182 | R33: 0.63020121 | S33: 2.9 | T33: 0.82 | U33: 0.47260274 | V33: 0.39013453 | W33: 0.091743119 | X33: 0.32374247 | Y33: 0.58798736 | Z33: 0.45193052 | AA33: 0.82857143 | AB33: 0.47674419 | AC33: 0.38199339 | AD33: 0.41707477 | AE33: 0.10703364 | AF33: 0.12 | AG33: 0.135 | AH33: 0.18 | AI33: 0.18 | AJ33: 0.65 | AK33: 0.6 | AL33: 1 | AM33: 1 | AN33: 0.72 | AO33: 1 | AP33: =AVERAGE(AK33,AN33) -> 0.66 | AQ33: =AVERAGE(AL33) -> 1 | AR33: =AVERAGE(AM33,AO33) -> 1 | AS33: {=_xlfn.IFS(AF33>'“主要目标”数据分表'!$C$2,1,AF33='“主要目标”数据分表'!$C$2,0,AF33<'“主要目标”数据分表'!$C$2,-1)} -> -1 | AT33: {=_xlfn.IFS(AG33>'“主要目标”数据分表'!$D$2,1,AG33='“主要目标”数据分表'!$D$2,0,AG33<'“主要目标”数据分表'!$D$2,-1)} -> 0 | AU33: {=_xlfn.IFS(AH33>'“主要目标”数据分表'!$E$2,1,AH33='“主要目标”数据分表'!$E$2,0,AH33<'“主要目标”数据分表'!$E$2,-1)} -> 0 | AV33: {=_xlfn.IFS(AI33>'“主要目标”数据分表'!$F$2,1,AI33='“主要目标”数据分表'!$F$2,0,AI33<'“主要目标”数据分表'!$F$2,-1)} -> -1 | AW33: {=_xlfn.IFS(AJ33>'“主要目标”数据分表'!$G$2,1,AJ33='“主要目标”数据分表'!$G$2,0,AJ33<'“主要目标”数据分表'!$G$2,-1)} -> 0
A34: 5 | B34: 内蒙古 | C34: 2016 | D34: 19310 | E34: 54592.2 | F34: 18128.1 | G34: 1.0651971 | I34: 0.32668048 | K34: 3.0114684 | M34: 0 | N34: 0 | O34: 1 | P34: 0.82466688 | Q34: -0.76539589 | R34: -0.99324524 | S34: 1.9 | T34: -0.6 | U34: -0.87123746 | V34: -0.9354067 | W34: -0.56914894 | X34: 0.27670642 | Y34: -0.55005269 | Z34: -0.71227702 | AA34: 0.54285714 | AB34: -0.34883721 | AC34: -0.70420021 | AD34: -1 | AE34: -0.66400709 | AF34: 0.18 | AG34: 0.135 | AH34: 0.18 | AI34: 0.25 | AJ34: 0.65 | AK34: 0.9 | AL34: 1 | AM34: 1 | AN34: 1 | AO34: 1 | AP34: =AVERAGE(AK34,AN34) -> 0.95 | AQ34: =AVERAGE(AL34) -> 1 | AR34: =AVERAGE(AM34,AO34) -> 1 | AS34: {=_xlfn.IFS(AF34>'“主要目标”数据分表'!$C$2,1,AF34='“主要目标”数据分表'!$C$2,0,AF34<'“主要目标”数据分表'!$C$2,-1)} -> -1 | AT34: {=_xlfn.IFS(AG34>'“主要目标”数据分表'!$D$2,1,AG34='“主要目标”数据分表'!$D$2,0,AG34<'“主要目标”数据分表'!$D$2,-1)} -> 0 | AU34: {=_xlfn.IFS(AH34>'“主要目标”数据分表'!$E$2,1,AH34='“主要目标”数据分表'!$E$2,0,AH34<'“主要目标”数据分表'!$E$2,-1)} -> 0 | AV34: {=_xlfn.IFS(AI34>'“主要目标”数据分表'!$F$2,1,AI34='“主要目标”数据分表'!$F$2,0,AI34<'“主要目标”数据分表'!$F$2,-1)} -> 0 | AW34: {=_xlfn.IFS(AJ34>'“主要目标”数据分表'!$G$2,1,AJ34='“主要目标”数据分表'!$G$2,0,AJ34<'“主要目标”数据分表'!$G$2,-1)} -> 0
A35: 5 | B35: 内蒙古 | C35: 2017 | D35: 19763 | E35: 57761.393 | F35: 16096.21 | G35: 1.2278046 | H35: =(G35-G34)/G34 -> 0.15265478 | I35: 0.35588349 | J35: =(I35-I34)/I34 -> 0.089393178 | K35: 3.5885089 | L35: =(K35-K34)/K34 -> 0.19161433 | M35: 0 | N35: 0 | O35: 1 | P35: 0.82466688 | Q35: -0.76539589 | R35: -0.99324524 | S35: 1.9 | T35: -0.6 | U35: -0.87123746 | V35: -0.9354067 | W35: -0.56914894 | X35: 0.27670642 | Y35: -0.55005269 | Z35: -0.71227702 | AA35: 0.54285714 | AB35: -0.34883721 | AC35: -0.70420021 | AD35: -1 | AE35: -0.66400709 | AF35: 0.18 | AG35: 0.135 | AH35: 0.18 | AI35: 0.25 | AJ35: 0.65 | AK35: 0.9 | AL35: 1 | AM35: 1 | AN35: 1 | AO35: 1 | AP35: =AVERAGE(AK35,AN35) -> 0.95 | AQ35: =AVERAGE(AL35) -> 1 | AR35: =AVERAGE(AM35,AO35) -> 1 | AS35: {=_xlfn.IFS(AF35>'“主要目标”数据分表'!$C$2,1,AF35='“主要目标”数据分表'!$C$2,0,AF35<'“主要目标”数据分表'!$C$2,-1)} -> -1 | AT35: {=_xlfn.IFS(AG35>'“主要目标”数据分表'!$D$2,1,AG35='“主要目标”数据分表'!$D$2,0,AG35<'“主要目标”数据分表'!$D$2,-1)} -> 0 | AU35: {=_xlfn.IFS(AH35>'“主要目标”数据分表'!$E$2,1,AH35='“主要目标”数据分表'!$E$2,0,AH35<'“主要目标”数据分表'!$E$2,-1)} -> 0 | AV35: {=_xlfn.IFS(AI35>'“主要目标”数据分表'!$F$2,1,AI35='“主要目标”数据分表'!$F$2,0,AI35<'“主要目标”数据分表'!$F$2,-1)} -> 0 | AW35: {=_xlfn.IFS(AJ35>'“主要目标”数据分表'!$G$2,1,AJ35='“主要目标”数据分表'!$G$2,0,AJ35<'“主要目标”数据分表'!$G$2,-1)} -> 0
A36: 5 | B36: 内蒙古 | C36: 2018 | D36: 23068 | E36: 60493.935 | F36: 17289.22 | G36: 1.3342418 | H36: =(G36-G35)/G35 -> 0.086689075 | I36: 0.35655925 | J36: =(I36-I35)/I35 -> 0.001898827 | K36: 3.4989395 | L36: =(K36-K35)/K35 -> -0.024960061 | M36: 0 | N36: 0 | O36: 1 | P36: 0.82466688 | Q36: -0.76539589 | R36: -0.99324524 | S36: 1.9 | T36: -0.6 | U36: -0.87123746 | V36: -0.9354067 | W36: -0.56914894 | X36: 0.27670642 | Y36: -0.55005269 | Z36: -0.71227702 | AA36: 0.54285714 | AB36: -0.34883721 | AC36: -0.70420021 | AD36: -1 | AE36: -0.66400709 | AF36: 0.18 | AG36: 0.135 | AH36: 0.18 | AI36: 0.25 | AJ36: 0.65 | AK36: 0.9 | AL36: 1 | AM36: 1 | AN36: 1 | AO36: 1 | AP36: =AVERAGE(AK36,AN36) -> 0.95 | AQ36: =AVERAGE(AL36) -> 1 | AR36: =AVERAGE(AM36,AO36) -> 1 | AS36: {=_xlfn.IFS(AF36>'“主要目标”数据分表'!$C$2,1,AF36='“主要目标”数据分表'!$C$2,0,AF36<'“主要目标”数据分表'!$C$2,-1)} -> -1 | AT36: {=_xlfn.IFS(AG36>'“主要目标”数据分表'!$D$2,1,AG36='“主要目标”数据分表'!$D$2,0,AG36<'“主要目标”数据分表'!$D$2,-1)} -> 0 | AU36: {=_xlfn.IFS(AH36>'“主要目标”数据分表'!$E$2,1,AH36='“主要目标”数据分表'!$E$2,0,AH36<'“主要目标”数据分表'!$E$2,-1)} -> 0 | AV36: {=_xlfn.IFS(AI36>'“主要目标”数据分表'!$F$2,1,AI36='“主要目标”数据分表'!$F$2,0,AI36<'“主要目标”数据分表'!$F$2,-1)} -> 0 | AW36: {=_xlfn.IFS(AJ36>'“主要目标”数据分表'!$G$2,1,AJ36='“主要目标”数据分表'!$G$2,0,AJ36<'“主要目标”数据分表'!$G$2,-1)} -> 0
A37: 5 | B37: 内蒙古 | C37: 2019 | D37: 25346 | E37: 63563.319 | F37: 17212.53 | G37: 1.4725319 | H37: =(G37-G36)/G36 -> 0.10364698 | I37: 0.3589921 | J37: =(I37-I36)/I36 -> 0.0068231288 | K37: 3.6928516 | L37: =(K37-K36)/K36 -> 0.055420261 | M37: 0 | N37: 0 | O37: 1 | P37: 0.82466688 | Q37: -0.76539589 | R37: -0.99324524 | S37: 1.9 | T37: -0.6 | U37: -0.87123746 | V37: -0.9354067 | W37: -0.56914894 | X37: 0.27670642 | Y37: -0.55005269 | Z37: -0.71227702 | AA37: 0.54285714 | AB37: -0.34883721 | AC37: -0.70420021 | AD37: -1 | AE37: -0.66400709 | AF37: 0.18 | AG37: 0.135 | AH37: 0.18 | AI37: 0.25 | AJ37: 0.65 | AK37: 0.9 | AL37: 1 | AM37: 1 | AN37: 1 | AO37: 1 | AP37: =AVERAGE(AK37,AN37) -> 0.95 | AQ37: =AVERAGE(AL37) -> 1 | AR37: =AVERAGE(AM37,AO37) -> 1 | AS37: {=_xlfn.IFS(AF37>'“主要目标”数据分表'!$C$2,1,AF37='“主要目标”数据分表'!$C$2,0,AF37<'“主要目标”数据分表'!$C$2,-1)} -> -1 | AT37: {=_xlfn.IFS(AG37>'“主要目标”数据分表'!$D$2,1,AG37='“主要目标”数据分表'!$D$2,0,AG37<'“主要目标”数据分表'!$D$2,-1)} -> 0 | AU37: {=_xlfn.IFS(AH37>'“主要目标”数据分表'!$E$2,1,AH37='“主要目标”数据分表'!$E$2,0,AH37<'“主要目标”数据分表'!$E$2,-1)} -> 0 | AV37: {=_xlfn.IFS(AI37>'“主要目标”数据分表'!$F$2,1,AI37='“主要目标”数据分表'!$F$2,0,AI37<'“主要目标”数据分表'!$F$2,-1)} -> 0 | AW37: {=_xlfn.IFS(AJ37>'“主要目标”数据分表'!$G$2,1,AJ37='“主要目标”数据分表'!$G$2,0,AJ37<'“主要目标”数据分表'!$G$2,-1)} -> 0
A38: 5 | B38: 内蒙古 | C38: 2020 | D38: 27133.65 | E38: 65228.307 | F38: 17359.82 | G38: 1.5630145 | H38: =(G38-G37)/G37 -> 0.061446919 | I38: 0.3705434 | J38: =(I38-I37)/I37 -> 0.032177052 | K38: 3.7574299 | L38: =(K38-K37)/K37 -> 0.017487369 | M38: 0 | N38: 0 | O38: 1 | P38: 0.82466688 | Q38: -0.76539589 | R38: -0.99324524 | S38: 1.9 | T38: -0.6 | U38: -0.87123746 | V38: -0.9354067 | W38: -0.56914894 | X38: 0.27670642 | Y38: -0.55005269 | Z38: -0.71227702 | AA38: 0.54285714 | AB38: -0.34883721 | AC38: -0.70420021 | AD38: -1 | AE38: -0.66400709 | AF38: 0.18 | AG38: 0.135 | AH38: 0.18 | AI38: 0.25 | AJ38: 0.65 | AK38: 0.9 | AL38: 1 | AM38: 1 | AN38: 1 | AO38: 1 | AP38: =AVERAGE(AK38,AN38) -> 0.95 | AQ38: =AVERAGE(AL38) -> 1 | AR38: =AVERAGE(AM38,AO38) -> 1 | AS38: {=_xlfn.IFS(AF38>'“主要目标”数据分表'!$C$2,1,AF38='“主要目标”数据分表'!$C$2,0,AF38<'“主要目标”数据分表'!$C$2,-1)} -> -1 | AT38: {=_xlfn.IFS(AG38>'“主要目标”数据分表'!$D$2,1,AG38='“主要目标”数据分表'!$D$2,0,AG38<'“主要目标”数据分表'!$D$2,-1)} -> 0 | AU38: {=_xlfn.IFS(AH38>'“主要目标”数据分表'!$E$2,1,AH38='“主要目标”数据分表'!$E$2,0,AH38<'“主要目标”数据分表'!$E$2,-1)} -> 0 | AV38: {=_xlfn.IFS(AI38>'“主要目标”数据分表'!$F$2,1,AI38='“主要目标”数据分表'!$F$2,0,AI38<'“主要目标”数据分表'!$F$2,-1)} -> 0 | AW38: {=_xlfn.IFS(AJ38>'“主要目标”数据分表'!$G$2,1,AJ38='“主要目标”数据分表'!$G$2,0,AJ38<'“主要目标”数据分表'!$G$2,-1)} -> 0
A39: 5 | B39: 内蒙古 | C39: 2021 | D39: 26900.46 | E39: 72847.094 | F39: 20514.195 | G39: 1.3113096 | H39: =(G39-G38)/G38 -> -0.16103811 | I39: 0.40318423 | J39: =(I39-I38)/I38 -> 0.088089082 | K39: 3.5510579 | L39: =(K39-K38)/K38 -> -0.0549237 | M39: 0 | N39: 0 | O39: 1 | P39: 0.82466688 | Q39: -0.76539589 | R39: -0.99324524 | S39: 1.9 | T39: -0.6 | U39: -0.87123746 | V39: -0.9354067 | W39: -0.56914894 | X39: 0.27670642 | Y39: -0.55005269 | Z39: -0.71227702 | AA39: 0.54285714 | AB39: -0.34883721 | AC39: -0.70420021 | AD39: -1 | AE39: -0.66400709 | AF39: 0.18 | AG39: 0.135 | AH39: 0.18 | AI39: 0.25 | AJ39: 0.65 | AK39: 0.9 | AL39: 1 | AM39: 1 | AN39: 1 | AO39: 1 | AP39: =AVERAGE(AK39,AN39) -> 0.95 | AQ39: =AVERAGE(AL39) -> 1 | AR39: =AVERAGE(AM39,AO39) -> 1 | AS39: {=_xlfn.IFS(AF39>'“主要目标”数据分表'!$C$2,1,AF39='“主要目标”数据分表'!$C$2,0,AF39<'“主要目标”数据分表'!$C$2,-1)} -> -1 | AT39: {=_xlfn.IFS(AG39>'“主要目标”数据分表'!$D$2,1,AG39='“主要目标”数据分表'!$D$2,0,AG39<'“主要目标”数据分表'!$D$2,-1)} -> 0 | AU39: {=_xlfn.IFS(AH39>'“主要目标”数据分表'!$E$2,1,AH39='“主要目标”数据分表'!$E$2,0,AH39<'“主要目标”数据分表'!$E$2,-1)} -> 0 | AV39: {=_xlfn.IFS(AI39>'“主要目标”数据分表'!$F$2,1,AI39='“主要目标”数据分表'!$F$2,0,AI39<'“主要目标”数据分表'!$F$2,-1)} -> 0 | AW39: {=_xlfn.IFS(AJ39>'“主要目标”数据分表'!$G$2,1,AJ39='“主要目标”数据分表'!$G$2,0,AJ39<'“主要目标”数据分表'!$G$2,-1)} -> 0
A40: 5 | B40: 内蒙古 | C40: 2022 | D40: 27980.98 | E40: 75702.872 | F40: 23158.6 | G40: 1.2082328 | H40: =(G40-G39)/G39 -> -0.078605987 | I40: 0.41102771 | J40: =(I40-I39)/I39 -> 0.01945382 | K40: 3.2688881 | L40: =(K40-K39)/K39 -> -0.079460777 | M40: 1 | N40: 0 | O40: 1 | P40: 0.82466688 | Q40: -0.76539589 | R40: -0.99324524 | S40: 1.9 | T40: -0.6 | U40: -0.87123746 | V40: -0.9354067 | W40: -0.56914894 | X40: 0.27670642 | Y40: -0.55005269 | Z40: -0.71227702 | AA40: 0.54285714 | AB40: -0.34883721 | AC40: -0.70420021 | AD40: -1 | AE40: -0.66400709 | AF40: 0.18 | AG40: 0.135 | AH40: 0.18 | AI40: 0.25 | AJ40: 0.65 | AK40: 0.9 | AL40: 1 | AM40: 1 | AN40: 1 | AO40: 1 | AP40: =AVERAGE(AK40,AN40) -> 0.95 | AQ40: =AVERAGE(AL40) -> 1 | AR40: =AVERAGE(AM40,AO40) -> 1 | AS40: {=_xlfn.IFS(AF40>'“主要目标”数据分表'!$C$2,1,AF40='“主要目标”数据分表'!$C$2,0,AF40<'“主要目标”数据分表'!$C$2,-1)} -> -1 | AT40: {=_xlfn.IFS(AG40>'“主要目标”数据分表'!$D$2,1,AG40='“主要目标”数据分表'!$D$2,0,AG40<'“主要目标”数据分表'!$D$2,-1)} -> 0 | AU40: {=_xlfn.IFS(AH40>'“主要目标”数据分表'!$E$2,1,AH40='“主要目标”数据分表'!$E$2,0,AH40<'“主要目标”数据分表'!$E$2,-1)} -> 0 | AV40: {=_xlfn.IFS(AI40>'“主要目标”数据分表'!$F$2,1,AI40='“主要目标”数据分表'!$F$2,0,AI40<'“主要目标”数据分表'!$F$2,-1)} -> 0 | AW40: {=_xlfn.IFS(AJ40>'“主要目标”数据分表'!$G$2,1,AJ40='“主要目标”数据分表'!$G$2,0,AJ40<'“主要目标”数据分表'!$G$2,-1)} -> 0
...

Sheet “主要目标”数据分表
A1: id | B1: 地 | C1: 非化石能源 | D1: 能耗强度 | E1: 碳排强度 | F1: 非化石能源_155 | G1: 碳排强度_155 | H1: 非化石能源（比中央） | I1: 能耗强度（比中央） | J1: 碳排强度（比中央） | K1: 非化石能源_155（比中央） | L1: 碳排强度_155（比中央）
A2: 0 | B2: 中央 | C2: 0.2 | D2: 0.135 | E2: 0.18 | F2: 0.25 | G2: 0.65 | H2: =C2/C$2 -> 1 | I2: =D2/D$2 -> 1 | J2: =E2/E$2 -> 1 | K2: =F2/F$2 -> 1 | L2: =G2/G$2 -> 1
A3: 1 | B3: 北京 | C3: 0.144 | D3: 0.14 | E3: 0.18 | F3: 0.25 | G3: 0.65 | H3: =C3/C$2 -> 0.72 | I3: =D3/D$2 -> 1.037037 | J3: =E3/E$2 -> 1 | K3: =F3/F$2 -> 1 | L3: =G3/G$2 -> 1
A4: 2 | B4: 天津 | C4: 0.117 | D4: 0.135 | E4: 0.18 | F4: 0.16 | G4: 0.65 | H4: =C4/C$2 -> 0.585 | I4: =D4/D$2 -> 1 | J4: =E4/E$2 -> 1 | K4: =F4/F$2 -> 0.64 | L4: =G4/G$2 -> 1
A5: 3 | B5: 河北 | C5: 0.13 | D5: 0.135 | E5: 0.18 | F5: 0.19 | G5: 0.65 | H5: =C5/C$2 -> 0.65 | I5: =D5/D$2 -> 1 | J5: =E5/E$2 -> 1 | K5: =F5/F$2 -> 0.76 | L5: =G5/G$2 -> 1
A6: 4 | B6: 山西 | C6: 0.12 | D6: 0.135 | E6: 0.18 | F6: 0.18 | G6: 0.65 | H6: =C6/C$2 -> 0.6 | I6: =D6/D$2 -> 1 | J6: =E6/E$2 -> 1 | K6: =F6/F$2 -> 0.72 | L6: =G6/G$2 -> 1
A7: 5 | B7: 内蒙古 | C7: 0.18 | D7: 0.135 | E7: 0.18 | F7: 0.25 | G7: 0.65 | H7: =C7/C$2 -> 0.9 | I7: =D7/D$2 -> 1 | J7: =E7/E$2 -> 1 | K7: =F7/F$2 -> 1 | L7: =G7/G$2 -> 1
A8: 6 | B8: 辽宁 | C8: 0.137 | D8: 0.145 | E8: 0.18 | F8: 0.2 | G8: 0.65 | H8: =C8/C$2 -> 0.685 | I8: =D8/D$2 -> 1.0740741 | J8: =E8/E$2 -> 1 | K8: =F8/F$2 -> 0.8 | L8: =G8/G$2 -> 1
A9: 7 | B9: 吉林 | C9: 0.177 | D9: 0.135 | E9: 0.18 | F9: 0.2 | G9: 0.65 | H9: =C9/C$2 -> 0.885 | I9: =D9/D$2 -> 1 | J9: =E9/E$2 -> 1 | K9: =F9/F$2 -> 0.8 | L9: =G9/G$2 -> 1
A10: 8 | B10: 黑龙江 | C10: 0.2 | D10: 0.135 | E10: 0.18 | F10: 0.25 | G10: 0.65 | H10: =C10/C$2 -> 1 | I10: =D10/D$2 -> 1 | J10: =E10/E$2 -> 1 | K10: =F10/F$2 -> 1 | L10: =G10/G$2 -> 1
A11: 9 | B11: 上海 | C11: 0.2 | D11: 0.14 | E11: 0.18 | F11: 0.25 | G11: 0.7 | H11: =C11/C$2 -> 1 | I11: =D11/D$2 -> 1.037037 | J11: =E11/E$2 -> 1 | K11: =F11/F$2 -> 1 | L11: =G11/G$2 -> 1.0769231
A12: 10 | B12: 江苏 | C12: 0.18 | D12: 0.14 | E12: 0.18 | F12: 0.25 | G12: 0.65 | H12: =C12/C$2 -> 0.9 | I12: =D12/D$2 -> 1.037037 | J12: =E12/E$2 -> 1 | K12: =F12/F$2 -> 1 | L12: =G12/G$2 -> 1
A13: 11 | B13: 浙江 | C13: 0.2 | D13: 0.135 | E13: 0.18 | F13: 0.25 | G13: 0.65 | H13: =C13/C$2 -> 1 | I13: =D13/D$2 -> 1 | J13: =E13/E$2 -> 1 | K13: =F13/F$2 -> 1 | L13: =G13/G$2 -> 1
... A32: 30 | B32: 新疆 | C32: 0.2 | D32: 0.135 | E32: 0.18 | F32: 0.25 | G32: 0.65 | H32: =C32/C$2 -> 1 | I32: =D32/D$2 -> 1 | J32: =E32/E$2 -> 1 | K32: =F32/F$2 -> 1 | L32: =G32/G$2 -> 1

Sheet 部分解释变量分表
B1: file | C1: avg_direct_sim | D1: avg_direct_degree | E1: avg_hidden_degree | F1: 主要目标 | G1: 主要目标_hid | H1: 70相似度 | I1: 80相似度 | J1: 90相似度 | K1: std_sim | L1: std_deg | M1: std_hid_deg | N1: std_主要目标 | O1: std_hid_主要目标 | P1: std_70 | Q1: std_80 | R1: std_90
A2: 0 | B2: 2030年前碳达峰行动方案.docx | C2: 1 | D2: 0 | E2: 0 | F2: 0 | G2: 0 | H2: 0 | I2: 0 | J2: 0 | K2: =(C2-MIN(C:C))/(MAX(C:C)-MIN(C:C)) -> 1 | L2: {=D2/MAX(ABS(D$2:D$26))} -> 0 | M2: {=E2/MAX(ABS(E$2:E$26))} -> 0 | N2: {=F2/MAX(ABS(F$2:F$26))} -> 0 | O2: {=G2/MAX(ABS(G$2:G$26))} -> 0 | P2: {=H2/MAX(ABS(H$2:H$26))} -> 0 | Q2: {=I2/MAX(ABS(I$2:I$26))} -> 0 | R2: {=J2/MAX(ABS(J$2:J$26))} -> 0
A3: 1 | B3: 北京市碳达峰实施方案.docx | C3: 0.75759066 | D3: 0.49120235 | E3: 0.1919221 | F3: 1.1 | G3: -0.03 | H3: 0.51785714 | I3: 0.24380165 | J3: 0.85714286 | K3: =(C3-MIN(C:C))/(MAX(C:C)-MIN(C:C)) -> 0 | L3: {=D3/MAX(ABS(D$2:D$26))} -> 0.35300316 | M3: {=E3/MAX(ABS(E$2:E$26))} -> 0.13763137 | N3: {=F3/MAX(ABS(F$2:F$26))} -> 0.31428571 | O3: {=G3/MAX(ABS(G$2:G$26))} -> -0.01744186 | P3: {=H3/MAX(ABS(H$2:H$26))} -> 0.41857143 | Q3: {=I3/MAX(ABS(I$2:I$26))} -> 0.26063706 | R3: {=J3/MAX(ABS(J$2:J$26))} -> 1
A4: 2 | B4: 天津市碳达峰实施方案.docx | C4: 0.83038969 | D4: 1.3914956 | E4: 1.3944648 | F4: 2.5 | G4: 1.72 | H4: 1.2372014 | I4: 0.79904306 | J4: 0.33505155 | K4: =(C4-MIN(C:C))/(MAX(C:C)-MIN(C:C)) -> 0.30031447 | L4: {=D4/MAX(ABS(D$2:D$26))} -> 1 | M4: {=E4/MAX(ABS(E$2:E$26))} -> 1 | N4: {=F4/MAX(ABS(F$2:F$26))} -> 0.71428571 | O4: {=G4/MAX(ABS(G$2:G$26))} -> 1 | P4: {=H4/MAX(ABS(H$2:H$26))} -> 1 | Q4: {=I4/MAX(ABS(I$2:I$26))} -> 0.85421995 | R4: {=J4/MAX(ABS(J$2:J$26))} -> 0.39089347
A5: 3 | B5: 河北省碳达峰实施方案.docx | C5: 0.86522324 | D5: 0.032258065 | E5: -0.22026952 | F5: 1.3 | G5: -0.16 | H5: -0.03514377 | I5: -0.052 | J5: -0.1294964 | K5: =(C5-MIN(C:C))/(MAX(C:C)-MIN(C:C)) -> 0.44401167 | L5: {=D5/MAX(ABS(D$2:D$26))} -> 0.023182297 | M5: {=E5/MAX(ABS(E$2:E$26))} -> -0.1579599 | N5: {=F5/MAX(ABS(F$2:F$26))} -> 0.37142857 | O5: {=G5/MAX(ABS(G$2:G$26))} -> -0.093023256 | P5: {=H5/MAX(ABS(H$2:H$26))} -> -0.028405861 | Q5: {=I5/MAX(ABS(I$2:I$26))} -> -0.055590793 | R5: {=J5/MAX(ABS(J$2:J$26))} -> -0.15107914
A6: 4 | B6: 山西省碳达峰实施方案.docx | C6: 0.83606886 | D6: 0.81818182 | E6: 0.63020121 | F6: 2.9 | G6: 0.82 | H6: 0.47260274 | I6: 0.39013453 | J6: 0.091743119 | K6: =(C6-MIN(C:C))/(MAX(C:C)-MIN(C:C)) -> 0.32374247 | L6: {=D6/MAX(ABS(D$2:D$26))} -> 0.58798736 | M6: {=E6/MAX(ABS(E$2:E$26))} -> 0.45193052 | N6: {=F6/MAX(ABS(F$2:F$26))} -> 0.82857143 | O6: {=G6/MAX(ABS(G$2:G$26))} -> 0.47674419 | P6: {=H6/MAX(ABS(H$2:H$26))} -> 0.38199339 | Q6: {=I6/MAX(ABS(I$2:I$26))} -> 0.41707477 | R6: {=J6/MAX(ABS(J$2:J$26))} -> 0.10703364
A7: 5 | B7: 内蒙古自治区碳达峰实施方案.docx | C7: 0.82466688 | D7: -0.76539589 | E7: -0.99324524 | F7: 1.9 | G7: -0.6 | H7: -0.87123746 | I7: -0.9354067 | J7: -0.56914894 | K7: =(C7-MIN(C:C))/(MAX(C:C)-MIN(C:C)) -> 0.27670642 | L7: {=D7/MAX(ABS(D$2:D$26))} -> -0.55005269 | M7: {=E7/MAX(ABS(E$2:E$26))} -> -0.71227702 | N7: {=F7/MAX(ABS(F$2:F$26))} -> 0.54285714 | O7: {=G7/MAX(ABS(G$2:G$26))} -> -0.34883721 | P7: {=H7/MAX(ABS(H$2:H$26))} -> -0.70420021 | Q7: {=I7/MAX(ABS(I$2:I$26))} -> -1 | R7: {=J7/MAX(ABS(J$2:J$26))} -> -0.66400709
A8: 6 | B8: 辽宁省碳达峰实施方案.docx | C8: 0.8307605 | D8: 0.85190616 | E8: 0.85626891 | F8: 3.5 | G8: 1.5 | H8: 0.65066225 | I8: 0.41855204 | J8: 0.1741573 | K8: =(C8-MIN(C:C))/(MAX(C:C)-MIN(C:C)) -> 0.30184413 | L8: {=D8/MAX(ABS(D$2:D$26))} -> 0.61222339 | M8: {=E8/MAX(ABS(E$2:E$26))} -> 0.61404842 | N8: {=F8/MAX(ABS(F$2:F$26))} -> 1 | O8: {=G8/MAX(ABS(G$2:G$26))} -> 0.87209302 | P8: {=H8/MAX(ABS(H$2:H$26))} -> 0.52591459 | Q8: {=I8/MAX(ABS(I$2:I$26))} -> 0.44745461 | R8: {=J8/MAX(ABS(J$2:J$26))} -> 0.20318352
A9: 7 | B9: 吉林省碳达峰实施方案.docx | C9: 0.84762756 | D9: 0.13196481 | E9: 0.057812573 | F9: 0.4 | G9: -0.54 | H9: 0.044728435 | I9: -0.10307018 | J9: -0.112 | K9: =(C9-MIN(C:C))/(MAX(C:C)-MIN(C:C)) -> 0.37142503 | L9: {=D9/MAX(ABS(D$2:D$26))} -> 0.09483667 | M9: {=E9/MAX(ABS(E$2:E$26))} -> 0.04145861 | N9: {=F9/MAX(ABS(F$2:F$26))} -> 0.11428571 | O9: {=G9/MAX(ABS(G$2:G$26))} -> -0.31395349 | P9: {=H9/MAX(ABS(H$2:H$26))} -> 0.036152914 | Q9: {=I9/MAX(ABS(I$2:I$26))} -> -0.11018755 | R9: {=J9/MAX(ABS(J$2:J$26))} -> -0.13066667
A10: 9 | B10: 上海市碳达峰实施方案.docx | C10: 0.82522388 | D10: 0.48093842 | E10: 0.60962854 | F10: 2.7 | G10: 0.51 | H10: 0.35084746 | I10: 0.23809524 | J10: 0.36413043 | K10: =(C10-MIN(C:C))/(MAX(C:C)-MIN(C:C)) -> 0.27900418 | L10: {=D10/MAX(ABS(D$2:D$26))} -> 0.34562698 | M10: {=E10/MAX(ABS(E$2:E$26))} -> 0.43717743 | N10: {=F10/MAX(ABS(F$2:F$26))} -> 0.77142857 | O10: {=G10/MAX(ABS(G$2:G$26))} -> 0.29651163 | P10: {=H10/MAX(ABS(H$2:H$26))} -> 0.28358153 | Q10: {=I10/MAX(ABS(I$2:I$26))} -> 0.2545366 | R10: {=J10/MAX(ABS(J$2:J$26))} -> 0.42481884
A11: 10 | B11: 江苏省碳达峰实施方案.docx | C11: 0.79737596 | D11: 0.68768328 | E11: 0.646556 | F11: 0.2 | G11: 0.08 | H11: 0.48442907 | I11: 0.34943182 | J11: 0.022222222 | K11: =(C11-MIN(C:C))/(MAX(C:C)-MIN(C:C)) -> 0.16412442 | L11: {=D11/MAX(ABS(D$2:D$26))} -> 0.49420443 | M11: {=E11/MAX(ABS(E$2:E$26))} -> 0.46365888 | N11: {=F11/MAX(ABS(F$2:F$26))} -> 0.057142857 | O11: {=G11/MAX(ABS(G$2:G$26))} -> 0.046511628 | P11: {=H11/MAX(ABS(H$2:H$26))} -> 0.39155232 | Q11: {=I11/MAX(ABS(I$2:I$26))} -> 0.37356138 | R11: {=J11/MAX(ABS(J$2:J$26))} -> 0.025925926
A12: 12 | B12: 安徽省碳达峰实施方案.docx | C12: 0.82532823 | D12: -0.021994135 | E12: -0.19511881 | F12: 1.1 | G12: -0.19 | H12: -0.042622951 | I12: -0.22906404 | J12: -0.11363636 | K12: =(C12-MIN(C:C))/(MAX(C:C)-MIN(C:C)) -> 0.27943466 | L12: {=D12/MAX(ABS(D$2:D$26))} -> -0.015806112 | M12: {=E12/MAX(ABS(E$2:E$26))} -> -0.1399238 | N12: {=F12/MAX(ABS(F$2:F$26))} -> 0.31428571 | O12: {=G12/MAX(ABS(G$2:G$26))} -> -0.11046512 | P12: {=H12/MAX(ABS(H$2:H$26))} -> -0.034451102 | Q12: {=I12/MAX(ABS(I$2:I$26))} -> -0.24488176 | R12: {=J12/MAX(ABS(J$2:J$26))} -> -0.13257576
A13: 14 | B13: 江西省碳达峰实施方案.docx | C13: 0.8371256 | D13: 0.36950147 | E13: 0.36063166 | F13: -1.2 | G13: -0.41 | H13: 0.28501629 | I13: 0.13738739 | J13: -0.15238095 | K13: =(C13-MIN(C:C))/(MAX(C:C)-MIN(C:C)) -> 0.32810177 | L13: {=D13/MAX(ABS(D$2:D$26))} -> 0.26554268 | M13: {=E13/MAX(ABS(E$2:E$26))} -> 0.25861654 | N13: {=F13/MAX(ABS(F$2:F$26))} -> -0.34285714 | O13: {=G13/MAX(ABS(G$2:G$26))} -> -0.23837209 | P13: {=H13/MAX(ABS(H$2:H$26))} -> 0.23037178 | Q13: {=I13/MAX(ABS(I$2:I$26))} -> 0.1468745 | R13: {=J13/MAX(ABS(J$2:J$26))} -> -0.17777778
