Workbook

Sheet sheet1
A1: id | B1: 地 | C1: year | D1: 能源消费总量(万吨标准煤) | E1: CO2排放总量(万吨) | F1: 生产总值（亿元） | G1: 单位GDP能耗 | H1: 单位GDP能耗增长率 | I1: 非化石能源占比 | J1: 非化石能源占比增长率 | K1: 单位GDP碳排放量 | L1: 单位GDP碳排放量增长率 | M1: post0 | N1: post1 | O1: post2 | P1: treated | Q1: avg_direct_sim | R1: avg_direct_degree | S1: avg_hidden_degree | T1: target | U1: target_hid | V1: deg70 | W1: deg80 | X1: deg90 | Y1: std_sim | Z1: std_deg | AA1: std_hid_deg | AB1: std_target | AC1: std_hid_target | AD1: std_70 | AE1: std_80 | AF1: std_90 | AG1: a145 | AH1: b145 | AI1: c145 | AJ1: a155 | AK1: c155 | AL1: std_a145 | AM1: std_b145 | AN1: std_c145 | AO1: std_a155 | AP1: std_c155 | AQ1: a | AR1: b | AS1: c | AT1: if_a | AU1: if_b | AV1: if_c | AW1: if_a_155 | AX1: if_c_155 | AY1: 工业结构 | AZ1: 城市化水平 | BA1: 人口密度 | BB1: 技术进步 | BC1: 财政自给率
A2: 1 | B2: 北京 | C2: 2016 | D2: 6917 | E2: 7413.4217 | F2: 25669.13 | G2: =D2/F2 -> 0.26946764 | I2: 0.35776976 | K2: =E2/F2 -> 0.28880689 | M2: 0 | N2: 0 | O2: 0 | P2: 1 | Q2: 0.75759066 | R2: 0.49120235 | S2: 0.1919221 | T2: 1.1 | U2: -0.03 | V2: 0.51785714 | W2: 0.24380165 | X2: 0.85714286 | Y2: 0 | Z2: 0.35300316 | AA2: 0.13763137 | AB2: 0.31428571 | AC2: -0.01744186 | AD2: 0.41857143 | AE2: 0.26063706 | AF2: 1 | AG2: 0.144 | AH2: 0.14 | AI2: 0.18 | AJ2: 0.25 | AK2: 0.65 | AL2: 0.72 | AM2: 1.037037 | AN2: 1 | AO2: 1 | AP2: 1 | AQ2: =AVERAGE(AL2,AO2) -> 0.86 | AR2: =AVERAGE(AM2) -> 1.037037 | AS2: =AVERAGE(AN2,AP2) -> 1 | AT2: {=_xlfn.IFS(AG2>sheet2!$C$2,1,AG2=sheet2!$C$2,0,AG2<sheet2!$C$2,-1)} -> -1 | AU2: {=_xlfn.IFS(AH2>sheet2!$D$2,1,AH2=sheet2!$D$2,0,AH2<sheet2!$D$2,-1)} -> 1 | AV2: {=_xlfn.IFS(AI2>sheet2!$E$2,1,AI2=sheet2!$E$2,0,AI2<sheet2!$E$2,-1)} -> 0 | AW2: {=_xlfn.IFS(AJ2>sheet2!$F$2,1,AJ2=sheet2!$F$2,0,AJ2<sheet2!$F$2,-1)} -> 0 | AX2: {=_xlfn.IFS(AK2>sheet2!$G$2,1,AK2=sheet2!$G$2,0,AK2<sheet2!$G$2,-1)} -> 0 | AY2: 0.18176697 | AZ2: 0.86742597 | BA2: 0.13379251 | BB2: 0.0099280069 | BC2: 0.79310792
A3: 1 | B3: 北京 | C3: 2017 | D3: 7088 | E3: 7623.383 | F3: 28014.94 | G3: =D3/F3 -> 0.25300786 | H3: =(G3-G2)/G2 -> -0.061082603 | I3: 0.36853608 | J3: =(I3-I2)/I2 -> 0.030092858 | K3: =E3/F3 -> 0.27211849 | L3: =(K3-K2)/K2 -> -0.057783963 | M3: 0 | N3: 0 | O3: 0 | P3: 1 | Q3: 0.75759066 | R3: 0.49120235 | S3: 0.1919221 | T3: 1.1 | U3: -0.03 | V3: 0.51785714 | W3: 0.24380165 | X3: 0.85714286 | Y3: 0 | Z3: 0.35300316 | AA3: 0.13763137 | AB3: 0.31428571 | AC3: -0.01744186 | AD3: 0.41857143 | AE3: 0.26063706 | AF3: 1 | AG3: 0.144 | AH3: 0.14 | AI3: 0.18 | AJ3: 0.25 | AK3: 0.65 | AL3: 0.72 | AM3: 1.037037 | AN3: 1 | AO3: 1 | AP3: 1 | AQ3: =AVERAGE(AL3,AO3) -> 0.86 | AR3: =AVERAGE(AM3) -> 1.037037 | AS3: =AVERAGE(AN3,AP3) -> 1 | AT3: {=_xlfn.IFS(AG3>sheet2!$C$2,1,AG3=sheet2!$C$2,0,AG3<sheet2!$C$2,-1)} -> -1 | AU3: {=_xlfn.IFS(AH3>sheet2!$D$2,1,AH3=sheet2!$D$2,0,AH3<sheet2!$D$2,-1)} -> 1 | AV3: {=_xlfn.IFS(AI3>sheet2!$E$2,1,AI3=sheet2!$E$2,0,AI3<sheet2!$E$2,-1)} -> 0 | AW3: {=_xlfn.IFS(AJ3>sheet2!$F$2,1,AJ3=sheet2!$F$2,0,AJ3<sheet2!$F$2,-1)} -> 0 | AX3: {=_xlfn.IFS(AK3>sheet2!$G$2,1,AK3=sheet2!$G$2,0,AK3<sheet2!$G$2,-1)} -> 0 | AY3: 0.18023954 | AZ3: 0.8691887 | BA3: 0.13373156 | BB3: 0.0096050572 | BC3: 0.79577495
A4: 1 | B4: 北京 | C4: 2018 | D4: 7270 | E4: 7770.4187 | F4: 30319.98 | G4: =D4/F4 -> 0.23977588 | H4: =(G4-G3)/G3 -> -0.052298674 | I4: 0.3894371 | J4: =(I4-I3)/I3 -> 0.056713642 | K4: =E4/F4 -> 0.25628047 | L4: =(K4-K3)/K3 -> -0.058202652 | M4: 0 | N4: 0 | O4: 0 | P4: 1 | Q4: 0.75759066 | R4: 0.49120235 | S4: 0.1919221 | T4: 1.1 | U4: -0.03 | V4: 0.51785714 | W4: 0.24380165 | X4: 0.85714286 | Y4: 0 | Z4: 0.35300316 | AA4: 0.13763137 | AB4: 0.31428571 | AC4: -0.01744186 | AD4: 0.41857143 | AE4: 0.26063706 | AF4: 1 | AG4: 0.144 | AH4: 0.14 | AI4: 0.18 | AJ4: 0.25 | AK4: 0.65 | AL4: 0.72 | AM4: 1.037037 | AN4: 1 | AO4: 1 | AP4: 1 | AQ4: =AVERAGE(AL4,AO4) -> 0.86 | AR4: =AVERAGE(AM4) -> 1.037037 | AS4: =AVERAGE(AN4,AP4) -> 1 | AT4: {=_xlfn.IFS(AG4>sheet2!$C$2,1,AG4=sheet2!$C$2,0,AG4<sheet2!$C$2,-1)} -> -1 | AU4: {=_xlfn.IFS(AH4>sheet2!$D$2,1,AH4=sheet2!$D$2,0,AH4<sheet2!$D$2,-1)} -> 1 | AV4: {=_xlfn.IFS(AI4>sheet2!$E$2,1,AI4=sheet2!$E$2,0,AI4<sheet2!$E$2,-1)} -> 0 | AW4: {=_xlfn.IFS(AJ4>sheet2!$F$2,1,AJ4=sheet2!$F$2,0,AJ4<sheet2!$F$2,-1)} -> 0 | AX4: {=_xlfn.IFS(AK4>sheet2!$G$2,1,AK4=sheet2!$G$2,0,AK4<sheet2!$G$2,-1)} -> 0 | AY4: 0.18065315 | AZ4: 0.87089416 | BA4: 0.13360966 | BB4: 0.009037285 | BC4: 0.77440597
A5: 1 | B5: 北京 | C5: 2019 | D5: 7360 | E5: 7804.4413 | F5: 35371.28 | G5: =D5/F5 -> 0.20807842 | H5: =(G5-G4)/G4 -> -0.13219622 | I5: 0.39378508 | J5: =(I5-I4)/I4 -> 0.011164767 | K5: =E5/F5 -> 0.22064345 | L5: =(K5-K4)/K4 -> -0.13905475 | M5: 0 | N5: 0 | O5: 0 | P5: 1 | Q5: 0.75759066 | R5: 0.49120235 | S5: 0.1919221 | T5: 1.1 | U5: -0.03 | V5: 0.51785714 | W5: 0.24380165 | X5: 0.85714286 | Y5: 0 | Z5: 0.35300316 | AA5: 0.13763137 | AB5: 0.31428571 | AC5: -0.01744186 | AD5: 0.41857143 | AE5: 0.26063706 | AF5: 1 | AG5: 0.144 | AH5: 0.14 | AI5: 0.18 | AJ5: 0.25 | AK5: 0.65 | AL5: 0.72 | AM5: 1.037037 | AN5: 1 | AO5: 1 | AP5: 1 | AQ5: =AVERAGE(AL5,AO5) -> 0.86 | AR5: =AVERAGE(AM5) -> 1.037037 | AS5: =AVERAGE(AN5,AP5) -> 1 | AT5: {=_xlfn.IFS(AG5>sheet2!$C$2,1,AG5=sheet2!$C$2,0,AG5<sheet2!$C$2,-1)} -> -1 | AU5: {=_xlfn.IFS(AH5>sheet2!$D$2,1,AH5=sheet2!$D$2,0,AH5<sheet2!$D$2,-1)} -> 1 | AV5: {=_xlfn.IFS(AI5>sheet2!$E$2,1,AI5=sheet2!$E$2,0,AI5<sheet2!$E$2,-1)} -> 0 | AW5: {=_xlfn.IFS(AJ5>sheet2!$F$2,1,AJ5=sheet2!$F$2,0,AJ5<sheet2!$F$2,-1)} -> 0 | AX5: {=_xlfn.IFS(AK5>sheet2!$G$2,1,AK5=sheet2!$G$2,0,AK5<sheet2!$G$2,-1)} -> 0 | AY5: 0.16433954 | AZ5: 0.87351598 | BA5: 0.13348775 | BB5: 0.0080626401 | BC5: 0.78522554
A6: 1 | B6: 北京 | C6: 2020 | D6: 6762.1 | E6: 7763.0137 | F6: 36102.55 | G6: =D6/F6 -> 0.18730256 | H6: =(G6-G5)/G5 -> -0.099846297 | I6: 0.45559969 | J6: =(I6-I5)/I5 -> 0.15697552 | K6: =E6/F6 -> 0.21502674 | L6: =(K6-K5)/K5 -> -0.025456044 | M6: 0 | N6: 0 | O6: 0 | P6: 1 | Q6: 0.75759066 | R6: 0.49120235 | S6: 0.1919221 | T6: 1.1 | U6: -0.03 | V6: 0.51785714 | W6: 0.24380165 | X6: 0.85714286 | Y6: 0 | Z6: 0.35300316 | AA6: 0.13763137 | AB6: 0.31428571 | AC6: -0.01744186 | AD6: 0.41857143 | AE6: 0.26063706 | AF6: 1 | AG6: 0.144 | AH6: 0.14 | AI6: 0.18 | AJ6: 0.25 | AK6: 0.65 | AL6: 0.72 | AM6: 1.037037 | AN6: 1 | AO6: 1 | AP6: 1 | AQ6: =AVERAGE(AL6,AO6) -> 0.86 | AR6: =AVERAGE(AM6) -> 1.037037 | AS6: =AVERAGE(AN6,AP6) -> 1 | AT6: {=_xlfn.IFS(AG6>sheet2!$C$2,1,AG6=sheet2!$C$2,0,AG6<sheet2!$C$2,-1)} -> -1 | AU6: {=_xlfn.IFS(AH6>sheet2!$D$2,1,AH6=sheet2!$D$2,0,AH6<sheet2!$D$2,-1)} -> 1 | AV6: {=_xlfn.IFS(AI6>sheet2!$E$2,1,AI6=sheet2!$E$2,0,AI6<sheet2!$E$2,-1)} -> 0 | AW6: {=_xlfn.IFS(AJ6>sheet2!$F$2,1,AJ6=sheet2!$F$2,0,AJ6<sheet2!$F$2,-1)} -> 0 | AX6: {=_xlfn.IFS(AK6>sheet2!$G$2,1,AK6=sheet2!$G$2,0,AK6<sheet2!$G$2,-1)} -> 0 | AY6: 0.16341782 | AZ6: 0.87528552 | BA6: 0.1334268 | BB6: 0.0082380801 | BC6: 0.77062272
A7: 1 | B7: 北京 | C7: 2021 | D7: 7103.62 | E7: 8010.2176 | F7: 40269.55 | G7: =D7/F7 -> 0.17640177 | H7: =(G7-G6)/G6 -> -0.058198812 | I7: 0.44803091 | J7: =(I7-I6)/I6 -> -0.016612797 | K7: =E7/F7 -> 0.198915 | L7: =(K7-K6)/K6 -> -0.074929003 | M7: 0 | N7: 0 | O7: 0 | P7: 1 | Q7: 0.75759066 | R7: 0.49120235 | S7: 0.1919221 | T7: 1.1 | U7: -0.03 | V7: 0.51785714 | W7: 0.24380165 | X7: 0.85714286 | Y7: 0 | Z7: 0.35300316 | AA7: 0.13763137 | AB7: 0.31428571 | AC7: -0.01744186 | AD7: 0.41857143 | AE7: 0.26063706 | AF7: 1 | AG7: 0.144 | AH7: 0.14 | AI7: 0.18 | AJ7: 0.25 | AK7: 0.65 | AL7: 0.72 | AM7: 1.037037 | AN7: 1 | AO7: 1 | AP7: 1 | AQ7: =AVERAGE(AL7,AO7) -> 0.86 | AR7: =AVERAGE(AM7) -> 1.037037 | AS7: =AVERAGE(AN7,AP7) -> 1 | AT7: {=_xlfn.IFS(AG7>sheet2!$C$2,1,AG7=sheet2!$C$2,0,AG7<sheet2!$C$2,-1)} -> -1 | AU7: {=_xlfn.IFS(AH7>sheet2!$D$2,1,AH7=sheet2!$D$2,0,AH7<sheet2!$D$2,-1)} -> 1 | AV7: {=_xlfn.IFS(AI7>sheet2!$E$2,1,AI7=sheet2!$E$2,0,AI7<sheet2!$E$2,-1)} -> 0 | AW7: {=_xlfn.IFS(AJ7>sheet2!$F$2,1,AJ7=sheet2!$F$2,0,AJ7<sheet2!$F$2,-1)} -> 0 | AX7: {=_xlfn.IFS(AK7>sheet2!$G$2,1,AK7=sheet2!$G$2,0,AK7<sheet2!$G$2,-1)} -> 0 | AY7: 0.19201109 | AZ7: 0.87528552 | BA7: 0.1334268 | BB7: 0.0077853962 | BC7: 0.82334645
A8: 1 | B8: 北京 | C8: 2022 | D8: 6896.89 | E8: 7715.7245 | F8: 41610.9 | G8: =D8/F8 -> 0.1657472 | H8: =(G8-G7)/G7 -> -0.060399487 | I8: 0.49718448 | J8: =(I8-I7)/I7 -> 0.10971023 | K8: =E8/F8 -> 0.18542556 | L8: =(K8-K7)/K7 -> -0.0678151 | M8: 1 | N8: 1 | O8: 0 | P8: 1 | Q8: 0.75759066 | R8: 0.49120235 | S8: 0.1919221 | T8: 1.1 | U8: -0.03 | V8: 0.51785714 | W8: 0.24380165 | X8: 0.85714286 | Y8: 0 | Z8: 0.35300316 | AA8: 0.13763137 | AB8: 0.31428571 | AC8: -0.01744186 | AD8: 0.41857143 | AE8: 0.26063706 | AF8: 1 | AG8: 0.144 | AH8: 0.14 | AI8: 0.18 | AJ8: 0.25 | AK8: 0.65 | AL8: 0.72 | AM8: 1.037037 | AN8: 1 | AO8: 1 | AP8: 1 | AQ8: =AVERAGE(AL8,AO8) -> 0.86 | AR8: =AVERAGE(AM8) -> 1.037037 | AS8: =AVERAGE(AN8,AP8) -> 1 | AT8: {=_xlfn.IFS(AG8>sheet2!$C$2,1,AG8=sheet2!$C$2,0,AG8<sheet2!$C$2,-1)} -> -1 | AU8: {=_xlfn.IFS(AH8>sheet2!$D$2,1,AH8=sheet2!$D$2,0,AH8<sheet2!$D$2,-1)} -> 1 | AV8: {=_xlfn.IFS(AI8>sheet2!$E$2,1,AI8=sheet2!$E$2,0,AI8<sheet2!$E$2,-1)} -> 0 | AW8: {=_xlfn.IFS(AJ8>sheet2!$F$2,1,AJ8=sheet2!$F$2,0,AJ8<sheet2!$F$2,-1)} -> 0 | AX8: {=_xlfn.IFS(AK8>sheet2!$G$2,1,AK8=sheet2!$G$2,0,AK8<sheet2!$G$2,-1)} -> 0 | AY8: 0.16727348 | AZ8: 0.87591575 | BA8: 0.13312203 | BB8: 0.0083871606 | BC8: 0.76506162
A9: 1 | B9: 北京 | C9: 2023 | D9: 7571.35 | E9: 8227.266 | F9: 43760.7 | G9: =D9/F9 -> 0.17301711 | H9: =(G9-G8)/G8 -> 0.043861481 | K9: =E9/F9 -> 0.18800581 | L9: =(K9-K8)/K8 -> 0.013915294 | M9: 1 | N9: 1 | O9: 1 | P9: 1 | Q9: 0.75759066 | R9: 0.49120235 | S9: 0.1919221 | T9: 1.1 | U9: -0.03 | V9: 0.51785714 | W9: 0.24380165 | X9: 0.85714286 | Y9: 0 | Z9: 0.35300316 | AA9: 0.13763137 | AB9: 0.31428571 | AC9: -0.01744186 | AD9: 0.41857143 | AE9: 0.26063706 | AF9: 1 | AG9: 0.144 | AH9: 0.14 | AI9: 0.18 | AJ9: 0.25 | AK9: 0.65 | AL9: 0.72 | AM9: 1.037037 | AN9: 1 | AO9: 1 | AP9: 1 | AQ9: =AVERAGE(AL9,AO9) -> 0.86 | AR9: =AVERAGE(AM9) -> 1.037037 | AS9: =AVERAGE(AN9,AP9) -> 1 | AT9: {=_xlfn.IFS(AG9>sheet2!$C$2,1,AG9=sheet2!$C$2,0,AG9<sheet2!$C$2,-1)} -> -1 | AU9: {=_xlfn.IFS(AH9>sheet2!$D$2,1,AH9=sheet2!$D$2,0,AH9<sheet2!$D$2,-1)} -> 1 | AV9: {=_xlfn.IFS(AI9>sheet2!$E$2,1,AI9=sheet2!$E$2,0,AI9<sheet2!$E$2,-1)} -> 0 | AW9: {=_xlfn.IFS(AJ9>sheet2!$F$2,1,AJ9=sheet2!$F$2,0,AJ9<sheet2!$F$2,-1)} -> 0 | AX9: {=_xlfn.IFS(AK9>sheet2!$G$2,1,AK9=sheet2!$G$2,0,AK9<sheet2!$G$2,-1)} -> 0 | AY9: 0.15753404 | AZ9: 0.87831656 | BA9: 0.13324394 | BB9: 0.010077579 | BC9: 0.77542418
A10: 2 | B10: 天津 | C10: 2016 | D10: 8078 | E10: 12475.773 | F10: 17885.39 | G10: =D10/F10 -> 0.45165356 | I10: 0.31494388 | K10: =E10/F10 -> 0.69753988 | M10: 0 | N10: 0 | O10: 0 | P10: 1 | Q10: 0.83038969 | R10: 1.3914956 | S10: 1.3944648 | T10: 2.5 | U10: 1.72 | V10: 1.2372014 | W10: 0.79904306 | X10: 0.33505155 | Y10: =(Q10-MIN(Q:Q))/(MAX(Q:Q)-MIN(Q:Q)) -> 0.30031447 | Z10: {=R10/MAX(ABS(R$2:R$26))} -> 1 | AA10: {=S10/MAX(ABS(S$2:S$26))} -> 1 | AB10: {=T10/MAX(ABS(T$2:T$26))} -> 0.86206897 | AC10: {=U10/MAX(ABS(U$2:U$26))} -> 1 | AD10: {=V10/MAX(ABS(V$2:V$26))} -> 1 | AE10: {=W10/MAX(ABS(W$2:W$26))} -> 1 | AF10: {=X10/MAX(ABS(X$2:X$26))} -> 0.39089347 | AG10: 0.117 | AH10: 0.135 | AI10: 0.18 | AJ10: 0.16 | AK10: 0.65 | AL10: 0.585 | AM10: 1 | AN10: 1 | AO10: 0.64 | AP10: 1 | AQ10: =AVERAGE(AL10,AO10) -> 0.6125 | AR10: =AVERAGE(AM10) -> 1 | AS10: =AVERAGE(AN10,AP10) -> 1 | AT10: {=_xlfn.IFS(AG10>sheet2!$C$2,1,AG10=sheet2!$C$2,0,AG10<sheet2!$C$2,-1)} -> -1 | AU10: {=_xlfn.IFS(AH10>sheet2!$D$2,1,AH10=sheet2!$D$2,0,AH10<sheet2!$D$2,-1)} -> 0 | AV10: {=_xlfn.IFS(AI10>sheet2!$E$2,1,AI10=sheet2!$E$2,0,AI10<sheet2!$E$2,-1)} -> 0 | AW10: {=_xlfn.IFS(AJ10>sheet2!$F$2,1,AJ10=sheet2!$F$2,0,AJ10<sheet2!$F$2,-1)} -> -1 | AX10: {=_xlfn.IFS(AK10>sheet2!$G$2,1,AK10=sheet2!$G$2,0,AK10<sheet2!$G$2,-1)} -> 0 | AY10: 0.24422168 | AZ10: 0.83298683 | BA10: 0.12108752 | BB10: 0.019566534 | BC10: 0.73619449
A11: 2 | B11: 天津 | C11: 2017 | D11: 7832 | E11: 12589.065 | F11: 18549.19 | G11: =D11/F11 -> 0.42222868 | H11: =(G11-G10)/G10 -> -0.06514922 | I11: 0.33162627 | J11: =(I11-I10)/I10 -> 0.052969385 | K11: =E11/F11 -> 0.67868544 | L11: =(K11-K10)/K10 -> -0.027029909 | M11: 0 | N11: 0 | O11: 0 | P11: 1 | Q11: 0.83038969 | R11: 1.3914956 | S11: 1.3944648 | T11: 2.5 | U11: 1.72 | V11: 1.2372014 | W11: 0.79904306 | X11: 0.33505155 | Y11: =(Q11-MIN(Q:Q))/(MAX(Q:Q)-MIN(Q:Q)) -> 0.30031447 | Z11: {=R11/MAX(ABS(R$2:R$26))} -> 1 | AA11: {=S11/MAX(ABS(S$2:S$26))} -> 1 | AB11: {=T11/MAX(ABS(T$2:T$26))} -> 0.86206897 | AC11: {=U11/MAX(ABS(U$2:U$26))} -> 1 | AD11: {=V11/MAX(ABS(V$2:V$26))} -> 1 | AE11: {=W11/MAX(ABS(W$2:W$26))} -> 1 | AF11: {=X11/MAX(ABS(X$2:X$26))} -> 0.39089347 | AG11: 0.117 | AH11: 0.135 | AI11: 0.18 | AJ11: 0.16 | AK11: 0.65 | AL11: 0.585 | AM11: 1 | AN11: 1 | AO11: 0.64 | AP11: 1 | AQ11: =AVERAGE(AL11,AO11) -> 0.6125 | AR11: =AVERAGE(AM11) -> 1 | AS11: =AVERAGE(AN11,AP11) -> 1 | AT11: {=_xlfn.IFS(AG11>sheet2!$C$2,1,AG11=sheet2!$C$2,0,AG11<sheet2!$C$2,-1)} -> -1 | AU11: {=_xlfn.IFS(AH11>sheet2!$D$2,1,AH11=sheet2!$D$2,0,AH11<sheet2!$D$2,-1)} -> 0 | AV11: {=_xlfn.IFS(AI11>sheet2!$E$2,1,AI11=sheet2!$E$2,0,AI11<sheet2!$E$2,-1)} -> 0 | AW11: {=_xlfn.IFS(AJ11>sheet2!$F$2,1,AJ11=sheet2!$F$2,0,AJ11<sheet2!$F$2,-1)} -> -1 | AX11: {=_xlfn.IFS(AK11>sheet2!$G$2,1,AK11=sheet2!$G$2,0,AK11<sheet2!$G$2,-1)} -> 0 | AY11: 0.24605387 | AZ11: 0.83546099 | BA11: 0.11831837 | BB11: 0.013000126 | BC11: 0.70383301
A12: 2 | B12: 天津 | C12: 2018 | D12: 7973 | E12: 13632.001 | F12: 18809.64 | G12: =D12/F12 -> 0.42387839 | H12: =(G12-G11)/G11 -> 0.0039071594 | I12: 0.34692661 | J12: =(I12-I11)/I11 -> 0.046137301 | K12: =E12/F12 -> 0.7247348 | L12: =(K12-K11)/K11 -> 0.067850805 | M12: 0 | N12: 0 | O12: 0 | P12: 1 | Q12: 0.83038969 | R12: 1.3914956 | S12: 1.3944648 | T12: 2.5 | U12: 1.72 | V12: 1.2372014 | W12: 0.79904306 | X12: 0.33505155 | Y12: =(Q12-MIN(Q:Q))/(MAX(Q:Q)-MIN(Q:Q)) -> 0.30031447 | Z12: {=R12/MAX(ABS(R$2:R$26))} -> 1 | AA12: {=S12/MAX(ABS(S$2:S$26))} -> 1 | AB12: {=T12/MAX(ABS(T$2:T$26))} -> 0.86206897 | AC12: {=U12/MAX(ABS(U$2:U$26))} -> 1 | AD12: {=V12/MAX(ABS(V$2:V$26))} -> 1 | AE12: {=W12/MAX(ABS(W$2:W$26))} -> 1 | AF12: {=X12/MAX(ABS(X$2:X$26))} -> 0.39089347 | AG12: 0.117 | AH12: 0.135 | AI12: 0.18 | AJ12: 0.16 | AK12: 0.65 | AL12: 0.585 | AM12: 1 | AN12: 1 | AO12: 0.64 | AP12: 1 | AQ12: =AVERAGE(AL12,AO12) -> 0.6125 | AR12: =AVERAGE(AM12) -> 1 | AS12: =AVERAGE(AN12,AP12) -> 1 | AT12: {=_xlfn.IFS(AG12>sheet2!$C$2,1,AG12=sheet2!$C$2,0,AG12<sheet2!$C$2,-1)} -> -1 | AU12: {=_xlfn.IFS(AH12>sheet2!$D$2,1,AH12=sheet2!$D$2,0,AH12<sheet2!$D$2,-1)} -> 0 | AV12: {=_xlfn.IFS(AI12>sheet2!$E$2,1,AI12=sheet2!$E$2,0,AI12<sheet2!$E$2,-1)} -> 0 | AW12: {=_xlfn.IFS(AJ12>sheet2!$F$2,1,AJ12=sheet2!$F$2,0,AJ12<sheet2!$F$2,-1)} -> -1 | AX12: {=_xlfn.IFS(AK12>sheet2!$G$2,1,AK12=sheet2!$G$2,0,AK12<sheet2!$G$2,-1)} -> 0 | AY12: 0.25706499 | AZ12: 0.83947939 | BA12: 0.1160527 | BB12: 0.013443963 | BC12: 0.67874038
A13: 2 | B13: 天津 | C13: 2019 | D13: 8241 | E13: 14204.096 | F13: 14104.28 | G13: =D13/F13 -> 0.58429073 | H13: =(G13-G12)/G12 -> 0.37843951 | I13: 0.35395048 | J13: =(I13-I12)/I12 -> 0.020245993 | K13: =E13/F13 -> 1.007077 | L13: =(K13-K12)/K12 -> 0.38958007 | M13: 0 | N13: 0 | O13: 0 | P13: 1 | Q13: 0.83038969 | R13: 1.3914956 | S13: 1.3944648 | T13: 2.5 | U13: 1.72 | V13: 1.2372014 | W13: 0.79904306 | X13: 0.33505155 | Y13: =(Q13-MIN(Q:Q))/(MAX(Q:Q)-MIN(Q:Q)) -> 0.30031447 | Z13: {=R13/MAX(ABS(R$2:R$26))} -> 1 | AA13: {=S13/MAX(ABS(S$2:S$26))} -> 1 | AB13: {=T13/MAX(ABS(T$2:T$26))} -> 0.86206897 | AC13: {=U13/MAX(ABS(U$2:U$26))} -> 1 | AD13: {=V13/MAX(ABS(V$2:V$26))} -> 1 | AE13: {=W13/MAX(ABS(W$2:W$26))} -> 1 | AF13: {=X13/MAX(ABS(X$2:X$26))} -> 0.39089347 | AG13: 0.117 | AH13: 0.135 | AI13: 0.18 | AJ13: 0.16 | AK13: 0.65 | AL13: 0.585 | AM13: 1 | AN13: 1 | AO13: 0.64 | AP13: 1 | AQ13: =AVERAGE(AL13,AO13) -> 0.6125 | AR13: =AVERAGE(AM13) -> 1 | AS13: =AVERAGE(AN13,AP13) -> 1 | AT13: {=_xlfn.IFS(AG13>sheet2!$C$2,1,AG13=sheet2!$C$2,0,AG13<sheet2!$C$2,-1)} -> -1 | AU13: {=_xlfn.IFS(AH13>sheet2!$D$2,1,AH13=sheet2!$D$2,0,AH13<sheet2!$D$2,-1)} -> 0 | AV13: {=_xlfn.IFS(AI13>sheet2!$E$2,1,AI13=sheet2!$E$2,0,AI13<sheet2!$E$2,-1)} -> 0 | AW13: {=_xlfn.IFS(AJ13>sheet2!$F$2,1,AJ13=sheet2!$F$2,0,AJ13<sheet2!$F$2,-1)} -> -1 | AX13: {=_xlfn.IFS(AK13>sheet2!$G$2,1,AK13=sheet2!$G$2,0,AK13<sheet2!$G$2,-1)} -> 0 | AY13: 0.35570054 | AZ13: 0.8433213 | BA13: 0.11622053 | BB13: 0.015132428 | BC13: 0.67789837
A14: 2 | B14: 天津 | C14: 2020 | D14: 8104.6 | E14: 13993.579 | F14: 14083.73 | G14: =D14/F14 -> 0.57545835 | H14: =(G14-G13)/G13 -> -0.01511641 | I14: 0.36016632 | J14: =(I14-I13)/I13 -> 0.017561309 | K14: =E14/F14 -> 0.9935989 | L14: =(K14-K13)/K13 -> -0.013383414 | M14: 0 | N14: 0 | O14: 0 | P14: 1 | Q14: 0.83038969 | R14: 1.3914956 | S14: 1.3944648 | T14: 2.5 | U14: 1.72 | V14: 1.2372014 | W14: 0.79904306 | X14: 0.33505155 | Y14: =(Q14-MIN(Q:Q))/(MAX(Q:Q)-MIN(Q:Q)) -> 0.30031447 | Z14: {=R14/MAX(ABS(R$2:R$26))} -> 1 | AA14: {=S14/MAX(ABS(S$2:S$26))} -> 1 | AB14: {=T14/MAX(ABS(T$2:T$26))} -> 0.86206897 | AC14: {=U14/MAX(ABS(U$2:U$26))} -> 1 | AD14: {=V14/MAX(ABS(V$2:V$26))} -> 1 | AE14: {=W14/MAX(ABS(W$2:W$26))} -> 1 | AF14: {=X14/MAX(ABS(X$2:X$26))} -> 0.39089347 | AG14: 0.117 | AH14: 0.135 | AI14: 0.18 | AJ14: 0.16 | AK14: 0.65 | AL14: 0.585 | AM14: 1 | AN14: 1 | AO14: 0.64 | AP14: 1 | AQ14: =AVERAGE(AL14,AO14) -> 0.6125 | AR14: =AVERAGE(AM14) -> 1 | AS14: =AVERAGE(AN14,AP14) -> 1 | AT14: {=_xlfn.IFS(AG14>sheet2!$C$2,1,AG14=sheet2!$C$2,0,AG14<sheet2!$C$2,-1)} -> -1 | AU14: {=_xlfn.IFS(AH14>sheet2!$D$2,1,AH14=sheet2!$D$2,0,AH14<sheet2!$D$2,-1)} -> 0 | AV14: {=_xlfn.IFS(AI14>sheet2!$E$2,1,AI14=sheet2!$E$2,0,AI14<sheet2!$E$2,-1)} -> 0 | AW14: {=_xlfn.IFS(AJ14>sheet2!$F$2,1,AJ14=sheet2!$F$2,0,AJ14<sheet2!$F$2,-1)} -> -1 | AX14: {=_xlfn.IFS(AK14>sheet2!$G$2,1,AK14=sheet2!$G$2,0,AK14<sheet2!$G$2,-1)} -> 0 | AY14: 0.35264806 | AZ14: 0.84715213 | BA14: 0.11638835 | BB14: 0.016243687 | BC14: 0.61024958
A15: 2 | B15: 天津 | C15: 2021 | D15: 8205.69 | E15: 14483.594 | F15: 15695.046 | G15: =D15/F15 -> 0.52282039 | H15: =(G15-G14)/G14 -> -0.091471357 | I15: 0.35929797 | J15: =(I15-I14)/I14 -> -0.0024109645 | K15: =E15/F15 -> 0.92281311 | L15: =(K15-K14)/K14 -> -0.071241818 | M15: 0 | N15: 0 | O15: 0 | P15: 1 | Q15: 0.83038969 | R15: 1.3914956 | S15: 1.3944648 | T15: 2.5 | U15: 1.72 | V15: 1.2372014 | W15: 0.79904306 | X15: 0.33505155 | Y15: =(Q15-MIN(Q:Q))/(MAX(Q:Q)-MIN(Q:Q)) -> 0.30031447 | Z15: {=R15/MAX(ABS(R$2:R$26))} -> 1 | AA15: {=S15/MAX(ABS(S$2:S$26))} -> 1 | AB15: {=T15/MAX(ABS(T$2:T$26))} -> 0.86206897 | AC15: {=U15/MAX(ABS(U$2:U$26))} -> 1 | AD15: {=V15/MAX(ABS(V$2:V$26))} -> 1 | AE15: {=W15/MAX(ABS(W$2:W$26))} -> 1 | AF15: {=X15/MAX(ABS(X$2:X$26))} -> 0.39089347 | AG15: 0.117 | AH15: 0.135 | AI15: 0.18 | AJ15: 0.16 | AK15: 0.65 | AL15: 0.585 | AM15: 1 | AN15: 1 | AO15: 0.64 | AP15: 1 | AQ15: =AVERAGE(AL15,AO15) -> 0.6125 | AR15: =AVERAGE(AM15) -> 1 | AS15: =AVERAGE(AN15,AP15) -> 1 | AT15: {=_xlfn.IFS(AG15>sheet2!$C$2,1,AG15=sheet2!$C$2,0,AG15<sheet2!$C$2,-1)} -> -1 | AU15: {=_xlfn.IFS(AH15>sheet2!$D$2,1,AH15=sheet2!$D$2,0,AH15<sheet2!$D$2,-1)} -> 0 | AV15: {=_xlfn.IFS(AI15>sheet2!$E$2,1,AI15=sheet2!$E$2,0,AI15<sheet2!$E$2,-1)} -> 0 | AW15: {=_xlfn.IFS(AJ15>sheet2!$F$2,1,AJ15=sheet2!$F$2,0,AJ15<sheet2!$F$2,-1)} -> -1 | AX15: {=_xlfn.IFS(AK15>sheet2!$G$2,1,AK15=sheet2!$G$2,0,AK15<sheet2!$G$2,-1)} -> 0 | AY15: 0.36830093 | AZ15: 0.84850692 | BA15: 0.11521356 | BB15: 0.016009096 | BC15: 0.6791518
A16: 2 | B16: 天津 | C16: 2022 | D16: 8121.77 | E16: 14301.85 | F16: 16311.3 | G16: =D16/F16 -> 0.49792291 | H16: =(G16-G15)/G15 -> -0.047621478 | I16: 0.39162797 | J16: =(I16-I15)/I15 -> 0.089981019 | K16: =E16/F16 -> 0.87680625 | L16: =(K16-K15)/K15 -> -0.049855008 | M16: 1 | N16: 1 | O16: 0 | P16: 1 | Q16: 0.83038969 | R16: 1.3914956 | S16: 1.3944648 | T16: 2.5 | U16: 1.72 | V16: 1.2372014 | W16: 0.79904306 | X16: 0.33505155 | Y16: =(Q16-MIN(Q:Q))/(MAX(Q:Q)-MIN(Q:Q)) -> 0.30031447 | Z16: {=R16/MAX(ABS(R$2:R$26))} -> 1 | AA16: {=S16/MAX(ABS(S$2:S$26))} -> 1 | AB16: {=T16/MAX(ABS(T$2:T$26))} -> 0.86206897 | AC16: {=U16/MAX(ABS(U$2:U$26))} -> 1 | AD16: {=V16/MAX(ABS(V$2:V$26))} -> 1 | AE16: {=W16/MAX(ABS(W$2:W$26))} -> 1 | AF16: {=X16/MAX(ABS(X$2:X$26))} -> 0.39089347 | AG16: 0.117 | AH16: 0.135 | AI16: 0.18 | AJ16: 0.16 | AK16: 0.65 | AL16: 0.585 | AM16: 1 | AN16: 1 | AO16: 0.64 | AP16: 1 | AQ16: =AVERAGE(AL16,AO16) -> 0.6125 | AR16: =AVERAGE(AM16) -> 1 | AS16: =AVERAGE(AN16,AP16) -> 1 | AT16: {=_xlfn.IFS(AG16>sheet2!$C$2,1,AG16=sheet2!$C$2,0,AG16<sheet2!$C$2,-1)} -> -1 | AU16: {=_xlfn.IFS(AH16>sheet2!$D$2,1,AH16=sheet2!$D$2,0,AH16<sheet2!$D$2,-1)} -> 0 | AV16: {=_xlfn.IFS(AI16>sheet2!$E$2,1,AI16=sheet2!$E$2,0,AI16<sheet2!$E$2,-1)} -> 0 | AW16: {=_xlfn.IFS(AJ16>sheet2!$F$2,1,AJ16=sheet2!$F$2,0,AJ16<sheet2!$F$2,-1)} -> -1 | AX16: {=_xlfn.IFS(AK16>sheet2!$G$2,1,AK16=sheet2!$G$2,0,AK16<sheet2!$G$2,-1)} -> 0 | AY16: 0.37352633 | AZ16: 0.85106383 | BA16: 0.11437442 | BB16: 0.017446249 | BC16: 0.67648535
A17: 2 | B17: 天津 | C17: 2023 | D17: 8493.12 | E17: 15167.833 | F17: 16737.3 | G17: =D17/F17 -> 0.50743668 | H17: =(G17-G16)/G16 -> 0.019106915 | K17: =E17/F17 -> 0.90622935 | L17: =(K17-K16)/K16 -> 0.033557127 | M17: 1 | N17: 1 | O17: 1 | P17: 1 | Q17: 0.83038969 | R17: 1.3914956 | S17: 1.3944648 | T17: 2.5 | U17: 1.72 | V17: 1.2372014 | W17: 0.79904306 | X17: 0.33505155 | Y17: =(Q17-MIN(Q:Q))/(MAX(Q:Q)-MIN(Q:Q)) -> 0.30031447 | Z17: {=R17/MAX(ABS(R$2:R$26))} -> 1 | AA17: {=S17/MAX(ABS(S$2:S$26))} -> 1 | AB17: {=T17/MAX(ABS(T$2:T$26))} -> 0.86206897 | AC17: {=U17/MAX(ABS(U$2:U$26))} -> 1 | AD17: {=V17/MAX(ABS(V$2:V$26))} -> 1 | AE17: {=W17/MAX(ABS(W$2:W$26))} -> 1 | AF17: {=X17/MAX(ABS(X$2:X$26))} -> 0.39089347 | AG17: 0.117 | AH17: 0.135 | AI17: 0.18 | AJ17: 0.16 | AK17: 0.65 | AL17: 0.585 | AM17: 1 | AN17: 1 | AO17: 0.64 | AP17: 1 | AQ17: =AVERAGE(AL17,AO17) -> 0.6125 | AR17: =AVERAGE(AM17) -> 1 | AS17: =AVERAGE(AN17,AP17) -> 1 | AT17: {=_xlfn.IFS(AG17>sheet2!$C$2,1,AG17=sheet2!$C$2,0,AG17<sheet2!$C$2,-1)} -> -1 | AU17: {=_xlfn.IFS(AH17>sheet2!$D$2,1,AH17=sheet2!$D$2,0,AH17<sheet2!$D$2,-1)} -> 0 | AV17: {=_xlfn.IFS(AI17>sheet2!$E$2,1,AI17=sheet2!$E$2,0,AI17<sheet2!$E$2,-1)} -> 0 | AW17: {=_xlfn.IFS(AJ17>sheet2!$F$2,1,AJ17=sheet2!$F$2,0,AJ17<sheet2!$F$2,-1)} -> -1 | AX17: {=_xlfn.IFS(AK17>sheet2!$G$2,1,AK17=sheet2!$G$2,0,AK17<sheet2!$G$2,-1)} -> 0 | AY17: 0.36329635 | AZ17: 0.85483871 | BA17: 0.11445834 | BB17: 0.017684728 | BC17: 0.61806415
A18: 3 | B18: 河北 | C18: 2016 | D18: 31458 | E18: 74877.961 | F18: 32070.45 | G18: =D18/F18 -> 0.98090298 | I18: 0.22307135 | K18: =E18/F18 -> 2.3347961 | M18: 0 | N18: 0 | O18: 0 | P18: 1 | Q18: 0.86522324 | R18: 0.032258065 | S18: -0.22026952 | T18: 1.3 | U18: -0.16 | V18: -0.03514377 | W18: -0.052 | X18: -0.1294964 | Y18: 0.44401167 | Z18: 0.023182297 | AA18: -0.1579599 | AB18: 0.37142857 | AC18: -0.093023256 | AD18: -0.028405861 | AE18: -0.055590793 | AF18: -0.15107914 | AG18: 0.13 | AH18: 0.135 | AI18: 0.18 | AJ18: 0.19 | AK18: 0.65 | AL18: 0.65 | AM18: 1 | AN18: 1 | AO18: 0.76 | AP18: 1 | AQ18: =AVERAGE(AL18,AO18) -> 0.705 | AR18: =AVERAGE(AM18) -> 1 | AS18: =AVERAGE(AN18,AP18) -> 1 | AT18: {=_xlfn.IFS(AG18>sheet2!$C$2,1,AG18=sheet2!$C$2,0,AG18<sheet2!$C$2,-1)} -> -1 | AU18: {=_xlfn.IFS(AH18>sheet2!$D$2,1,AH18=sheet2!$D$2,0,AH18<sheet2!$D$2,-1)} -> 0 | AV18: {=_xlfn.IFS(AI18>sheet2!$E$2,1,AI18=sheet2!$E$2,0,AI18<sheet2!$E$2,-1)} -> 0 | AW18: {=_xlfn.IFS(AJ18>sheet2!$F$2,1,AJ18=sheet2!$F$2,0,AJ18<sheet2!$F$2,-1)} -> -1 | AX18: {=_xlfn.IFS(AK18>sheet2!$G$2,1,AK18=sheet2!$G$2,0,AK18<sheet2!$G$2,-1)} -> 0 | AY18: 0.38453779 | AZ18: 0.53871186 | BA18: 0.039115331 | BB18: 0.0096244611 | BC18: 0.47108949
A19: 3 | B19: 河北 | C19: 2017 | D19: 32083 | E19: 75443.372 | F19: 34016.32 | G19: =D19/F19 -> 0.94316493 | H19: =(G19-G18)/G18 -> -0.038472768 | I19: 0.24563241 | J19: =(I19-I18)/I18 -> 0.1011383 | K19: =E19/F19 -> 2.2178581 | L19: =(K19-K18)/K18 -> -0.050084873 | M19: 0 | N19: 0 | O19: 0 | P19: 1 | Q19: 0.86522324 | R19: 0.032258065 | S19: -0.22026952 | T19: 1.3 | U19: -0.16 | V19: -0.03514377 | W19: -0.052 | X19: -0.1294964 | Y19: 0.44401167 | Z19: 0.023182297 | AA19: -0.1579599 | AB19: 0.37142857 | AC19: -0.093023256 | AD19: -0.028405861 | AE19: -0.055590793 | AF19: -0.15107914 | AG19: 0.13 | AH19: 0.135 | AI19: 0.18 | AJ19: 0.19 | AK19: 0.65 | AL19: 0.65 | AM19: 1 | AN19: 1 | AO19: 0.76 | AP19: 1 | AQ19: =AVERAGE(AL19,AO19) -> 0.705 | AR19: =AVERAGE(AM19) -> 1 | AS19: =AVERAGE(AN19,AP19) -> 1 | AT19: {=_xlfn.IFS(AG19>sheet2!$C$2,1,AG19=sheet2!$C$2,0,AG19<sheet2!$C$2,-1)} -> -1 | AU19: {=_xlfn.IFS(AH19>sheet2!$D$2,1,AH19=sheet2!$D$2,0,AH19<sheet2!$D$2,-1)} -> 0 | AV19: {=_xlfn.IFS(AI19>sheet2!$E$2,1,AI19=sheet2!$E$2,0,AI19<sheet2!$E$2,-1)} -> 0 | AW19: {=_xlfn.IFS(AJ19>sheet2!$F$2,1,AJ19=sheet2!$F$2,0,AJ19<sheet2!$F$2,-1)} -> -1 | AX19: {=_xlfn.IFS(AK19>sheet2!$G$2,1,AK19=sheet2!$G$2,0,AK19<sheet2!$G$2,-1)} -> 0 | AY19: 0.37564322 | AZ19: 0.55743015 | BA19: 0.039295659 | BB19: 0.010317648 | BC19: 0.48708274
A20: 3 | B20: 河北 | C20: 2018 | D20: 32185 | E20: 79620.28 | F20: 36010.27 | G20: =D20/F20 -> 0.8937728 | H20: =(G20-G19)/G19 -> -0.052368491 | I20: 0.28301301 | J20: =(I20-I19)/I19 -> 0.15218106 | K20: =E20/F20 -> 2.2110437 | L20: =(K20-K19)/K19 -> -0.0030725317 | M20: 0 | N20: 0 | O20: 0 | P20: 1 | Q20: 0.86522324 | R20: 0.032258065 | S20: -0.22026952 | T20: 1.3 | U20: -0.16 | V20: -0.03514377 | W20: -0.052 | X20: -0.1294964 | Y20: 0.44401167 | Z20: 0.023182297 | AA20: -0.1579599 | AB20: 0.37142857 | AC20: -0.093023256 | AD20: -0.028405861 | AE20: -0.055590793 | AF20: -0.15107914 | AG20: 0.13 | AH20: 0.135 | AI20: 0.18 | AJ20: 0.19 | AK20: 0.65 | AL20: 0.65 | AM20: 1 | AN20: 1 | AO20: 0.76 | AP20: 1 | AQ20: =AVERAGE(AL20,AO20) -> 0.705 | AR20: =AVERAGE(AM20) -> 1 | AS20: =AVERAGE(AN20,AP20) -> 1 | AT20: {=_xlfn.IFS(AG20>sheet2!$C$2,1,AG20=sheet2!$C$2,0,AG20<sheet2!$C$2,-1)} -> -1 | AU20: {=_xlfn.IFS(AH20>sheet2!$D$2,1,AH20=sheet2!$D$2,0,AH20<sheet2!$D$2,-1)} -> 0 | AV20: {=_xlfn.IFS(AI20>sheet2!$E$2,1,AI20=sheet2!$E$2,0,AI20<sheet2!$E$2,-1)} -> 0 | AW20: {=_xlfn.IFS(AJ20>sheet2!$F$2,1,AJ20=sheet2!$F$2,0,AJ20<sheet2!$F$2,-1)} -> -1 | AX20: {=_xlfn.IFS(AK20>sheet2!$G$2,1,AK20=sheet2!$G$2,0,AK20<sheet2!$G$2,-1)} -> 0 | AY20: 0.35834499 | AZ20: 0.57325613 | BA20: 0.039385823 | BB20: 0.010607852 | BC20: 0.45479737
A21: 3 | B21: 河北 | C21: 2019 | D21: 32545 | E21: 82819.72 | F21: 35104.52 | G21: =D21/F21 -> 0.92708859 | H21: =(G21-G20)/G20 -> 0.037275454 | I21: 0.26492564 | J21: =(I21-I20)/I20 -> -0.063910033 | K21: =E21/F21 -> 2.3592324 | L21: =(K21-K20)/K20 -> 0.067022053 | M21: 0 | N21: 0 | O21: 0 | P21: 1 | Q21: 0.86522324 | R21: 0.032258065 | S21: -0.22026952 | T21: 1.3 | U21: -0.16 | V21: -0.03514377 | W21: -0.052 | X21: -0.1294964 | Y21: 0.44401167 | Z21: 0.023182297 | AA21: -0.1579599 | AB21: 0.37142857 | AC21: -0.093023256 | AD21: -0.028405861 | AE21: -0.055590793 | AF21: -0.15107914 | AG21: 0.13 | AH21: 0.135 | AI21: 0.18 | AJ21: 0.19 | AK21: 0.65 | AL21: 0.65 | AM21: 1 | AN21: 1 | AO21: 0.76 | AP21: 1 | AQ21: =AVERAGE(AL21,AO21) -> 0.705 | AR21: =AVERAGE(AM21) -> 1 | AS21: =AVERAGE(AN21,AP21) -> 1 | AT21: {=_xlfn.IFS(AG21>sheet2!$C$2,1,AG21=sheet2!$C$2,0,AG21<sheet2!$C$2,-1)} -> -1 | AU21: {=_xlfn.IFS(AH21>sheet2!$D$2,1,AH21=sheet2!$D$2,0,AH21<sheet2!$D$2,-1)} -> 0 | AV21: {=_xlfn.IFS(AI21>sheet2!$E$2,1,AI21=sheet2!$E$2,0,AI21<sheet2!$E$2,-1)} -> 0 | AW21: {=_xlfn.IFS(AJ21>sheet2!$F$2,1,AJ21=sheet2!$F$2,0,AJ21<sheet2!$F$2,-1)} -> -1 | AX21: {=_xlfn.IFS(AK21>sheet2!$G$2,1,AK21=sheet2!$G$2,0,AK21<sheet2!$G$2,-1)} -> 0 | AY21: 0.38744014 | AZ21: 0.58775346 | BA21: 0.039497202 | BB21: 0.012493622 | BC21: 0.44999061
A22: 3 | B22: 河北 | C22: 2020 | D22: 32782.76 | E22: 82674.329 | F22: 36206.89 | G22: =D22/F22 -> 0.90542877 | H22: =(G22-G21)/G21 -> -0.023363267 | I22: 0.27888529 | J22: =(I22-I21)/I21 -> 0.052692731 | K22: =E22/F22 -> 2.2833866 | L22: =(K22-K21)/K21 -> -0.03214848 | M22: 0 | N22: 0 | O22: 0 | P22: 1 | Q22: 0.86522324 | R22: 0.032258065 | S22: -0.22026952 | T22: 1.3 | U22: -0.16 | V22: -0.03514377 | W22: -0.052 | X22: -0.1294964 | Y22: 0.44401167 | Z22: 0.023182297 | AA22: -0.1579599 | AB22: 0.37142857 | AC22: -0.093023256 | AD22: -0.028405861 | AE22: -0.055590793 | AF22: -0.15107914 | AG22: 0.13 | AH22: 0.135 | AI22: 0.18 | AJ22: 0.19 | AK22: 0.65 | AL22: 0.65 | AM22: 1 | AN22: 1 | AO22: 0.76 | AP22: 1 | AQ22: =AVERAGE(AL22,AO22) -> 0.705 | AR22: =AVERAGE(AM22) -> 1 | AS22: =AVERAGE(AN22,AP22) -> 1 | AT22: {=_xlfn.IFS(AG22>sheet2!$C$2,1,AG22=sheet2!$C$2,0,AG22<sheet2!$C$2,-1)} -> -1 | AU22: {=_xlfn.IFS(AH22>sheet2!$D$2,1,AH22=sheet2!$D$2,0,AH22<sheet2!$D$2,-1)} -> 0 | AV22: {=_xlfn.IFS(AI22>sheet2!$E$2,1,AI22=sheet2!$E$2,0,AI22<sheet2!$E$2,-1)} -> 0 | AW22: {=_xlfn.IFS(AJ22>sheet2!$F$2,1,AJ22=sheet2!$F$2,0,AJ22<sheet2!$F$2,-1)} -> -1 | AX22: {=_xlfn.IFS(AK22>sheet2!$G$2,1,AK22=sheet2!$G$2,0,AK22<sheet2!$G$2,-1)} -> 0 | AY22: 0.38495436 | AZ22: 0.60075027 | BA22: 0.039587366 | BB22: 0.013407791 | BC22: 0.42408834
A23: 3 | B23: 河北 | C23: 2021 | D23: 33085.852 | E23: 82061.505 | F23: 40391.27 | G23: =D23/F23 -> 0.81913373 | H23: =(G23-G22)/G22 -> -0.095308486 | I23: 0.31943668 | J23: =(I23-I22)/I22 -> 0.14540525 | K23: =E23/F23 -> 2.0316644 | L23: =(K23-K22)/K22 -> -0.11024075 | M23: 0 | N23: 0 | O23: 0 | P23: 1 | Q23: 0.86522324 | R23: 0.032258065 | S23: -0.22026952 | T23: 1.3 | U23: -0.16 | V23: -0.03514377 | W23: -0.052 | X23: -0.1294964 | Y23: 0.44401167 | Z23: 0.023182297 | AA23: -0.1579599 | AB23: 0.37142857 | AC23: -0.093023256 | AD23: -0.028405861 | AE23: -0.055590793 | AF23: -0.15107914 | AG23: 0.13 | AH23: 0.135 | AI23: 0.18 | AJ23: 0.19 | AK23: 0.65 | AL23: 0.65 | AM23: 1 | AN23: 1 | AO23: 0.76 | AP23: 1 | AQ23: =AVERAGE(AL23,AO23) -> 0.705 | AR23: =AVERAGE(AM23) -> 1 | AS23: =AVERAGE(AN23,AP23) -> 1 | AT23: {=_xlfn.IFS(AG23>sheet2!$C$2,1,AG23=sheet2!$C$2,0,AG23<sheet2!$C$2,-1)} -> -1 | AU23: {=_xlfn.IFS(AH23>sheet2!$D$2,1,AH23=sheet2!$D$2,0,AH23<sheet2!$D$2,-1)} -> 0 | AV23: {=_xlfn.IFS(AI23>sheet2!$E$2,1,AI23=sheet2!$E$2,0,AI23<sheet2!$E$2,-1)} -> 0 | AW23: {=_xlfn.IFS(AJ23>sheet2!$F$2,1,AJ23=sheet2!$F$2,0,AJ23<sheet2!$F$2,-1)} -> -1 | AX23: {=_xlfn.IFS(AK23>sheet2!$G$2,1,AK23=sheet2!$G$2,0,AK23<sheet2!$G$2,-1)} -> 0 | AY23: 0.40728603 | AZ23: 0.61143931 | BA23: 0.039502506 | BB23: 0.014121675 | BC23: 0.47101278
A24: 3 | B24: 河北 | C24: 2022 | D24: 32538.48 | E24: 78668.402 | F24: 42370.4 | G24: =D24/F24 -> 0.7679531 | H24: =(G24-G23)/G23 -> -0.062481408 | I24: 0.32134809 | J24: =(I24-I23)/I23 -> 0.0059836922 | K24: =E24/F24 -> 1.856683 | L24: =(K24-K23)/K23 -> -0.086127107 | M24: 1 | N24: 1 | O24: 0 | P24: 1 | Q24: 0.86522324 | R24: 0.032258065 | S24: -0.22026952 | T24: 1.3 | U24: -0.16 | V24: -0.03514377 | W24: -0.052 | X24: -0.1294964 | Y24: 0.44401167 | Z24: 0.023182297 | AA24: -0.1579599 | AB24: 0.37142857 | AC24: -0.093023256 | AD24: -0.028405861 | AE24: -0.055590793 | AF24: -0.15107914 | AG24: 0.13 | AH24: 0.135 | AI24: 0.18 | AJ24: 0.19 | AK24: 0.65 | AL24: 0.65 | AM24: 1 | AN24: 1 | AO24: 0.76 | AP24: 1 | AQ24: =AVERAGE(AL24,AO24) -> 0.705 | AR24: =AVERAGE(AM24) -> 1 | AS24: =AVERAGE(AN24,AP24) -> 1 | AT24: {=_xlfn.IFS(AG24>sheet2!$C$2,1,AG24=sheet2!$C$2,0,AG24<sheet2!$C$2,-1)} -> -1 | AU24: {=_xlfn.IFS(AH24>sheet2!$D$2,1,AH24=sheet2!$D$2,0,AH24<sheet2!$D$2,-1)} -> 0 | AV24: {=_xlfn.IFS(AI24>sheet2!$E$2,1,AI24=sheet2!$E$2,0,AI24<sheet2!$E$2,-1)} -> 0 | AW24: {=_xlfn.IFS(AJ24>sheet2!$F$2,1,AJ24=sheet2!$F$2,0,AJ24<sheet2!$F$2,-1)} -> -1 | AX24: {=_xlfn.IFS(AK24>sheet2!$G$2,1,AK24=sheet2!$G$2,0,AK24<sheet2!$G$2,-1)} -> 0 | AY24: 0.3872208 | AZ24: 0.61657682 | BA24: 0.039354 | BB24: 0.015007352 | BC24: 0.43589694
A25: 3 | B25: 河北 | C25: 2023 | D25: 33615.32 | E25: 81030.319 | F25: 43944.1 | G25: =D25/F25 -> 0.76495639 | H25: =(G25-G24)/G24 -> -0.0039022065 | K25: =E25/F25 -> 1.8439408 | L25: =(K25-K24)/K24 -> -0.0068628902 | M25: 1 | N25: 1 | O25: 1 | P25: 1 | Q25: 0.86522324 | R25: 0.032258065 | S25: -0.22026952 | T25: 1.3 | U25: -0.16 | V25: -0.03514377 | W25: -0.052 | X25: -0.1294964 | Y25: 0.44401167 | Z25: 0.023182297 | AA25: -0.1579599 | AB25: 0.37142857 | AC25: -0.093023256 | AD25: -0.028405861 | AE25: -0.055590793 | AF25: -0.15107914 | AG25: 0.13 | AH25: 0.135 | AI25: 0.18 | AJ25: 0.19 | AK25: 0.65 | AL25: 0.65 | AM25: 1 | AN25: 1 | AO25: 0.76 | AP25: 1 | AQ25: =AVERAGE(AL25,AO25) -> 0.705 | AR25: =AVERAGE(AM25) -> 1 | AS25: =AVERAGE(AN25,AP25) -> 1 | AT25: {=_xlfn.IFS(AG25>sheet2!$C$2,1,AG25=sheet2!$C$2,0,AG25<sheet2!$C$2,-1)} -> -1 | AU25: {=_xlfn.IFS(AH25>sheet2!$D$2,1,AH25=sheet2!$D$2,0,AH25<sheet2!$D$2,-1)} -> 0 | AV25: {=_xlfn.IFS(AI25>sheet2!$E$2,1,AI25=sheet2!$E$2,0,AI25<sheet2!$E$2,-1)} -> 0 | AW25: {=_xlfn.IFS(AJ25>sheet2!$F$2,1,AJ25=sheet2!$F$2,0,AJ25<sheet2!$F$2,-1)} -> -1 | AX25: {=_xlfn.IFS(AK25>sheet2!$G$2,1,AK25=sheet2!$G$2,0,AK25<sheet2!$G$2,-1)} -> 0 | AY25: 0.38940836 | AZ25: 0.62775599 | BA25: 0.039210798 | BB25: 0.016009043 | BC25: 0.44623218
A26: 4 | B26: 山西 | C26: 2016 | D26: 18974 | E26: 50115.142 | F26: 13050.41 | G26: =D26/F26 -> 1.4539007 | I26: 0.24061153 | K26: =E26/F26 -> 3.8401201 | M26: 0 | N26: 0 | O26: 0 | P26: 1 | Q26: 0.83606886 | R26: 0.81818182 | S26: 0.63020121 | T26: 2.9 | U26: 0.82 | V26: 0.47260274 | W26: 0.39013453 | X26: 0.091743119 | Y26: 0.32374247 | Z26: 0.58798736 | AA26: 0.45193052 | AB26: 0.82857143 | AC26: 0.47674419 | AD26: 0.38199339 | AE26: 0.41707477 | AF26: 0.10703364 | AG26: 0.12 | AH26: 0.135 | AI26: 0.18 | AJ26: 0.18 | AK26: 0.65 | AL26: 0.6 | AM26: 1 | AN26: 1 | AO26: 0.72 | AP26: 1 | AQ26: =AVERAGE(AL26,AO26) -> 0.66 | AR26: =AVERAGE(AM26) -> 1 | AS26: =AVERAGE(AN26,AP26) -> 1 | AT26: {=_xlfn.IFS(AG26>sheet2!$C$2,1,AG26=sheet2!$C$2,0,AG26<sheet2!$C$2,-1)} -> -1 | AU26: {=_xlfn.IFS(AH26>sheet2!$D$2,1,AH26=sheet2!$D$2,0,AH26<sheet2!$D$2,-1)} -> 0 | AV26: {=_xlfn.IFS(AI26>sheet2!$E$2,1,AI26=sheet2!$E$2,0,AI26<sheet2!$E$2,-1)} -> 0 | AW26: {=_xlfn.IFS(AJ26>sheet2!$F$2,1,AJ26=sheet2!$F$2,0,AJ26<sheet2!$F$2,-1)} -> -1 | AX26: {=_xlfn.IFS(AK26>sheet2!$G$2,1,AK26=sheet2!$G$2,0,AK26<sheet2!$G$2,-1)} -> 0 | AY26: 0.39183443 | AZ26: 0.57256688 | BA26: 0.022425302 | BB26: 0.0074808608 | BC26: 0.45408678
A27: 4 | B27: 山西 | C27: 2017 | D27: 19581 | E27: 50653.639 | F27: 15528.42 | G27: =D27/F27 -> 1.2609783 | H27: =(G27-G26)/G26 -> -0.13269299 | I27: 0.26312939 | J27: =(I27-I26)/I26 -> 0.093585968 | K27: =E27/F27 -> 3.2619957 | L27: =(K27-K26)/K26 -> -0.15054853 | M27: 0 | N27: 0 | O27: 0 | P27: 1 | Q27: 0.83606886 | R27: 0.81818182 | S27: 0.63020121 | T27: 2.9 | U27: 0.82 | V27: 0.47260274 | W27: 0.39013453 | X27: 0.091743119 | Y27: 0.32374247 | Z27: 0.58798736 | AA27: 0.45193052 | AB27: 0.82857143 | AC27: 0.47674419 | AD27: 0.38199339 | AE27: 0.41707477 | AF27: 0.10703364 | AG27: 0.12 | AH27: 0.135 | AI27: 0.18 | AJ27: 0.18 | AK27: 0.65 | AL27: 0.6 | AM27: 1 | AN27: 1 | AO27: 0.72 | AP27: 1 | AQ27: =AVERAGE(AL27,AO27) -> 0.66 | AR27: =AVERAGE(AM27) -> 1 | AS27: =AVERAGE(AN27,AP27) -> 1 | AT27: {=_xlfn.IFS(AG27>sheet2!$C$2,1,AG27=sheet2!$C$2,0,AG27<sheet2!$C$2,-1)} -> -1 | AU27: {=_xlfn.IFS(AH27>sheet2!$D$2,1,AH27=sheet2!$D$2,0,AH27<sheet2!$D$2,-1)} -> 0 | AV27: {=_xlfn.IFS(AI27>sheet2!$E$2,1,AI27=sheet2!$E$2,0,AI27<sheet2!$E$2,-1)} -> 0 | AW27: {=_xlfn.IFS(AJ27>sheet2!$F$2,1,AJ27=sheet2!$F$2,0,AJ27<sheet2!$F$2,-1)} -> -1 | AX27: {=_xlfn.IFS(AK27>sheet2!$G$2,1,AK27=sheet2!$G$2,0,AK27<sheet2!$G$2,-1)} -> 0 | AY27: 0.4273004 | AZ27: 0.58603989 | BA27: 0.022399775 | BB27: 0.0072275415 | BC27: 0.49701578
A28: 4 | B28: 山西 | C28: 2018 | D28: 20199 | E28: 52257.304 | F28: 16818.11 | G28: =D28/F28 -> 1.2010268 | H28: =(G28-G27)/G27 -> -0.047543649 | I28: 0.29171652 | J28: =(I28-I27)/I27 -> 0.10864285 | K28: =E28/F28 -> 3.1072043 | L28: =(K28-K27)/K27 -> -0.047452958 | M28: 0 | N28: 0 | O28: 0 | P28: 1 | Q28: 0.83606886 | R28: 0.81818182 | S28: 0.63020121 | T28: 2.9 | U28: 0.82 | V28: 0.47260274 | W28: 0.39013453 | X28: 0.091743119 | Y28: 0.32374247 | Z28: 0.58798736 | AA28: 0.45193052 | AB28: 0.82857143 | AC28: 0.47674419 | AD28: 0.38199339 | AE28: 0.41707477 | AF28: 0.10703364 | AG28: 0.12 | AH28: 0.135 | AI28: 0.18 | AJ28: 0.18 | AK28: 0.65 | AL28: 0.6 | AM28: 1 | AN28: 1 | AO28: 0.72 | AP28: 1 | AQ28: =AVERAGE(AL28,AO28) -> 0.66 | AR28: =AVERAGE(AM28) -> 1 | AS28: =AVERAGE(AN28,AP28) -> 1 | AT28: {=_xlfn.IFS(AG28>sheet2!$C$2,1,AG28=sheet2!$C$2,0,AG28<sheet2!$C$2,-1)} -> -1 | AU28: {=_xlfn.IFS(AH28>sheet2!$D$2,1,AH28=sheet2!$D$2,0,AH28<sheet2!$D$2,-1)} -> 0 | AV28: {=_xlfn.IFS(AI28>sheet2!$E$2,1,AI28=sheet2!$E$2,0,AI28<sheet2!$E$2,-1)} -> 0 | AW28: {=_xlfn.IFS(AJ28>sheet2!$F$2,1,AJ28=sheet2!$F$2,0,AJ28<sheet2!$F$2,-1)} -> -1 | AX28: {=_xlfn.IFS(AK28>sheet2!$G$2,1,AK28=sheet2!$G$2,0,AK28<sheet2!$G$2,-1)} -> 0 | AY28: 0.42064774 | AZ28: 0.59851513 | BA28: 0.022348722 | BB28: 0.0078042717 | BC28: 0.53518865
A29: 4 | B29: 山西 | C29: 2019 | D29: 20859 | E29: 52940.152 | F29: 17026.68 | G29: =D29/F29 -> 1.2250773 | H29: =(G29-G28)/G28 -> 0.020025032 | I29: 0.29011884 | J29: =(I29-I28)/I28 -> -0.0054768283 | K29: =E29/F29 -> 3.1092469 | L29: =(K29-K28)/K28 -> 0.0006573652 | M29: 0 | N29: 0 | O29: 0 | P29: 1 | Q29: 0.83606886 | R29: 0.81818182 | S29: 0.63020121 | T29: 2.9 | U29: 0.82 | V29: 0.47260274 | W29: 0.39013453 | X29: 0.091743119 | Y29: 0.32374247 | Z29: 0.58798736 | AA29: 0.45193052 | AB29: 0.82857143 | AC29: 0.47674419 | AD29: 0.38199339 | AE29: 0.41707477 | AF29: 0.10703364 | AG29: 0.12 | AH29: 0.135 | AI29: 0.18 | AJ29: 0.18 | AK29: 0.65 | AL29: 0.6 | AM29: 1 | AN29: 1 | AO29: 0.72 | AP29: 1 | AQ29: =AVERAGE(AL29,AO29) -> 0.66 | AR29: =AVERAGE(AM29) -> 1 | AS29: =AVERAGE(AN29,AP29) -> 1 | AT29: {=_xlfn.IFS(AG29>sheet2!$C$2,1,AG29=sheet2!$C$2,0,AG29<sheet2!$C$2,-1)} -> -1 | AU29: {=_xlfn.IFS(AH29>sheet2!$D$2,1,AH29=sheet2!$D$2,0,AH29<sheet2!$D$2,-1)} -> 0 | AV29: {=_xlfn.IFS(AI29>sheet2!$E$2,1,AI29=sheet2!$E$2,0,AI29<sheet2!$E$2,-1)} -> 0 | AW29: {=_xlfn.IFS(AJ29>sheet2!$F$2,1,AJ29=sheet2!$F$2,0,AJ29<sheet2!$F$2,-1)} -> -1 | AX29: {=_xlfn.IFS(AK29>sheet2!$G$2,1,AK29=sheet2!$G$2,0,AK29<sheet2!$G$2,-1)} -> 0 | AY29: 0.43478235 | AZ29: 0.61281098 | BA29: 0.022316813 | BB29: 0.008109702 | BC29: 0.4983803
A30: 4 | B30: 山西 | C30: 2020 | D30: 20980.55 | E30: 53023.822 | F30: 17651.93 | G30: =D30/F30 -> 1.1885697 | H30: =(G30-G29)/G29 -> -0.029800241 | I30: 0.30115491 | J30: =(I30-I29)/I29 -> 0.038039843 | K30: =E30/F30 -> 3.0038541 | L30: =(K30-K29)/K29 -> -0.033896568 | M30: 0 | N30: 0 | O30: 0 | P30: 1 | Q30: 0.83606886 | R30: 0.81818182 | S30: 0.63020121 | T30: 2.9 | U30: 0.82 | V30: 0.47260274 | W30: 0.39013453 | X30: 0.091743119 | Y30: 0.32374247 | Z30: 0.58798736 | AA30: 0.45193052 | AB30: 0.82857143 | AC30: 0.47674419 | AD30: 0.38199339 | AE30: 0.41707477 | AF30: 0.10703364 | AG30: 0.12 | AH30: 0.135 | AI30: 0.18 | AJ30: 0.18 | AK30: 0.65 | AL30: 0.6 | AM30: 1 | AN30: 1 | AO30: 0.72 | AP30: 1 | AQ30: =AVERAGE(AL30,AO30) -> 0.66 | AR30: =AVERAGE(AM30) -> 1 | AS30: =AVERAGE(AN30,AP30) -> 1 | AT30: {=_xlfn.IFS(AG30>sheet2!$C$2,1,AG30=sheet2!$C$2,0,AG30<sheet2!$C$2,-1)} -> -1 | AU30: {=_xlfn.IFS(AH30>sheet2!$D$2,1,AH30=sheet2!$D$2,0,AH30<sheet2!$D$2,-1)} -> 0 | AV30: {=_xlfn.IFS(AI30>sheet2!$E$2,1,AI30=sheet2!$E$2,0,AI30<sheet2!$E$2,-1)} -> 0 | AW30: {=_xlfn.IFS(AJ30>sheet2!$F$2,1,AJ30=sheet2!$F$2,0,AJ30<sheet2!$F$2,-1)} -> -1 | AX30: {=_xlfn.IFS(AK30>sheet2!$G$2,1,AK30=sheet2!$G$2,0,AK30<sheet2!$G$2,-1)} -> 0 | AY30: 0.42149499 | AZ30: 0.6252149 | BA30: 0.022272141 | BB30: 0.0088477011 | BC30: 0.44935011
A31: 4 | B31: 山西 | C31: 2021 | D31: 21643.94 | E31: 57900.73 | F31: 22590.161 | G31: =D31/F31 -> 0.95811359 | H31: =(G31-G30)/G30 -> -0.19389368 | I31: 0.30944368 | J31: =(I31-I30)/I30 -> 0.027523269 | K31: =E31/F31 -> 2.5630951 | L31: =(K31-K30)/K30 -> -0.14673117 | M31: 0 | N31: 0 | O31: 0 | P31: 1 | Q31: 0.83606886 | R31: 0.81818182 | S31: 0.63020121 | T31: 2.9 | U31: 0.82 | V31: 0.47260274 | W31: 0.39013453 | X31: 0.091743119 | Y31: 0.32374247 | Z31: 0.58798736 | AA31: 0.45193052 | AB31: 0.82857143 | AC31: 0.47674419 | AD31: 0.38199339 | AE31: 0.41707477 | AF31: 0.10703364 | AG31: 0.12 | AH31: 0.135 | AI31: 0.18 | AJ31: 0.18 | AK31: 0.65 | AL31: 0.6 | AM31: 1 | AN31: 1 | AO31: 0.72 | AP31: 1 | AQ31: =AVERAGE(AL31,AO31) -> 0.66 | AR31: =AVERAGE(AM31) -> 1 | AS31: =AVERAGE(AN31,AP31) -> 1 | AT31: {=_xlfn.IFS(AG31>sheet2!$C$2,1,AG31=sheet2!$C$2,0,AG31<sheet2!$C$2,-1)} -> -1 | AU31: {=_xlfn.IFS(AH31>sheet2!$D$2,1,AH31=sheet2!$D$2,0,AH31<sheet2!$D$2,-1)} -> 0 | AV31: {=_xlfn.IFS(AI31>sheet2!$E$2,1,AI31=sheet2!$E$2,0,AI31<sheet2!$E$2,-1)} -> 0 | AW31: {=_xlfn.IFS(AJ31>sheet2!$F$2,1,AJ31=sheet2!$F$2,0,AJ31<sheet2!$F$2,-1)} -> -1 | AX31: {=_xlfn.IFS(AK31>sheet2!$G$2,1,AK31=sheet2!$G$2,0,AK31<sheet2!$G$2,-1)} -> 0 | AY31: 0.48217895 | AZ31: 0.6341954 | BA31: 0.022208324 | BB31: 0.0082445097 | BC31: 0.56165711
A32: 4 | B32: 山西 | C32: 2022 | D32: 21918.5 | E32: 58957.834 | F32: 25642.6 | G32: =D32/F32 -> 0.85476902 | H32: =(G32-G31)/G31 -> -0.10786255 | I32: 0.376648 | J32: =(I32-I31)/I31 -> 0.21717787 | K32: =E32/F32 -> 2.2992143 | L32: =(K32-K31)/K31 -> -0.10295393 | M32: 1 | N32: 1 | O32: 0 | P32: 1 | Q32: 0.83606886 | R32: 0.81818182 | S32: 0.63020121 | T32: 2.9 | U32: 0.82 | V32: 0.47260274 | W32: 0.39013453 | X32: 0.091743119 | Y32: 0.32374247 | Z32: 0.58798736 | AA32: 0.45193052 | AB32: 0.82857143 | AC32: 0.47674419 | AD32: 0.38199339 | AE32: 0.41707477 | AF32: 0.10703364 | AG32: 0.12 | AH32: 0.135 | AI32: 0.18 | AJ32: 0.18 | AK32: 0.65 | AL32: 0.6 | AM32: 1 | AN32: 1 | AO32: 0.72 | AP32: 1 | AQ32: =AVERAGE(AL32,AO32) -> 0.66 | AR32: =AVERAGE(AM32) -> 1 | AS32: =AVERAGE(AN32,AP32) -> 1 | AT32: {=_xlfn.IFS(AG32>sheet2!$C$2,1,AG32=sheet2!$C$2,0,AG32<sheet2!$C$2,-1)} -> -1 | AU32: {=_xlfn.IFS(AH32>sheet2!$D$2,1,AH32=sheet2!$D$2,0,AH32<sheet2!$D$2,-1)} -> 0 | AV32: {=_xlfn.IFS(AI32>sheet2!$E$2,1,AI32=sheet2!$E$2,0,AI32<sheet2!$E$2,-1)} -> 0 | AW32: {=_xlfn.IFS(AJ32>sheet2!$F$2,1,AJ32=sheet2!$F$2,0,AJ32<sheet2!$F$2,-1)} -> -1 | AX32: {=_xlfn.IFS(AK32>sheet2!$G$2,1,AK32=sheet2!$G$2,0,AK32<sheet2!$G$2,-1)} -> 0 | AY32: 0.49398657 | AZ32: 0.63947142 | BA32: 0.022214706 | BB32: 0.0078895393 | BC32: 0.58776312
A33: 4 | B33: 山西 | C33: 2023 | D33: 8426.28 | E33: 62909.476 | F33: 25698.184 | G33: =D33/F33 -> 0.32789398 | H33: =(G33-G32)/G32 -> -0.61639464 | K33: =E33/F33 -> 2.4480125 | L33: =(K33-K32)/K32 -> 0.064716948 | M33: 1 | N33: 1 | O33: 1 | P33: 1 | Q33: 0.83606886 | R33: 0.81818182 | S33: 0.63020121 | T33: 2.9 | U33: 0.82 | V33: 0.47260274 | W33: 0.39013453 | X33: 0.091743119 | Y33: 0.32374247 | Z33: 0.58798736 | AA33: 0.45193052 | AB33: 0.82857143 | AC33: 0.47674419 | AD33: 0.38199339 | AE33: 0.41707477 | AF33: 0.10703364 | AG33: 0.12 | AH33: 0.135 | AI33: 0.18 | AJ33: 0.18 | AK33: 0.65 | AL33: 0.6 | AM33: 1 | AN33: 1 | AO33: 0.72 | AP33: 1 | AQ33: =AVERAGE(AL33,AO33) -> 0.66 | AR33: =AVERAGE(AM33) -> 1 | AS33: =AVERAGE(AN33,AP33) -> 1 | AT33: {=_xlfn.IFS(AG33>sheet2!$C$2,1,AG33=sheet2!$C$2,0,AG33<sheet2!$C$2,-1)} -> -1 | AU33: {=_xlfn.IFS(AH33>sheet2!$D$2,1,AH33=sheet2!$D$2,0,AH33<sheet2!$D$2,-1)} -> 0 | AV33: {=_xlfn.IFS(AI33>sheet2!$E$2,1,AI33=sheet2!$E$2,0,AI33<sheet2!$E$2,-1)} -> 0 | AW33: {=_xlfn.IFS(AJ33>sheet2!$F$2,1,AJ33=sheet2!$F$2,0,AJ33<sheet2!$F$2,-1)} -> -1 | AX33: {=_xlfn.IFS(AK33>sheet2!$G$2,1,AK33=sheet2!$G$2,0,AK33<sheet2!$G$2,-1)} -> 0 | AY33: 0.46462815 | AZ33: 0.64974033 | BA33: 0.02211898 | BB33: 0.0084670767 | BC33: 0.54831135
A34: 5 | B34: 内蒙古 | C34: 2016 | D34: 19310 | E34: 54592.2 | F34: 18128.1 | G34: =D34/F34 -> 1.0651971 | I34: 0.32668048 | K34: =E34/F34 -> 3.0114684 | M34: 0 | N34: 0 | O34: 0 | P34: 1 | Q34: 0.82466688 | R34: -0.76539589 | S34: -0.99324524 | T34: 1.9 | U34: -0.6 | V34: -0.87123746 | W34: -0.9354067 | X34: -0.56914894 | Y34: 0.27670642 | Z34: -0.55005269 | AA34: -0.71227702 | AB34: 0.54285714 | AC34: -0.34883721 | AD34: -0.70420021 | AE34: -1 | AF34: -0.66400709 | AG34: 0.18 | AH34: 0.135 | AI34: 0.18 | AJ34: 0.25 | AK34: 0.65 | AL34: 0.9 | AM34: 1 | AN34: 1 | AO34: 1 | AP34: 1 | AQ34: =AVERAGE(AL34,AO34) -> 0.95 | AR34: =AVERAGE(AM34) -> 1 | AS34: =AVERAGE(AN34,AP34) -> 1 | AT34: {=_xlfn.IFS(AG34>sheet2!$C$2,1,AG34=sheet2!$C$2,0,AG34<sheet2!$C$2,-1)} -> -1 | AU34: {=_xlfn.IFS(AH34>sheet2!$D$2,1,AH34=sheet2!$D$2,0,AH34<sheet2!$D$2,-1)} -> 0 | AV34: {=_xlfn.IFS(AI34>sheet2!$E$2,1,AI34=sheet2!$E$2,0,AI34<sheet2!$E$2,-1)} -> 0 | AW34: {=_xlfn.IFS(AJ34>sheet2!$F$2,1,AJ34=sheet2!$F$2,0,AJ34<sheet2!$F$2,-1)} -> 0 | AX34: {=_xlfn.IFS(AK34>sheet2!$G$2,1,AK34=sheet2!$G$2,0,AK34<sheet2!$G$2,-1)} -> 0 | AY34: 0.30779839 | AZ34: 0.63382594 | BA34: 0.0021265841 | BB34: 0.0070600504 | BC34: 0.4468335
A35: 5 | B35: 内蒙古 | C35: 2017 | D35: 19763 | E35: 57761.393 | F35: 16096.21 | G35: =D35/F35 -> 1.2278046 | H35: =(G35-G34)/G34 -> 0.15265478 | I35: 0.35588349 | J35: =(I35-I34)/I34 -> 0.089393178 | K35: =E35/F35 -> 3.5885089 | L35: =(K35-K34)/K34 -> 0.19161433 | M35: 0 | N35: 0 | O35: 0 | P35: 1 | Q35: 0.82466688 | R35: -0.76539589 | S35: -0.99324524 | T35: 1.9 | U35: -0.6 | V35: -0.87123746 | W35: -0.9354067 | X35: -0.56914894 | Y35: 0.27670642 | Z35: -0.55005269 | AA35: -0.71227702 | AB35: 0.54285714 | AC35: -0.34883721 | AD35: -0.70420021 | AE35: -1 | AF35: -0.66400709 | AG35: 0.18 | AH35: 0.135 | AI35: 0.18 | AJ35: 0.25 | AK35: 0.65 | AL35: 0.9 | AM35: 1 | AN35: 1 | AO35: 1 | AP35: 1 | AQ35: =AVERAGE(AL35,AO35) -> 0.95 | AR35: =AVERAGE(AM35) -> 1 | AS35: =AVERAGE(AN35,AP35) -> 1 | AT35: {=_xlfn.IFS(AG35>sheet2!$C$2,1,AG35=sheet2!$C$2,0,AG35<sheet2!$C$2,-1)} -> -1 | AU35: {=_xlfn.IFS(AH35>sheet2!$D$2,1,AH35=sheet2!$D$2,0,AH35<sheet2!$D$2,-1)} -> 0 | AV35: {=_xlfn.IFS(AI35>sheet2!$E$2,1,AI35=sheet2!$E$2,0,AI35<sheet2!$E$2,-1)} -> 0 | AW35: {=_xlfn.IFS(AJ35>sheet2!$F$2,1,AJ35=sheet2!$F$2,0,AJ35<sheet2!$F$2,-1)} -> 0 | AX35: {=_xlfn.IFS(AK35>sheet2!$G$2,1,AK35=sheet2!$G$2,0,AK35<sheet2!$G$2,-1)} -> 0 | AY35: 0.36494305 | AZ35: 0.64611591 | BA35: 0.0021239652 | BB35: 0.0067260554 | BC35: 0.37599036
A36: 5 | B36: 内蒙古 | C36: 2018 | D36: 23068 | E36: 60493.935 | F36: 17289.22 | G36: =D36/F36 -> 1.3342418 | H36: =(G36-G35)/G35 -> 0.086689075 | I36: 0.35655925 | J36: =(I36-I35)/I35 -> 0.001898827 | K36: =E36/F36 -> 3.4989395 | L36: =(K36-K35)/K35 -> -0.024960061 | M36: 0 | N36: 0 | O36: 0 | P36: 1 | Q36: 0.82466688 | R36: -0.76539589 | S36: -0.99324524 | T36: 1.9 | U36: -0.6 | V36: -0.87123746 | W36: -0.9354067 | X36: -0.56914894 | Y36: 0.27670642 | Z36: -0.55005269 | AA36: -0.71227702 | AB36: 0.54285714 | AC36: -0.34883721 | AD36: -0.70420021 | AE36: -1 | AF36: -0.66400709 | AG36: 0.18 | AH36: 0.135 | AI36: 0.18 | AJ36: 0.25 | AK36: 0.65 | AL36: 0.9 | AM36: 1 | AN36: 1 | AO36: 1 | AP36: 1 | AQ36: =AVERAGE(AL36,AO36) -> 0.95 | AR36: =AVERAGE(AM36) -> 1 | AS36: =AVERAGE(AN36,AP36) -> 1 | AT36: {=_xlfn.IFS(AG36>sheet2!$C$2,1,AG36=sheet2!$C$2,0,AG36<sheet2!$C$2,-1)} -> -1 | AU36: {=_xlfn.IFS(AH36>sheet2!$D$2,1,AH36=sheet2!$D$2,0,AH36<sheet2!$D$2,-1)} -> 0 | AV36: {=_xlfn.IFS(AI36>sheet2!$E$2,1,AI36=sheet2!$E$2,0,AI36<sheet2!$E$2,-1)} -> 0 | AW36: {=_xlfn.IFS(AJ36>sheet2!$F$2,1,AJ36=sheet2!$F$2,0,AJ36<sheet2!$F$2,-1)} -> 0 | AX36: {=_xlfn.IFS(AK36>sheet2!$G$2,1,AK36=sheet2!$G$2,0,AK36<sheet2!$G$2,-1)} -> 0 | AY36: 0.36643643 | AZ36: 0.6552436 | BA36: 0.0021143624 | BB36: 0.005978257 | BC36: 0.3844904
A37: 5 | B37: 内蒙古 | C37: 2019 | D37: 25346 | E37: 63563.319 | F37: 17212.53 | G37: =D37/F37 -> 1.4725319 | H37: =(G37-G36)/G36 -> 0.10364698 | I37: 0.3589921 | J37: =(I37-I36)/I36 -> 0.0068231288 | K37: =E37/F37 -> 3.6928516 | L37: =(K37-K36)/K36 -> 0.055420261 | M37: 0 | N37: 0 | O37: 0 | P37: 1 | Q37: 0.82466688 | R37: -0.76539589 | S37: -0.99324524 | T37: 1.9 | U37: -0.6 | V37: -0.87123746 | W37: -0.9354067 | X37: -0.56914894 | Y37: 0.27670642 | Z37: -0.55005269 | AA37: -0.71227702 | AB37: 0.54285714 | AC37: -0.34883721 | AD37: -0.70420021 | AE37: -1 | AF37: -0.66400709 | AG37: 0.18 | AH37: 0.135 | AI37: 0.18 | AJ37: 0.25 | AK37: 0.65 | AL37: 0.9 | AM37: 1 | AN37: 1 | AO37: 1 | AP37: 1 | AQ37: =AVERAGE(AL37,AO37) -> 0.95 | AR37: =AVERAGE(AM37) -> 1 | AS37: =AVERAGE(AN37,AP37) -> 1 | AT37: {=_xlfn.IFS(AG37>sheet2!$C$2,1,AG37=sheet2!$C$2,0,AG37<sheet2!$C$2,-1)} -> -1 | AU37: {=_xlfn.IFS(AH37>sheet2!$D$2,1,AH37=sheet2!$D$2,0,AH37<sheet2!$D$2,-1)} -> 0 | AV37: {=_xlfn.IFS(AI37>sheet2!$E$2,1,AI37=sheet2!$E$2,0,AI37<sheet2!$E$2,-1)} -> 0 | AW37: {=_xlfn.IFS(AJ37>sheet2!$F$2,1,AJ37=sheet2!$F$2,0,AJ37<sheet2!$F$2,-1)} -> 0 | AX37: {=_xlfn.IFS(AK37>sheet2!$G$2,1,AK37=sheet2!$G$2,0,AK37<sheet2!$G$2,-1)} -> 0 | AY37: 0.39355051 | AZ37: 0.66459627 | BA37: 0.0021082515 | BB37: 0.0068765312 | BC37: 0.40378874
A38: 5 | B38: 内蒙古 | C38: 2020 | D38: 27133.65 | E38: 65228.307 | F38: 17359.82 | G38: =D38/F38 -> 1.5630145 | H38: =(G38-G37)/G37 -> 0.061446919 | I38: 0.3705434 | J38: =(I38-I37)/I37 -> 0.032177052 | K38: =E38/F38 -> 3.7574299 | L38: =(K38-K37)/K37 -> 0.017487369 | M38: 0 | N38: 0 | O38: 0 | P38: 1 | Q38: 0.82466688 | R38: -0.76539589 | S38: -0.99324524 | T38: 1.9 | U38: -0.6 | V38: -0.87123746 | W38: -0.9354067 | X38: -0.56914894 | Y38: 0.27670642 | Z38: -0.55005269 | AA38: -0.71227702 | AB38: 0.54285714 | AC38: -0.34883721 | AD38: -0.70420021 | AE38: -1 | AF38: -0.66400709 | AG38: 0.18 | AH38: 0.135 | AI38: 0.18 | AJ38: 0.25 | AK38: 0.65 | AL38: 0.9 | AM38: 1 | AN38: 1 | AO38: 1 | AP38: 1 | AQ38: =AVERAGE(AL38,AO38) -> 0.95 | AR38: =AVERAGE(AM38) -> 1 | AS38: =AVERAGE(AN38,AP38) -> 1 | AT38: {=_xlfn.IFS(AG38>sheet2!$C$2,1,AG38=sheet2!$C$2,0,AG38<sheet2!$C$2,-1)} -> -1 | AU38: {=_xlfn.IFS(AH38>sheet2!$D$2,1,AH38=sheet2!$D$2,0,AH38<sheet2!$D$2,-1)} -> 0 | AV38: {=_xlfn.IFS(AI38>sheet2!$E$2,1,AI38=sheet2!$E$2,0,AI38<sheet2!$E$2,-1)} -> 0 | AW38: {=_xlfn.IFS(AJ38>sheet2!$F$2,1,AJ38=sheet2!$F$2,0,AJ38<sheet2!$F$2,-1)} -> 0 | AX38: {=_xlfn.IFS(AK38>sheet2!$G$2,1,AK38=sheet2!$G$2,0,AK38<sheet2!$G$2,-1)} -> 0 | AY38: 0.39111581 | AZ38: 0.6749896 | BA38: 0.0020977757 | BB38: 0.0074523469 | BC38: 0.38921019
A39: 5 | B39: 内蒙古 | C39: 2021 | D39: 26900.46 | E39: 72847.094 | F39: 20514.195 | G39: =D39/F39 -> 1.3113096 | H39: =(G39-G38)/G38 -> -0.16103811 | I39: 0.40318423 | J39: =(I39-I38)/I38 -> 0.088089082 | K39: =E39/F39 -> 3.5510579 | L39: =(K39-K38)/K38 -> -0.0549237 | M39: 0 | N39: 0 | O39: 0 | P39: 1 | Q39: 0.82466688 | R39: -0.76539589 | S39: -0.99324524 | T39: 1.9 | U39: -0.6 | V39: -0.87123746 | W39: -0.9354067 | X39: -0.56914894 | Y39: 0.27670642 | Z39: -0.55005269 | AA39: -0.71227702 | AB39: 0.54285714 | AC39: -0.34883721 | AD39: -0.70420021 | AE39: -1 | AF39: -0.66400709 | AG39: 0.18 | AH39: 0.135 | AI39: 0.18 | AJ39: 0.25 | AK39: 0.65 | AL39: 0.9 | AM39: 1 | AN39: 1 | AO39: 1 | AP39: 1 | AQ39: =AVERAGE(AL39,AO39) -> 0.95 | AR39: =AVERAGE(AM39) -> 1 | AS39: =AVERAGE(AN39,AP39) -> 1 | AT39: {=_xlfn.IFS(AG39>sheet2!$C$2,1,AG39=sheet2!$C$2,0,AG39<sheet2!$C$2,-1)} -> -1 | AU39: {=_xlfn.IFS(AH39>sheet2!$D$2,1,AH39=sheet2!$D$2,0,AH39<sheet2!$D$2,-1)} -> 0 | AV39: {=_xlfn.IFS(AI39>sheet2!$E$2,1,AI39=sheet2!$E$2,0,AI39<sheet2!$E$2,-1)} -> 0 | AW39: {=_xlfn.IFS(AJ39>sheet2!$F$2,1,AJ39=sheet2!$F$2,0,AJ39<sheet2!$F$2,-1)} -> 0 | AX39: {=_xlfn.IFS(AK39>sheet2!$G$2,1,AK39=sheet2!$G$2,0,AK39<sheet2!$G$2,-1)} -> 0 | AY39: 0.47023537 | AZ39: 0.68208333 | BA39: 0.0020951568 | BB39: 0.0075447466 | BC39: 0.44850054
A40: 5 | B40: 内蒙古 | C40: 2022 | D40: 27980.98 | E40: 75702.872 | F40: 23158.6 | G40: =D40/F40 -> 1.2082328 | H40: =(G40-G39)/G39 -> -0.078605987 | I40: 0.41102771 | J40: =(I40-I39)/I39 -> 0.01945382 | K40: =E40/F40 -> 3.2688881 | L40: =(K40-K39)/K39 -> -0.079460777 | M40: 1 | N40: 1 | O40: 0 | P40: 1 | Q40: 0.82466688 | R40: -0.76539589 | S40: -0.99324524 | T40: 1.9 | U40: -0.6 | V40: -0.87123746 | W40: -0.9354067 | X40: -0.56914894 | Y40: 0.27670642 | Z40: -0.55005269 | AA40: -0.71227702 | AB40: 0.54285714 | AC40: -0.34883721 | AD40: -0.70420021 | AE40: -1 | AF40: -0.66400709 | AG40: 0.18 | AH40: 0.135 | AI40: 0.18 | AJ40: 0.25 | AK40: 0.65 | AL40: 0.9 | AM40: 1 | AN40: 1 | AO40: 1 | AP40: 1 | AQ40: =AVERAGE(AL40,AO40) -> 0.95 | AR40: =AVERAGE(AM40) -> 1 | AS40: =AVERAGE(AN40,AP40) -> 1 | AT40: {=_xlfn.IFS(AG40>sheet2!$C$2,1,AG40=sheet2!$C$2,0,AG40<sheet2!$C$2,-1)} -> -1 | AU40: {=_xlfn.IFS(AH40>sheet2!$D$2,1,AH40=sheet2!$D$2,0,AH40<sheet2!$D$2,-1)} -> 0 | AV40: {=_xlfn.IFS(AI40>sheet2!$E$2,1,AI40=sheet2!$E$2,0,AI40<sheet2!$E$2,-1)} -> 0 | AW40: {=_xlfn.IFS(AJ40>sheet2!$F$2,1,AJ40=sheet2!$F$2,0,AJ40<sheet2!$F$2,-1)} -> 0 | AX40: {=_xlfn.IFS(AK40>sheet2!$G$2,1,AK40=sheet2!$G$2,0,AK40<sheet2!$G$2,-1)} -> 0 | AY40: 0.47139292 | AZ40: 0.68596418 | BA40: 0.0020960298 | BB40: 0.007377566 | BC40: 0.47971024
...

Sheet 变量表
A1: 自变量 | B1: 解释
A2: post1 | B2: 中央是否在该年出台中央文件
A3: post2 | B3: 地方在该年是否出台地方文件
A4: treated | B4: 中央文件发布后地方是否有跟进发布地方文件
A5: avg_direct_sim | B5: 相似度
A6: avg_direct_degree | B6: 相对语调
A7: avg_hidden_degree | B7: 隐式相对语调（最相近十个句子的平均）
A8: target | B8: “主要目标”段落的相对语调
A9: target_hid | B9: “主要目标”段落的隐式相对语调
A10: deg70 | B10: 控制相似度阈值为70的相对语调
A11: deg80 | B11: 控制相似度阈值为80的相对语调
A12: deg90 | B12: 控制相似度阈值为90的相对语调
... A45: 单位GDP碳排放量增长率 | B45: -

Sheet Sheet5
A1: 0.35300316 | B1: 1 | E1: id | F1: 地 | G1: year | H1: 非化石能源占比 | I1: 非化石能源占比增长率 | J1: a145 | K1: b145 | L1: c145 | M1: a155 | N1: c155 | O1: std_a145 | P1: std_b145 | Q1: std_c145 | R1: std_a155 | S1: std_c155 | T1: a | U1: b | V1: c | W1: if_a | X1: if_b | Y1: if_c | Z1: if_a_155 | AA1: if_c_155
A2: 1 | B2: 1 | E2: 1 | F2: 北京 | G2: 2016 | H2: 0.35776976 | J2: 0.144 | K2: 0.14 | L2: 0.18 | M2: 0.25 | N2: 0.65 | O2: 0.72 | P2: 1.037037 | Q2: 1 | R2: 1 | S2: 1 | T2: =AVERAGE(O2,R2) -> 0.86 | U2: =AVERAGE(P2) -> 1.037037 | V2: =AVERAGE(Q2,S2) -> 1 | W2: {=_xlfn.IFS(J2>sheet2!$C$2,1,J2=sheet2!$C$2,0,J2<sheet2!$C$2,-1)} -> -1 | X2: {=_xlfn.IFS(K2>sheet2!$D$2,1,K2=sheet2!$D$2,0,K2<sheet2!$D$2,-1)} -> 1 | Y2: {=_xlfn.IFS(L2>sheet2!$E$2,1,L2=sheet2!$E$2,0,L2<sheet2!$E$2,-1)} -> 0 | Z2: {=_xlfn.IFS(M2>sheet2!$F$2,1,M2=sheet2!$F$2,0,M2<sheet2!$F$2,-1)} -> 0 | AA2: {=_xlfn.IFS(N2>sheet2!$G$2,1,N2=sheet2!$G$2,0,N2<sheet2!$G$2,-1)} -> 0
A3: 0.023182297 | B3: 1 | E3: 1 | F3: 北京 | G3: 2017 | H3: 0.36853608 | I3: =(H3-H2)/H2 -> 0.030092858 | J3: 0.144 | K3: 0.14 | L3: 0.18 | M3: 0.25 | N3: 0.65 | O3: 0.72 | P3: 1.037037 | Q3: 1 | R3: 1 | S3: 1 | T3: =AVERAGE(O3,R3) -> 0.86 | U3: =AVERAGE(P3) -> 1.037037 | V3: =AVERAGE(Q3,S3) -> 1 | W3: {=_xlfn.IFS(J3>sheet2!$C$2,1,J3=sheet2!$C$2,0,J3<sheet2!$C$2,-1)} -> -1 | X3: {=_xlfn.IFS(K3>sheet2!$D$2,1,K3=sheet2!$D$2,0,K3<sheet2!$D$2,-1)} -> 1 | Y3: {=_xlfn.IFS(L3>sheet2!$E$2,1,L3=sheet2!$E$2,0,L3<sheet2!$E$2,-1)} -> 0 | Z3: {=_xlfn.IFS(M3>sheet2!$F$2,1,M3=sheet2!$F$2,0,M3<sheet2!$F$2,-1)} -> 0 | AA3: {=_xlfn.IFS(N3>sheet2!$G$2,1,N3=sheet2!$G$2,0,N3<sheet2!$G$2,-1)} -> 0
A4: 0.58798736 | B4: 1 | E4: 1 | F4: 北京 | G4: 2018 | H4: 0.3894371 | I4: =(H4-H3)/H3 -> 0.056713642 | J4: 0.144 | K4: 0.14 | L4: 0.18 | M4: 0.25 | N4: 0.65 | O4: 0.72 | P4: 1.037037 | Q4: 1 | R4: 1 | S4: 1 | T4: =AVERAGE(O4,R4) -> 0.86 | U4: =AVERAGE(P4) -> 1.037037 | V4: =AVERAGE(Q4,S4) -> 1 | W4: {=_xlfn.IFS(J4>sheet2!$C$2,1,J4=sheet2!$C$2,0,J4<sheet2!$C$2,-1)} -> -1 | X4: {=_xlfn.IFS(K4>sheet2!$D$2,1,K4=sheet2!$D$2,0,K4<sheet2!$D$2,-1)} -> 1 | Y4: {=_xlfn.IFS(L4>sheet2!$E$2,1,L4=sheet2!$E$2,0,L4<sheet2!$E$2,-1)} -> 0 | Z4: {=_xlfn.IFS(M4>sheet2!$F$2,1,M4=sheet2!$F$2,0,M4<sheet2!$F$2,-1)} -> 0 | AA4: {=_xlfn.IFS(N4>sheet2!$G$2,1,N4=sheet2!$G$2,0,N4<sheet2!$G$2,-1)} -> 0
A5: -0.55005269 | B5: 1 | E5: 1 | F5: 北京 | G5: 2019 | H5: 0.39378508 | I5: =(H5-H4)/H4 -> 0.011164767 | J5: 0.144 | K5: 0.14 | L5: 0.18 | M5: 0.25 | N5: 0.65 | O5: 0.72 | P5: 1.037037 | Q5: 1 | R5: 1 | S5: 1 | T5: =AVERAGE(O5,R5) -> 0.86 | U5: =AVERAGE(P5) -> 1.037037 | V5: =AVERAGE(Q5,S5) -> 1 | W5: {=_xlfn.IFS(J5>sheet2!$C$2,1,J5=sheet2!$C$2,0,J5<sheet2!$C$2,-1)} -> -1 | X5: {=_xlfn.IFS(K5>sheet2!$D$2,1,K5=sheet2!$D$2,0,K5<sheet2!$D$2,-1)} -> 1 | Y5: {=_xlfn.IFS(L5>sheet2!$E$2,1,L5=sheet2!$E$2,0,L5<sheet2!$E$2,-1)} -> 0 | Z5: {=_xlfn.IFS(M5>sheet2!$F$2,1,M5=sheet2!$F$2,0,M5<sheet2!$F$2,-1)} -> 0 | AA5: {=_xlfn.IFS(N5>sheet2!$G$2,1,N5=sheet2!$G$2,0,N5<sheet2!$G$2,-1)} -> 0
A6: 0.61222339 | B6: 1 | E6: 1 | F6: 北京 | G6: 2020 | H6: 0.45559969 | I6: =(H6-H5)/H5 -> 0.15697552 | J6: 0.144 | K6: 0.14 | L6: 0.18 | M6: 0.25 | N6: 0.65 | O6: 0.72 | P6: 1.037037 | Q6: 1 | R6: 1 | S6: 1 | T6: =AVERAGE(O6,R6) -> 0.86 | U6: =AVERAGE(P6) -> 1.037037 | V6: =AVERAGE(Q6,S6) -> 1 | W6: {=_xlfn.IFS(J6>sheet2!$C$2,1,J6=sheet2!$C$2,0,J6<sheet2!$C$2,-1)} -> -1 | X6: {=_xlfn.IFS(K6>sheet2!$D$2,1,K6=sheet2!$D$2,0,K6<sheet2!$D$2,-1)} -> 1 | Y6: {=_xlfn.IFS(L6>sheet2!$E$2,1,L6=sheet2!$E$2,0,L6<sheet2!$E$2,-1)} -> 0 | Z6: {=_xlfn.IFS(M6>sheet2!$F$2,1,M6=sheet2!$F$2,0,M6<sheet2!$F$2,-1)} -> 0 | AA6: {=_xlfn.IFS(N6>sheet2!$G$2,1,N6=sheet2!$G$2,0,N6<sheet2!$G$2,-1)} -> 0
A7: 0.09483667 | B7: 1 | E7: 1 | F7: 北京 | G7: 2021 | H7: 0.44803091 | I7: =(H7-H6)/H6 -> -0.016612797 | J7: 0.155 | K7: 0.14 | L7: 0.18 | M7: 0.22 | N7: 0.65 | O7: 0.775 | P7: 1.037037 | Q7: 1 | R7: 0.88 | S7: 1 | T7: =AVERAGE(O7,R7) -> 0.8275 | U7: =AVERAGE(P7) -> 1.037037 | V7: =AVERAGE(Q7,S7) -> 1 | W7: {=_xlfn.IFS(J7>sheet2!$C$2,1,J7=sheet2!$C$2,0,J7<sheet2!$C$2,-1)} -> -1 | X7: {=_xlfn.IFS(K7>sheet2!$D$2,1,K7=sheet2!$D$2,0,K7<sheet2!$D$2,-1)} -> 1 | Y7: {=_xlfn.IFS(L7>sheet2!$E$2,1,L7=sheet2!$E$2,0,L7<sheet2!$E$2,-1)} -> 0 | Z7: {=_xlfn.IFS(M7>sheet2!$F$2,1,M7=sheet2!$F$2,0,M7<sheet2!$F$2,-1)} -> -1 | AA7: {=_xlfn.IFS(N7>sheet2!$G$2,1,N7=sheet2!$G$2,0,N7<sheet2!$G$2,-1)} -> 0
A8: 0 | B8: 0 | E8: 1 | F8: 北京 | G8: 2022 | H8: 0.49718448 | I8: =(H8-H7)/H7 -> 0.10971023 | J8: 0.155 | K8: 0.14 | L8: 0.18 | M8: 0.22 | N8: 0.65 | O8: 0.775 | P8: 1.037037 | Q8: 1 | R8: 0.88 | S8: 1 | T8: =AVERAGE(O8,R8) -> 0.8275 | U8: =AVERAGE(P8) -> 1.037037 | V8: =AVERAGE(Q8,S8) -> 1 | W8: {=_xlfn.IFS(J8>sheet2!$C$2,1,J8=sheet2!$C$2,0,J8<sheet2!$C$2,-1)} -> -1 | X8: {=_xlfn.IFS(K8>sheet2!$D$2,1,K8=sheet2!$D$2,0,K8<sheet2!$D$2,-1)} -> 1 | Y8: {=_xlfn.IFS(L8>sheet2!$E$2,1,L8=sheet2!$E$2,0,L8<sheet2!$E$2,-1)} -> 0 | Z8: {=_xlfn.IFS(M8>sheet2!$F$2,1,M8=sheet2!$F$2,0,M8<sheet2!$F$2,-1)} -> -1 | AA8: {=_xlfn.IFS(N8>sheet2!$G$2,1,N8=sheet2!$G$2,0,N8<sheet2!$G$2,-1)} -> 0
A9: 0.34562698 | B9: 1 | E9: 1 | F9: 北京 | G9: 2023 | J9: 0.144 | K9: 0.14 | L9: 0.18 | M9: 0.25 | N9: 0.65 | O9: 0.72 | P9: 1.037037 | Q9: 1 | R9: 1 | S9: 1 | T9: =AVERAGE(O9,R9) -> 0.86 | U9: =AVERAGE(P9) -> 1.037037 | V9: =AVERAGE(Q9,S9) -> 1 | W9: {=_xlfn.IFS(J9>sheet2!$C$2,1,J9=sheet2!$C$2,0,J9<sheet2!$C$2,-1)} -> -1 | X9: {=_xlfn.IFS(K9>sheet2!$D$2,1,K9=sheet2!$D$2,0,K9<sheet2!$D$2,-1)} -> 1 | Y9: {=_xlfn.IFS(L9>sheet2!$E$2,1,L9=sheet2!$E$2,0,L9<sheet2!$E$2,-1)} -> 0 | Z9: {=_xlfn.IFS(M9>sheet2!$F$2,1,M9=sheet2!$F$2,0,M9<sheet2!$F$2,-1)} -> 0 | AA9: {=_xlfn.IFS(N9>sheet2!$G$2,1,N9=sheet2!$G$2,0,N9<sheet2!$G$2,-1)} -> 0
A10: 0.49420443 | B10: 1 | E10: 2 | F10: 天津 | G10: 2016 | H10: 0.31494388 | J10: 0.117 | K10: 0.135 | L10: 0.18 | M10: 0.16 | N10: 0.65 | O10: 0.585 | P10: 1 | Q10: 1 | R10: 0.64 | S10: 1 | T10: =AVERAGE(O10,R10) -> 0.6125 | U10: =AVERAGE(P10) -> 1 | V10: =AVERAGE(Q10,S10) -> 1 | W10: {=_xlfn.IFS(J10>sheet2!$C$2,1,J10=sheet2!$C$2,0,J10<sheet2!$C$2,-1)} -> -1 | X10: {=_xlfn.IFS(K10>sheet2!$D$2,1,K10=sheet2!$D$2,0,K10<sheet2!$D$2,-1)} -> 0 | Y10: {=_xlfn.IFS(L10>sheet2!$E$2,1,L10=sheet2!$E$2,0,L10<sheet2!$E$2,-1)} -> 0 | Z10: {=_xlfn.IFS(M10>sheet2!$F$2,1,M10=sheet2!$F$2,0,M10<sheet2!$F$2,-1)} -> -1 | AA10: {=_xlfn.IFS(N10>sheet2!$G$2,1,N10=sheet2!$G$2,0,N10<sheet2!$G$2,-1)} -> 0
